Workbook

Sheet DATA
I1: BÁO CÁO DOANH THU DỰ ÁN | V1: Người lập: | W1: N.T.T.Hằng
I2: TURNOVER REPORT | V2: Ngày báo cáo: | W2: =TODAY()
W3: Đơn vị tính: đồng
A4: TT No | B4: Tên đơn vị nhận hóa đơn Company's name | C4: Tên khách hàng Client name | D4: Số hợp đồng/ dự án Contract/ Prj number | E4: Tên dự án Project name | F4: Phân loại Classification | G4: Thời hạn hợp đồng Contract duration | I4: Giá trị hợp đồng (tạm tính/tháng) Total contract | J4: Tháng-Năm Month-Year | K4: KL nghiệm thu đã xuất hóa đơn/ giá trị tạm ứng Invoice amount/ Advance amount | L4: CĐT trừ tiền (Phạt, cung cấp thiếu...) Deduct | M4: Khoản đã thu Received amount | O4: Còn phải thu Remain amount | P4: Tình trạng dự án Project status | Q4: Payment document submit date/ Ngày gửi HSTT cho KH | R4: Số hóa đơn GTGT Invoice no. | S4: Điều khoản thanh toán /Nội dung TT Payment term /Content payment | T4: Tần suất thanh toán/ Payment frequency | U4: Thời gian dự kiến phát hành hóa đơn/ Est. issuing invoice | V4: Contract status/ (Yes/ Pending/NA) | W4: Ghi chú Remark
G5: Từ From | H5: Đến To | M5: Số tiền Amount | N5: Ngày thu Received date

Sheet Status
E1: BÁO CÁO TÌNH TRẠNG DOANH THU
E2: STATUS OF TURNOVER REPORT
E3: =YEAR(TODAY())
C4: Reviewed date: | D4: =TODAY() | G4: VND | H4: Ratio (%)
B5: A. Tổng giá trị còn lại các dự án đã ký hợp đồng đang thực hiện chưa thanh toán Value of ongoing projects | G5: =SUMIF(DATA!$P:$P,"Ongoing",DATA!$I:$I)
A6: Sent | B6: B. Tổng giá trị đã thực hiện xong, đợi thanh toán Value of waiting for payment projects | G6: =SUM(G7:G10) | H6: =G6/G13
C7: Giá trị đợi thanh toán đã quá thời hạn (các dự án đã gửi hồ sơ thanh toán cho KH) Waiting for payment out time (submitted the document payment to clients ) | G7: =SUMIF(DATA!$P:$P,"Waiting for payment out time",DATA!$O:$O) | H7: =G7/G13
C8: Giá trị đợi thanh toán trong thời hạn (các dự án đã gửi hồ sơ thanh toán cho KH) Waiting for payment in time (submitted the document payment to clients ) | G8: =SUMIF(DATA!$P:$P,"Waiting for payment in time",DATA!$O:$O) | H8: =G8/G13
C9: Giá trị đợi thanh toán (các dự án đã xong, đã gửi bản nháp hóa đơn/ Hồ sơ nghiệm thu cho KH & đang chờ KH xác nhận để gửi hồ sơ thanh toán chính thức) Pending Payment (work done & sent the draft invoice/ Work completion for checking & waiting client's confirmation) | G9: =SUMIF(DATA!$P:$P,"Pending Payment",DATA!$I:$I) | H9: =G9/G13
C10: Giá trị thanh toán thiếu (khoản "còn phải thu": Bảo hành, Xử lý bồi thường, KH giữ lại,...) Total remaining debt (Warranty, Compensation amount,...) | G10: =SUMIF(DATA!$P:$P,"Remaining",DATA!$I:$I) | H10: =G10/G13
B11: C. Tổng giá trị dự án triển khai chậm hoặc hoàn tất hồ sơ chậm Delay amount | G11: =SUMIF(DATA!$P:$P,"Delay",DATA!$I:$I) | H11: =G11/G13
A12: Y | B12: D. Tổng giá trị các dự án KH phạt vi phạm Penalty amount in year | G12: =SUMIFS(DATA!L:L,DATA!J:J,">="&DATE(Status!E3,1,1),DATA!J:J,"<="&DATE(Status!E3,12,31)) | H12: =G12/G13
A13: Y | B13: E. Giá trị đã thu các dự án trong năm Revenue of done job in year | G13: =SUMIFS(DATA!M:M,DATA!N:N,">="&DATE(Status!E3,1,1),DATA!N:N,"<="&DATE(Status!E3,12,31)) | H13: =G13/G13
G14: =PlanActual!P1009
G15: =G13-G14 | H15: Diff

Sheet PlanActual
I1: KẾ HOẠCH & THỰC TẾ DOANH THU TRONG NĂM | P1: Prepared by Nguyễn Thị Thu Hằng
H2: YEAR: | I2: =YEAR(TODAY()) | O2: Date: | P2: =TODAY()
A4: No | B4: Tên Khách hàng Client Name | D4: 1 | E4: 2 | F4: 3 | G4: 4 | H4: 5 | I4: 6 | J4: 7 | K4: 8 | L4: 9 | M4: 10 | N4: 11 | O4: 12 | P4: Total | Q4: Ratio
A5: Trung gian tính ngày cuối của tháng | D5: 31 | E5: =DAY(EOMONTH(DATE(I2,E4,1),0)) | F5: 31 | G5: 30 | H5: 31 | I5: 30 | J5: 31 | K5: 31 | L5: 30 | M5: 31 | N5: 30 | O5: 31
A6: 1 | B6: VNPT IDC - NAM THANG LONG(Inactive) | C6: Kế hoạch | D6: =SUMIFS(DATA!$I:$I,DATA!$C:$C,$B6,DATA!$J:$J,">="&DATE($I$2,D$4,1),DATA!$J:$J,"<="&DATE($I$2,D$4,D$5)) | E6: =SUMIFS(DATA!$I:$I,DATA!$C:$C,$B6,DATA!$J:$J,">="&DATE($I$2,E$4,1),DATA!$J:$J,"<="&DATE($I$2,E$4,E$5)) | F6: =SUMIFS(DATA!$I:$I,DATA!$C:$C,$B6,DATA!$J:$J,">="&DATE($I$2,F$4,1),DATA!$J:$J,"<="&DATE($I$2,F$4,F$5)) | G6: =SUMIFS(DATA!$I:$I,DATA!$C:$C,$B6,DATA!$J:$J,">="&DATE($I$2,G$4,1),DATA!$J:$J,"<="&DATE($I$2,G$4,G$5)) | H6: =SUMIFS(DATA!$I:$I,DATA!$C:$C,$B6,DATA!$J:$J,">="&DATE($I$2,H$4,1),DATA!$J:$J,"<="&DATE($I$2,H$4,H$5)) | I6: =SUMIFS(DATA!$I:$I,DATA!$C:$C,$B6,DATA!$J:$J,">="&DATE($I$2,I$4,1),DATA!$J:$J,"<="&DATE($I$2,I$4,I$5)) | J6: =SUMIFS(DATA!$I:$I,DATA!$C:$C,$B6,DATA!$J:$J,">="&DATE($I$2,J$4,1),DATA!$J:$J,"<="&DATE($I$2,J$4,J$5)) | K6: =SUMIFS(DATA!$I:$I,DATA!$C:$C,$B6,DATA!$J:$J,">="&DATE($I$2,K$4,1),DATA!$J:$J,"<="&DATE($I$2,K$4,K$5)) | ... O6: =SUMIFS(DATA!$I:$I,DATA!$C:$C,$B6,DATA!$J:$J,">="&DATE($I$2,O$4,1),DATA!$J:$J,"<="&DATE($I$2,O$4,O$5)) | P6: =SUM(D6:O6)
C7: Thực tế | D7: =SUMIFS(DATA!$M:$M,DATA!$C:$C,$B6,DATA!$N:$N,">="&DATE($I$2,D$4,1),DATA!$N:$N,"<="&DATE($I$2,D$4,D$5)) | E7: =SUMIFS(DATA!$M:$M,DATA!$C:$C,$B6,DATA!$N:$N,">="&DATE($I$2,E$4,1),DATA!$N:$N,"<="&DATE($I$2,E$4,E$5)) | F7: =SUMIFS(DATA!$M:$M,DATA!$C:$C,$B6,DATA!$N:$N,">="&DATE($I$2,F$4,1),DATA!$N:$N,"<="&DATE($I$2,F$4,F$5)) | G7: =SUMIFS(DATA!$M:$M,DATA!$C:$C,$B6,DATA!$N:$N,">="&DATE($I$2,G$4,1),DATA!$N:$N,"<="&DATE($I$2,G$4,G$5)) | H7: =SUMIFS(DATA!$M:$M,DATA!$C:$C,$B6,DATA!$N:$N,">="&DATE($I$2,H$4,1),DATA!$N:$N,"<="&DATE($I$2,H$4,H$5)) | I7: =SUMIFS(DATA!$M:$M,DATA!$C:$C,$B6,DATA!$N:$N,">="&DATE($I$2,I$4,1),DATA!$N:$N,"<="&DATE($I$2,I$4,I$5)) | J7: =SUMIFS(DATA!$M:$M,DATA!$C:$C,$B6,DATA!$N:$N,">="&DATE($I$2,J$4,1),DATA!$N:$N,"<="&DATE($I$2,J$4,J$5)) | K7: =SUMIFS(DATA!$M:$M,DATA!$C:$C,$B6,DATA!$N:$N,">="&DATE($I$2,K$4,1),DATA!$N:$N,"<="&DATE($I$2,K$4,K$5)) | ... O7: =SUMIFS(DATA!$M:$M,DATA!$C:$C,$B6,DATA!$N:$N,">="&DATE($I$2,O$4,1),DATA!$N:$N,"<="&DATE($I$2,O$4,O$5)) | P7: =SUM(D7:O7)
A8: 2 | B8: EMBASSY OF AUSTRALIA | C8: Kế hoạch | D8: =SUMIFS(DATA!$I:$I,DATA!$C:$C,$B8,DATA!$J:$J,">="&DATE($I$2,D$4,1),DATA!$J:$J,"<="&DATE($I$2,D$4,D$5)) | E8: =SUMIFS(DATA!$I:$I,DATA!$C:$C,$B8,DATA!$J:$J,">="&DATE($I$2,E$4,1),DATA!$J:$J,"<="&DATE($I$2,E$4,E$5)) | F8: =SUMIFS(DATA!$I:$I,DATA!$C:$C,$B8,DATA!$J:$J,">="&DATE($I$2,F$4,1),DATA!$J:$J,"<="&DATE($I$2,F$4,F$5)) | G8: =SUMIFS(DATA!$I:$I,DATA!$C:$C,$B8,DATA!$J:$J,">="&DATE($I$2,G$4,1),DATA!$J:$J,"<="&DATE($I$2,G$4,G$5)) | H8: =SUMIFS(DATA!$I:$I,DATA!$C:$C,$B8,DATA!$J:$J,">="&DATE($I$2,H$4,1),DATA!$J:$J,"<="&DATE($I$2,H$4,H$5)) | I8: =SUMIFS(DATA!$I:$I,DATA!$C:$C,$B8,DATA!$J:$J,">="&DATE($I$2,I$4,1),DATA!$J:$J,"<="&DATE($I$2,I$4,I$5)) | J8: =SUMIFS(DATA!$I:$I,DATA!$C:$C,$B8,DATA!$J:$J,">="&DATE($I$2,J$4,1),DATA!$J:$J,"<="&DATE($I$2,J$4,J$5)) | K8: =SUMIFS(DATA!$I:$I,DATA!$C:$C,$B8,DATA!$J:$J,">="&DATE($I$2,K$4,1),DATA!$J:$J,"<="&DATE($I$2,K$4,K$5)) | ... O8: =SUMIFS(DATA!$I:$I,DATA!$C:$C,$B8,DATA!$J:$J,">="&DATE($I$2,O$4,1),DATA!$J:$J,"<="&DATE($I$2,O$4,O$5)) | P8: =SUM(D8:O8)
C9: Thực tế | D9: =SUMIFS(DATA!$M:$M,DATA!$C:$C,$B8,DATA!$N:$N,">="&DATE($I$2,D$4,1),DATA!$N:$N,"<="&DATE($I$2,D$4,D$5)) | E9: =SUMIFS(DATA!$M:$M,DATA!$C:$C,$B8,DATA!$N:$N,">="&DATE($I$2,E$4,1),DATA!$N:$N,"<="&DATE($I$2,E$4,E$5)) | F9: =SUMIFS(DATA!$M:$M,DATA!$C:$C,$B8,DATA!$N:$N,">="&DATE($I$2,F$4,1),DATA!$N:$N,"<="&DATE($I$2,F$4,F$5)) | G9: =SUMIFS(DATA!$M:$M,DATA!$C:$C,$B8,DATA!$N:$N,">="&DATE($I$2,G$4,1),DATA!$N:$N,"<="&DATE($I$2,G$4,G$5)) | H9: =SUMIFS(DATA!$M:$M,DATA!$C:$C,$B8,DATA!$N:$N,">="&DATE($I$2,H$4,1),DATA!$N:$N,"<="&DATE($I$2,H$4,H$5)) | I9: =SUMIFS(DATA!$M:$M,DATA!$C:$C,$B8,DATA!$N:$N,">="&DATE($I$2,I$4,1),DATA!$N:$N,"<="&DATE($I$2,I$4,I$5)) | J9: =SUMIFS(DATA!$M:$M,DATA!$C:$C,$B8,DATA!$N:$N,">="&DATE($I$2,J$4,1),DATA!$N:$N,"<="&DATE($I$2,J$4,J$5)) | K9: =SUMIFS(DATA!$M:$M,DATA!$C:$C,$B8,DATA!$N:$N,">="&DATE($I$2,K$4,1),DATA!$N:$N,"<="&DATE($I$2,K$4,K$5)) | ... O9: =SUMIFS(DATA!$M:$M,DATA!$C:$C,$B8,DATA!$N:$N,">="&DATE($I$2,O$4,1),DATA!$N:$N,"<="&DATE($I$2,O$4,O$5)) | P9: =SUM(D9:O9)
A10: 3 | B10: YAMAHA MOTOR VIETNAM | C10: Kế hoạch | D10: =SUMIFS(DATA!$I:$I,DATA!$C:$C,$B10,DATA!$J:$J,">="&DATE($I$2,D$4,1),DATA!$J:$J,"<="&DATE($I$2,D$4,D$5)) | E10: =SUMIFS(DATA!$I:$I,DATA!$C:$C,$B10,DATA!$J:$J,">="&DATE($I$2,E$4,1),DATA!$J:$J,"<="&DATE($I$2,E$4,E$5)) | F10: =SUMIFS(DATA!$I:$I,DATA!$C:$C,$B10,DATA!$J:$J,">="&DATE($I$2,F$4,1),DATA!$J:$J,"<="&DATE($I$2,F$4,F$5)) | G10: =SUMIFS(DATA!$I:$I,DATA!$C:$C,$B10,DATA!$J:$J,">="&DATE($I$2,G$4,1),DATA!$J:$J,"<="&DATE($I$2,G$4,G$5)) | H10: =SUMIFS(DATA!$I:$I,DATA!$C:$C,$B10,DATA!$J:$J,">="&DATE($I$2,H$4,1),DATA!$J:$J,"<="&DATE($I$2,H$4,H$5)) | I10: =SUMIFS(DATA!$I:$I,DATA!$C:$C,$B10,DATA!$J:$J,">="&DATE($I$2,I$4,1),DATA!$J:$J,"<="&DATE($I$2,I$4,I$5)) | J10: =SUMIFS(DATA!$I:$I,DATA!$C:$C,$B10,DATA!$J:$J,">="&DATE($I$2,J$4,1),DATA!$J:$J,"<="&DATE($I$2,J$4,J$5)) | K10: =SUMIFS(DATA!$I:$I,DATA!$C:$C,$B10,DATA!$J:$J,">="&DATE($I$2,K$4,1),DATA!$J:$J,"<="&DATE($I$2,K$4,K$5)) | ... O10: =SUMIFS(DATA!$I:$I,DATA!$C:$C,$B10,DATA!$J:$J,">="&DATE($I$2,O$4,1),DATA!$J:$J,"<="&DATE($I$2,O$4,O$5)) | P10: =SUM(D10:O10)
C11: Thực tế | D11: =SUMIFS(DATA!$M:$M,DATA!$C:$C,$B10,DATA!$N:$N,">="&DATE($I$2,D$4,1),DATA!$N:$N,"<="&DATE($I$2,D$4,D$5)) | E11: =SUMIFS(DATA!$M:$M,DATA!$C:$C,$B10,DATA!$N:$N,">="&DATE($I$2,E$4,1),DATA!$N:$N,"<="&DATE($I$2,E$4,E$5)) | F11: =SUMIFS(DATA!$M:$M,DATA!$C:$C,$B10,DATA!$N:$N,">="&DATE($I$2,F$4,1),DATA!$N:$N,"<="&DATE($I$2,F$4,F$5)) | G11: =SUMIFS(DATA!$M:$M,DATA!$C:$C,$B10,DATA!$N:$N,">="&DATE($I$2,G$4,1),DATA!$N:$N,"<="&DATE($I$2,G$4,G$5)) | H11: =SUMIFS(DATA!$M:$M,DATA!$C:$C,$B10,DATA!$N:$N,">="&DATE($I$2,H$4,1),DATA!$N:$N,"<="&DATE($I$2,H$4,H$5)) | I11: =SUMIFS(DATA!$M:$M,DATA!$C:$C,$B10,DATA!$N:$N,">="&DATE($I$2,I$4,1),DATA!$N:$N,"<="&DATE($I$2,I$4,I$5)) | J11: =SUMIFS(DATA!$M:$M,DATA!$C:$C,$B10,DATA!$N:$N,">="&DATE($I$2,J$4,1),DATA!$N:$N,"<="&DATE($I$2,J$4,J$5)) | K11: =SUMIFS(DATA!$M:$M,DATA!$C:$C,$B10,DATA!$N:$N,">="&DATE($I$2,K$4,1),DATA!$N:$N,"<="&DATE($I$2,K$4,K$5)) | ... O11: =SUMIFS(DATA!$M:$M,DATA!$C:$C,$B10,DATA!$N:$N,">="&DATE($I$2,O$4,1),DATA!$N:$N,"<="&DATE($I$2,O$4,O$5)) | P11: =SUM(D11:O11)
A12: 4 | B12: CÔNG TY TNHH THÁP LÁNG HẠ | C12: Kế hoạch | D12: =SUMIFS(DATA!$I:$I,DATA!$C:$C,$B12,DATA!$J:$J,">="&DATE($I$2,D$4,1),DATA!$J:$J,"<="&DATE($I$2,D$4,D$5)) | E12: =SUMIFS(DATA!$I:$I,DATA!$C:$C,$B12,DATA!$J:$J,">="&DATE($I$2,E$4,1),DATA!$J:$J,"<="&DATE($I$2,E$4,E$5)) | F12: =SUMIFS(DATA!$I:$I,DATA!$C:$C,$B12,DATA!$J:$J,">="&DATE($I$2,F$4,1),DATA!$J:$J,"<="&DATE($I$2,F$4,F$5)) | G12: =SUMIFS(DATA!$I:$I,DATA!$C:$C,$B12,DATA!$J:$J,">="&DATE($I$2,G$4,1),DATA!$J:$J,"<="&DATE($I$2,G$4,G$5)) | H12: =SUMIFS(DATA!$I:$I,DATA!$C:$C,$B12,DATA!$J:$J,">="&DATE($I$2,H$4,1),DATA!$J:$J,"<="&DATE($I$2,H$4,H$5)) | I12: =SUMIFS(DATA!$I:$I,DATA!$C:$C,$B12,DATA!$J:$J,">="&DATE($I$2,I$4,1),DATA!$J:$J,"<="&DATE($I$2,I$4,I$5)) | J12: =SUMIFS(DATA!$I:$I,DATA!$C:$C,$B12,DATA!$J:$J,">="&DATE($I$2,J$4,1),DATA!$J:$J,"<="&DATE($I$2,J$4,J$5)) | K12: =SUMIFS(DATA!$I:$I,DATA!$C:$C,$B12,DATA!$J:$J,">="&DATE($I$2,K$4,1),DATA!$J:$J,"<="&DATE($I$2,K$4,K$5)) | ... O12: =SUMIFS(DATA!$I:$I,DATA!$C:$C,$B12,DATA!$J:$J,">="&DATE($I$2,O$4,1),DATA!$J:$J,"<="&DATE($I$2,O$4,O$5)) | P12: =SUM(D12:O12)
C13: Thực tế | D13: =SUMIFS(DATA!$M:$M,DATA!$C:$C,$B12,DATA!$N:$N,">="&DATE($I$2,D$4,1),DATA!$N:$N,"<="&DATE($I$2,D$4,D$5)) | E13: =SUMIFS(DATA!$M:$M,DATA!$C:$C,$B12,DATA!$N:$N,">="&DATE($I$2,E$4,1),DATA!$N:$N,"<="&DATE($I$2,E$4,E$5)) | F13: =SUMIFS(DATA!$M:$M,DATA!$C:$C,$B12,DATA!$N:$N,">="&DATE($I$2,F$4,1),DATA!$N:$N,"<="&DATE($I$2,F$4,F$5)) | G13: =SUMIFS(DATA!$M:$M,DATA!$C:$C,$B12,DATA!$N:$N,">="&DATE($I$2,G$4,1),DATA!$N:$N,"<="&DATE($I$2,G$4,G$5)) | H13: =SUMIFS(DATA!$M:$M,DATA!$C:$C,$B12,DATA!$N:$N,">="&DATE($I$2,H$4,1),DATA!$N:$N,"<="&DATE($I$2,H$4,H$5)) | I13: =SUMIFS(DATA!$M:$M,DATA!$C:$C,$B12,DATA!$N:$N,">="&DATE($I$2,I$4,1),DATA!$N:$N,"<="&DATE($I$2,I$4,I$5)) | J13: =SUMIFS(DATA!$M:$M,DATA!$C:$C,$B12,DATA!$N:$N,">="&DATE($I$2,J$4,1),DATA!$N:$N,"<="&DATE($I$2,J$4,J$5)) | K13: =SUMIFS(DATA!$M:$M,DATA!$C:$C,$B12,DATA!$N:$N,">="&DATE($I$2,K$4,1),DATA!$N:$N,"<="&DATE($I$2,K$4,K$5)) | ... O13: =SUMIFS(DATA!$M:$M,DATA!$C:$C,$B12,DATA!$N:$N,">="&DATE($I$2,O$4,1),DATA!$N:$N,"<="&DATE($I$2,O$4,O$5)) | P13: =SUM(D13:O13)
A14: 5 | B14: TRUNG TÂM HẠ TẦNG IDC - CÔNG TY CÔNG NGHỆ THÔNG TIN VNPT (VNPT-IT) | C14: Kế hoạch | D14: =SUMIFS(DATA!$I:$I,DATA!$C:$C,$B14,DATA!$J:$J,">="&DATE($I$2,D$4,1),DATA!$J:$J,"<="&DATE($I$2,D$4,D$5)) | E14: =SUMIFS(DATA!$I:$I,DATA!$C:$C,$B14,DATA!$J:$J,">="&DATE($I$2,E$4,1),DATA!$J:$J,"<="&DATE($I$2,E$4,E$5)) | F14: =SUMIFS(DATA!$I:$I,DATA!$C:$C,$B14,DATA!$J:$J,">="&DATE($I$2,F$4,1),DATA!$J:$J,"<="&DATE($I$2,F$4,F$5)) | G14: =SUMIFS(DATA!$I:$I,DATA!$C:$C,$B14,DATA!$J:$J,">="&DATE($I$2,G$4,1),DATA!$J:$J,"<="&DATE($I$2,G$4,G$5)) | H14: =SUMIFS(DATA!$I:$I,DATA!$C:$C,$B14,DATA!$J:$J,">="&DATE($I$2,H$4,1),DATA!$J:$J,"<="&DATE($I$2,H$4,H$5)) | I14: =SUMIFS(DATA!$I:$I,DATA!$C:$C,$B14,DATA!$J:$J,">="&DATE($I$2,I$4,1),DATA!$J:$J,"<="&DATE($I$2,I$4,I$5)) | J14: =SUMIFS(DATA!$I:$I,DATA!$C:$C,$B14,DATA!$J:$J,">="&DATE($I$2,J$4,1),DATA!$J:$J,"<="&DATE($I$2,J$4,J$5)) | K14: =SUMIFS(DATA!$I:$I,DATA!$C:$C,$B14,DATA!$J:$J,">="&DATE($I$2,K$4,1),DATA!$J:$J,"<="&DATE($I$2,K$4,K$5)) | ... O14: =SUMIFS(DATA!$I:$I,DATA!$C:$C,$B14,DATA!$J:$J,">="&DATE($I$2,O$4,1),DATA!$J:$J,"<="&DATE($I$2,O$4,O$5)) | P14: =SUM(D14:O14)
C15: Thực tế | D15: =SUMIFS(DATA!$M:$M,DATA!$C:$C,$B14,DATA!$N:$N,">="&DATE($I$2,D$4,1),DATA!$N:$N,"<="&DATE($I$2,D$4,D$5)) | E15: =SUMIFS(DATA!$M:$M,DATA!$C:$C,$B14,DATA!$N:$N,">="&DATE($I$2,E$4,1),DATA!$N:$N,"<="&DATE($I$2,E$4,E$5)) | F15: =SUMIFS(DATA!$M:$M,DATA!$C:$C,$B14,DATA!$N:$N,">="&DATE($I$2,F$4,1),DATA!$N:$N,"<="&DATE($I$2,F$4,F$5)) | G15: =SUMIFS(DATA!$M:$M,DATA!$C:$C,$B14,DATA!$N:$N,">="&DATE($I$2,G$4,1),DATA!$N:$N,"<="&DATE($I$2,G$4,G$5)) | H15: =SUMIFS(DATA!$M:$M,DATA!$C:$C,$B14,DATA!$N:$N,">="&DATE($I$2,H$4,1),DATA!$N:$N,"<="&DATE($I$2,H$4,H$5)) | I15: =SUMIFS(DATA!$M:$M,DATA!$C:$C,$B14,DATA!$N:$N,">="&DATE($I$2,I$4,1),DATA!$N:$N,"<="&DATE($I$2,I$4,I$5)) | J15: =SUMIFS(DATA!$M:$M,DATA!$C:$C,$B14,DATA!$N:$N,">="&DATE($I$2,J$4,1),DATA!$N:$N,"<="&DATE($I$2,J$4,J$5)) | K15: =SUMIFS(DATA!$M:$M,DATA!$C:$C,$B14,DATA!$N:$N,">="&DATE($I$2,K$4,1),DATA!$N:$N,"<="&DATE($I$2,K$4,K$5)) | ... O15: =SUMIFS(DATA!$M:$M,DATA!$C:$C,$B14,DATA!$N:$N,">="&DATE($I$2,O$4,1),DATA!$N:$N,"<="&DATE($I$2,O$4,O$5)) | P15: =SUM(D15:O15)
A16: 6 | B16: CRYSTAL MARTIN VIETNAM | C16: Kế hoạch | D16: =SUMIFS(DATA!$I:$I,DATA!$C:$C,$B16,DATA!$J:$J,">="&DATE($I$2,D$4,1),DATA!$J:$J,"<="&DATE($I$2,D$4,D$5)) | E16: =SUMIFS(DATA!$I:$I,DATA!$C:$C,$B16,DATA!$J:$J,">="&DATE($I$2,E$4,1),DATA!$J:$J,"<="&DATE($I$2,E$4,E$5)) | F16: =SUMIFS(DATA!$I:$I,DATA!$C:$C,$B16,DATA!$J:$J,">="&DATE($I$2,F$4,1),DATA!$J:$J,"<="&DATE($I$2,F$4,F$5)) | G16: =SUMIFS(DATA!$I:$I,DATA!$C:$C,$B16,DATA!$J:$J,">="&DATE($I$2,G$4,1),DATA!$J:$J,"<="&DATE($I$2,G$4,G$5)) | H16: =SUMIFS(DATA!$I:$I,DATA!$C:$C,$B16,DATA!$J:$J,">="&DATE($I$2,H$4,1),DATA!$J:$J,"<="&DATE($I$2,H$4,H$5)) | I16: =SUMIFS(DATA!$I:$I,DATA!$C:$C,$B16,DATA!$J:$J,">="&DATE($I$2,I$4,1),DATA!$J:$J,"<="&DATE($I$2,I$4,I$5)) | J16: =SUMIFS(DATA!$I:$I,DATA!$C:$C,$B16,DATA!$J:$J,">="&DATE($I$2,J$4,1),DATA!$J:$J,"<="&DATE($I$2,J$4,J$5)) | K16: =SUMIFS(DATA!$I:$I,DATA!$C:$C,$B16,DATA!$J:$J,">="&DATE($I$2,K$4,1),DATA!$J:$J,"<="&DATE($I$2,K$4,K$5)) | ... O16: =SUMIFS(DATA!$I:$I,DATA!$C:$C,$B16,DATA!$J:$J,">="&DATE($I$2,O$4,1),DATA!$J:$J,"<="&DATE($I$2,O$4,O$5)) | P16: =SUM(D16:O16)
C17: Thực tế | D17: =SUMIFS(DATA!$M:$M,DATA!$C:$C,$B16,DATA!$N:$N,">="&DATE($I$2,D$4,1),DATA!$N:$N,"<="&DATE($I$2,D$4,D$5)) | E17: =SUMIFS(DATA!$M:$M,DATA!$C:$C,$B16,DATA!$N:$N,">="&DATE($I$2,E$4,1),DATA!$N:$N,"<="&DATE($I$2,E$4,E$5)) | F17: =SUMIFS(DATA!$M:$M,DATA!$C:$C,$B16,DATA!$N:$N,">="&DATE($I$2,F$4,1),DATA!$N:$N,"<="&DATE($I$2,F$4,F$5)) | G17: =SUMIFS(DATA!$M:$M,DATA!$C:$C,$B16,DATA!$N:$N,">="&DATE($I$2,G$4,1),DATA!$N:$N,"<="&DATE($I$2,G$4,G$5)) | H17: =SUMIFS(DATA!$M:$M,DATA!$C:$C,$B16,DATA!$N:$N,">="&DATE($I$2,H$4,1),DATA!$N:$N,"<="&DATE($I$2,H$4,H$5)) | I17: =SUMIFS(DATA!$M:$M,DATA!$C:$C,$B16,DATA!$N:$N,">="&DATE($I$2,I$4,1),DATA!$N:$N,"<="&DATE($I$2,I$4,I$5)) | J17: =SUMIFS(DATA!$M:$M,DATA!$C:$C,$B16,DATA!$N:$N,">="&DATE($I$2,J$4,1),DATA!$N:$N,"<="&DATE($I$2,J$4,J$5)) | K17: =SUMIFS(DATA!$M:$M,DATA!$C:$C,$B16,DATA!$N:$N,">="&DATE($I$2,K$4,1),DATA!$N:$N,"<="&DATE($I$2,K$4,K$5)) | ... O17: =SUMIFS(DATA!$M:$M,DATA!$C:$C,$B16,DATA!$N:$N,">="&DATE($I$2,O$4,1),DATA!$N:$N,"<="&DATE($I$2,O$4,O$5)) | P17: =SUM(D17:O17)
A18: 7 | B18: RMIT UNIVERSITY | C18: Kế hoạch | D18: =SUMIFS(DATA!$I:$I,DATA!$C:$C,$B18,DATA!$J:$J,">="&DATE($I$2,D$4,1),DATA!$J:$J,"<="&DATE($I$2,D$4,D$5)) | E18: =SUMIFS(DATA!$I:$I,DATA!$C:$C,$B18,DATA!$J:$J,">="&DATE($I$2,E$4,1),DATA!$J:$J,"<="&DATE($I$2,E$4,E$5)) | F18: =SUMIFS(DATA!$I:$I,DATA!$C:$C,$B18,DATA!$J:$J,">="&DATE($I$2,F$4,1),DATA!$J:$J,"<="&DATE($I$2,F$4,F$5)) | G18: =SUMIFS(DATA!$I:$I,DATA!$C:$C,$B18,DATA!$J:$J,">="&DATE($I$2,G$4,1),DATA!$J:$J,"<="&DATE($I$2,G$4,G$5)) | H18: =SUMIFS(DATA!$I:$I,DATA!$C:$C,$B18,DATA!$J:$J,">="&DATE($I$2,H$4,1),DATA!$J:$J,"<="&DATE($I$2,H$4,H$5)) | I18: =SUMIFS(DATA!$I:$I,DATA!$C:$C,$B18,DATA!$J:$J,">="&DATE($I$2,I$4,1),DATA!$J:$J,"<="&DATE($I$2,I$4,I$5)) | J18: =SUMIFS(DATA!$I:$I,DATA!$C:$C,$B18,DATA!$J:$J,">="&DATE($I$2,J$4,1),DATA!$J:$J,"<="&DATE($I$2,J$4,J$5)) | K18: =SUMIFS(DATA!$I:$I,DATA!$C:$C,$B18,DATA!$J:$J,">="&DATE($I$2,K$4,1),DATA!$J:$J,"<="&DATE($I$2,K$4,K$5)) | ... O18: =SUMIFS(DATA!$I:$I,DATA!$C:$C,$B18,DATA!$J:$J,">="&DATE($I$2,O$4,1),DATA!$J:$J,"<="&DATE($I$2,O$4,O$5)) | P18: =SUM(D18:O18)
C19: Thực tế | D19: =SUMIFS(DATA!$M:$M,DATA!$C:$C,$B18,DATA!$N:$N,">="&DATE($I$2,D$4,1),DATA!$N:$N,"<="&DATE($I$2,D$4,D$5)) | E19: =SUMIFS(DATA!$M:$M,DATA!$C:$C,$B18,DATA!$N:$N,">="&DATE($I$2,E$4,1),DATA!$N:$N,"<="&DATE($I$2,E$4,E$5)) | F19: =SUMIFS(DATA!$M:$M,DATA!$C:$C,$B18,DATA!$N:$N,">="&DATE($I$2,F$4,1),DATA!$N:$N,"<="&DATE($I$2,F$4,F$5)) | G19: =SUMIFS(DATA!$M:$M,DATA!$C:$C,$B18,DATA!$N:$N,">="&DATE($I$2,G$4,1),DATA!$N:$N,"<="&DATE($I$2,G$4,G$5)) | H19: =SUMIFS(DATA!$M:$M,DATA!$C:$C,$B18,DATA!$N:$N,">="&DATE($I$2,H$4,1),DATA!$N:$N,"<="&DATE($I$2,H$4,H$5)) | I19: =SUMIFS(DATA!$M:$M,DATA!$C:$C,$B18,DATA!$N:$N,">="&DATE($I$2,I$4,1),DATA!$N:$N,"<="&DATE($I$2,I$4,I$5)) | J19: =SUMIFS(DATA!$M:$M,DATA!$C:$C,$B18,DATA!$N:$N,">="&DATE($I$2,J$4,1),DATA!$N:$N,"<="&DATE($I$2,J$4,J$5)) | K19: =SUMIFS(DATA!$M:$M,DATA!$C:$C,$B18,DATA!$N:$N,">="&DATE($I$2,K$4,1),DATA!$N:$N,"<="&DATE($I$2,K$4,K$5)) | ... O19: =SUMIFS(DATA!$M:$M,DATA!$C:$C,$B18,DATA!$N:$N,">="&DATE($I$2,O$4,1),DATA!$N:$N,"<="&DATE($I$2,O$4,O$5)) | P19: =SUM(D19:O19)
A20: 8 | B20: GOLDEN PALACE MỄ TRÌ | C20: Kế hoạch | D20: =SUMIFS(DATA!$I:$I,DATA!$C:$C,$B20,DATA!$J:$J,">="&DATE($I$2,D$4,1),DATA!$J:$J,"<="&DATE($I$2,D$4,D$5)) | E20: =SUMIFS(DATA!$I:$I,DATA!$C:$C,$B20,DATA!$J:$J,">="&DATE($I$2,E$4,1),DATA!$J:$J,"<="&DATE($I$2,E$4,E$5)) | F20: =SUMIFS(DATA!$I:$I,DATA!$C:$C,$B20,DATA!$J:$J,">="&DATE($I$2,F$4,1),DATA!$J:$J,"<="&DATE($I$2,F$4,F$5)) | G20: =SUMIFS(DATA!$I:$I,DATA!$C:$C,$B20,DATA!$J:$J,">="&DATE($I$2,G$4,1),DATA!$J:$J,"<="&DATE($I$2,G$4,G$5)) | H20: =SUMIFS(DATA!$I:$I,DATA!$C:$C,$B20,DATA!$J:$J,">="&DATE($I$2,H$4,1),DATA!$J:$J,"<="&DATE($I$2,H$4,H$5)) | I20: =SUMIFS(DATA!$I:$I,DATA!$C:$C,$B20,DATA!$J:$J,">="&DATE($I$2,I$4,1),DATA!$J:$J,"<="&DATE($I$2,I$4,I$5)) | J20: =SUMIFS(DATA!$I:$I,DATA!$C:$C,$B20,DATA!$J:$J,">="&DATE($I$2,J$4,1),DATA!$J:$J,"<="&DATE($I$2,J$4,J$5)) | K20: =SUMIFS(DATA!$I:$I,DATA!$C:$C,$B20,DATA!$J:$J,">="&DATE($I$2,K$4,1),DATA!$J:$J,"<="&DATE($I$2,K$4,K$5)) | ... O20: =SUMIFS(DATA!$I:$I,DATA!$C:$C,$B20,DATA!$J:$J,">="&DATE($I$2,O$4,1),DATA!$J:$J,"<="&DATE($I$2,O$4,O$5)) | P20: =SUM(D20:O20)
C21: Thực tế | D21: =SUMIFS(DATA!$M:$M,DATA!$C:$C,$B20,DATA!$N:$N,">="&DATE($I$2,D$4,1),DATA!$N:$N,"<="&DATE($I$2,D$4,D$5)) | E21: =SUMIFS(DATA!$M:$M,DATA!$C:$C,$B20,DATA!$N:$N,">="&DATE($I$2,E$4,1),DATA!$N:$N,"<="&DATE($I$2,E$4,E$5)) | F21: =SUMIFS(DATA!$M:$M,DATA!$C:$C,$B20,DATA!$N:$N,">="&DATE($I$2,F$4,1),DATA!$N:$N,"<="&DATE($I$2,F$4,F$5)) | G21: =SUMIFS(DATA!$M:$M,DATA!$C:$C,$B20,DATA!$N:$N,">="&DATE($I$2,G$4,1),DATA!$N:$N,"<="&DATE($I$2,G$4,G$5)) | H21: =SUMIFS(DATA!$M:$M,DATA!$C:$C,$B20,DATA!$N:$N,">="&DATE($I$2,H$4,1),DATA!$N:$N,"<="&DATE($I$2,H$4,H$5)) | I21: =SUMIFS(DATA!$M:$M,DATA!$C:$C,$B20,DATA!$N:$N,">="&DATE($I$2,I$4,1),DATA!$N:$N,"<="&DATE($I$2,I$4,I$5)) | J21: =SUMIFS(DATA!$M:$M,DATA!$C:$C,$B20,DATA!$N:$N,">="&DATE($I$2,J$4,1),DATA!$N:$N,"<="&DATE($I$2,J$4,J$5)) | K21: =SUMIFS(DATA!$M:$M,DATA!$C:$C,$B20,DATA!$N:$N,">="&DATE($I$2,K$4,1),DATA!$N:$N,"<="&DATE($I$2,K$4,K$5)) | ... O21: =SUMIFS(DATA!$M:$M,DATA!$C:$C,$B20,DATA!$N:$N,">="&DATE($I$2,O$4,1),DATA!$N:$N,"<="&DATE($I$2,O$4,O$5)) | P21: =SUM(D21:O21)
A22: 9 | B22: U.S. PEACE CORPS | C22: Kế hoạch | D22: =SUMIFS(DATA!$I:$I,DATA!$C:$C,$B22,DATA!$J:$J,">="&DATE($I$2,D$4,1),DATA!$J:$J,"<="&DATE($I$2,D$4,D$5)) | E22: =SUMIFS(DATA!$I:$I,DATA!$C:$C,$B22,DATA!$J:$J,">="&DATE($I$2,E$4,1),DATA!$J:$J,"<="&DATE($I$2,E$4,E$5)) | F22: =SUMIFS(DATA!$I:$I,DATA!$C:$C,$B22,DATA!$J:$J,">="&DATE($I$2,F$4,1),DATA!$J:$J,"<="&DATE($I$2,F$4,F$5)) | G22: =SUMIFS(DATA!$I:$I,DATA!$C:$C,$B22,DATA!$J:$J,">="&DATE($I$2,G$4,1),DATA!$J:$J,"<="&DATE($I$2,G$4,G$5)) | H22: =SUMIFS(DATA!$I:$I,DATA!$C:$C,$B22,DATA!$J:$J,">="&DATE($I$2,H$4,1),DATA!$J:$J,"<="&DATE($I$2,H$4,H$5)) | I22: =SUMIFS(DATA!$I:$I,DATA!$C:$C,$B22,DATA!$J:$J,">="&DATE($I$2,I$4,1),DATA!$J:$J,"<="&DATE($I$2,I$4,I$5)) | J22: =SUMIFS(DATA!$I:$I,DATA!$C:$C,$B22,DATA!$J:$J,">="&DATE($I$2,J$4,1),DATA!$J:$J,"<="&DATE($I$2,J$4,J$5)) | K22: =SUMIFS(DATA!$I:$I,DATA!$C:$C,$B22,DATA!$J:$J,">="&DATE($I$2,K$4,1),DATA!$J:$J,"<="&DATE($I$2,K$4,K$5)) | ... O22: =SUMIFS(DATA!$I:$I,DATA!$C:$C,$B22,DATA!$J:$J,">="&DATE($I$2,O$4,1),DATA!$J:$J,"<="&DATE($I$2,O$4,O$5)) | P22: =SUM(D22:O22)
C23: Thực tế | D23: =SUMIFS(DATA!$M:$M,DATA!$C:$C,$B22,DATA!$N:$N,">="&DATE($I$2,D$4,1),DATA!$N:$N,"<="&DATE($I$2,D$4,D$5)) | E23: =SUMIFS(DATA!$M:$M,DATA!$C:$C,$B22,DATA!$N:$N,">="&DATE($I$2,E$4,1),DATA!$N:$N,"<="&DATE($I$2,E$4,E$5)) | F23: =SUMIFS(DATA!$M:$M,DATA!$C:$C,$B22,DATA!$N:$N,">="&DATE($I$2,F$4,1),DATA!$N:$N,"<="&DATE($I$2,F$4,F$5)) | G23: =SUMIFS(DATA!$M:$M,DATA!$C:$C,$B22,DATA!$N:$N,">="&DATE($I$2,G$4,1),DATA!$N:$N,"<="&DATE($I$2,G$4,G$5)) | H23: =SUMIFS(DATA!$M:$M,DATA!$C:$C,$B22,DATA!$N:$N,">="&DATE($I$2,H$4,1),DATA!$N:$N,"<="&DATE($I$2,H$4,H$5)) | I23: =SUMIFS(DATA!$M:$M,DATA!$C:$C,$B22,DATA!$N:$N,">="&DATE($I$2,I$4,1),DATA!$N:$N,"<="&DATE($I$2,I$4,I$5)) | J23: =SUMIFS(DATA!$M:$M,DATA!$C:$C,$B22,DATA!$N:$N,">="&DATE($I$2,J$4,1),DATA!$N:$N,"<="&DATE($I$2,J$4,J$5)) | K23: =SUMIFS(DATA!$M:$M,DATA!$C:$C,$B22,DATA!$N:$N,">="&DATE($I$2,K$4,1),DATA!$N:$N,"<="&DATE($I$2,K$4,K$5)) | ... O23: =SUMIFS(DATA!$M:$M,DATA!$C:$C,$B22,DATA!$N:$N,">="&DATE($I$2,O$4,1),DATA!$N:$N,"<="&DATE($I$2,O$4,O$5)) | P23: =SUM(D23:O23)
A24: 10 | B24: DETECH TOWER II | C24: Kế hoạch | D24: =SUMIFS(DATA!$I:$I,DATA!$C:$C,$B24,DATA!$J:$J,">="&DATE($I$2,D$4,1),DATA!$J:$J,"<="&DATE($I$2,D$4,D$5)) | E24: =SUMIFS(DATA!$I:$I,DATA!$C:$C,$B24,DATA!$J:$J,">="&DATE($I$2,E$4,1),DATA!$J:$J,"<="&DATE($I$2,E$4,E$5)) | F24: =SUMIFS(DATA!$I:$I,DATA!$C:$C,$B24,DATA!$J:$J,">="&DATE($I$2,F$4,1),DATA!$J:$J,"<="&DATE($I$2,F$4,F$5)) | G24: =SUMIFS(DATA!$I:$I,DATA!$C:$C,$B24,DATA!$J:$J,">="&DATE($I$2,G$4,1),DATA!$J:$J,"<="&DATE($I$2,G$4,G$5)) | H24: =SUMIFS(DATA!$I:$I,DATA!$C:$C,$B24,DATA!$J:$J,">="&DATE($I$2,H$4,1),DATA!$J:$J,"<="&DATE($I$2,H$4,H$5)) | I24: =SUMIFS(DATA!$I:$I,DATA!$C:$C,$B24,DATA!$J:$J,">="&DATE($I$2,I$4,1),DATA!$J:$J,"<="&DATE($I$2,I$4,I$5)) | J24: =SUMIFS(DATA!$I:$I,DATA!$C:$C,$B24,DATA!$J:$J,">="&DATE($I$2,J$4,1),DATA!$J:$J,"<="&DATE($I$2,J$4,J$5)) | K24: =SUMIFS(DATA!$I:$I,DATA!$C:$C,$B24,DATA!$J:$J,">="&DATE($I$2,K$4,1),DATA!$J:$J,"<="&DATE($I$2,K$4,K$5)) | ... O24: =SUMIFS(DATA!$I:$I,DATA!$C:$C,$B24,DATA!$J:$J,">="&DATE($I$2,O$4,1),DATA!$J:$J,"<="&DATE($I$2,O$4,O$5)) | P24: =SUM(D24:O24)
C25: Thực tế | D25: =SUMIFS(DATA!$M:$M,DATA!$C:$C,$B24,DATA!$N:$N,">="&DATE($I$2,D$4,1),DATA!$N:$N,"<="&DATE($I$2,D$4,D$5)) | E25: =SUMIFS(DATA!$M:$M,DATA!$C:$C,$B24,DATA!$N:$N,">="&DATE($I$2,E$4,1),DATA!$N:$N,"<="&DATE($I$2,E$4,E$5)) | F25: =SUMIFS(DATA!$M:$M,DATA!$C:$C,$B24,DATA!$N:$N,">="&DATE($I$2,F$4,1),DATA!$N:$N,"<="&DATE($I$2,F$4,F$5)) | G25: =SUMIFS(DATA!$M:$M,DATA!$C:$C,$B24,DATA!$N:$N,">="&DATE($I$2,G$4,1),DATA!$N:$N,"<="&DATE($I$2,G$4,G$5)) | H25: =SUMIFS(DATA!$M:$M,DATA!$C:$C,$B24,DATA!$N:$N,">="&DATE($I$2,H$4,1),DATA!$N:$N,"<="&DATE($I$2,H$4,H$5)) | I25: =SUMIFS(DATA!$M:$M,DATA!$C:$C,$B24,DATA!$N:$N,">="&DATE($I$2,I$4,1),DATA!$N:$N,"<="&DATE($I$2,I$4,I$5)) | J25: =SUMIFS(DATA!$M:$M,DATA!$C:$C,$B24,DATA!$N:$N,">="&DATE($I$2,J$4,1),DATA!$N:$N,"<="&DATE($I$2,J$4,J$5)) | K25: =SUMIFS(DATA!$M:$M,DATA!$C:$C,$B24,DATA!$N:$N,">="&DATE($I$2,K$4,1),DATA!$N:$N,"<="&DATE($I$2,K$4,K$5)) | ... O25: =SUMIFS(DATA!$M:$M,DATA!$C:$C,$B24,DATA!$N:$N,">="&DATE($I$2,O$4,1),DATA!$N:$N,"<="&DATE($I$2,O$4,O$5)) | P25: =SUM(D25:O25)
A26: 11 | B26: WIDIA SHINKI VIETNAM | C26: Kế hoạch | D26: =SUMIFS(DATA!$I:$I,DATA!$C:$C,$B26,DATA!$J:$J,">="&DATE($I$2,D$4,1),DATA!$J:$J,"<="&DATE($I$2,D$4,D$5)) | E26: =SUMIFS(DATA!$I:$I,DATA!$C:$C,$B26,DATA!$J:$J,">="&DATE($I$2,E$4,1),DATA!$J:$J,"<="&DATE($I$2,E$4,E$5)) | F26: =SUMIFS(DATA!$I:$I,DATA!$C:$C,$B26,DATA!$J:$J,">="&DATE($I$2,F$4,1),DATA!$J:$J,"<="&DATE($I$2,F$4,F$5)) | G26: =SUMIFS(DATA!$I:$I,DATA!$C:$C,$B26,DATA!$J:$J,">="&DATE($I$2,G$4,1),DATA!$J:$J,"<="&DATE($I$2,G$4,G$5)) | H26: =SUMIFS(DATA!$I:$I,DATA!$C:$C,$B26,DATA!$J:$J,">="&DATE($I$2,H$4,1),DATA!$J:$J,"<="&DATE($I$2,H$4,H$5)) | I26: =SUMIFS(DATA!$I:$I,DATA!$C:$C,$B26,DATA!$J:$J,">="&DATE($I$2,I$4,1),DATA!$J:$J,"<="&DATE($I$2,I$4,I$5)) | J26: =SUMIFS(DATA!$I:$I,DATA!$C:$C,$B26,DATA!$J:$J,">="&DATE($I$2,J$4,1),DATA!$J:$J,"<="&DATE($I$2,J$4,J$5)) | K26: =SUMIFS(DATA!$I:$I,DATA!$C:$C,$B26,DATA!$J:$J,">="&DATE($I$2,K$4,1),DATA!$J:$J,"<="&DATE($I$2,K$4,K$5)) | ... O26: =SUMIFS(DATA!$I:$I,DATA!$C:$C,$B26,DATA!$J:$J,">="&DATE($I$2,O$4,1),DATA!$J:$J,"<="&DATE($I$2,O$4,O$5)) | P26: =SUM(D26:O26)
C27: Thực tế | D27: =SUMIFS(DATA!$M:$M,DATA!$C:$C,$B26,DATA!$N:$N,">="&DATE($I$2,D$4,1),DATA!$N:$N,"<="&DATE($I$2,D$4,D$5)) | E27: =SUMIFS(DATA!$M:$M,DATA!$C:$C,$B26,DATA!$N:$N,">="&DATE($I$2,E$4,1),DATA!$N:$N,"<="&DATE($I$2,E$4,E$5)) | F27: =SUMIFS(DATA!$M:$M,DATA!$C:$C,$B26,DATA!$N:$N,">="&DATE($I$2,F$4,1),DATA!$N:$N,"<="&DATE($I$2,F$4,F$5)) | G27: =SUMIFS(DATA!$M:$M,DATA!$C:$C,$B26,DATA!$N:$N,">="&DATE($I$2,G$4,1),DATA!$N:$N,"<="&DATE($I$2,G$4,G$5)) | H27: =SUMIFS(DATA!$M:$M,DATA!$C:$C,$B26,DATA!$N:$N,">="&DATE($I$2,H$4,1),DATA!$N:$N,"<="&DATE($I$2,H$4,H$5)) | I27: =SUMIFS(DATA!$M:$M,DATA!$C:$C,$B26,DATA!$N:$N,">="&DATE($I$2,I$4,1),DATA!$N:$N,"<="&DATE($I$2,I$4,I$5)) | J27: =SUMIFS(DATA!$M:$M,DATA!$C:$C,$B26,DATA!$N:$N,">="&DATE($I$2,J$4,1),DATA!$N:$N,"<="&DATE($I$2,J$4,J$5)) | K27: =SUMIFS(DATA!$M:$M,DATA!$C:$C,$B26,DATA!$N:$N,">="&DATE($I$2,K$4,1),DATA!$N:$N,"<="&DATE($I$2,K$4,K$5)) | ... O27: =SUMIFS(DATA!$M:$M,DATA!$C:$C,$B26,DATA!$N:$N,">="&DATE($I$2,O$4,1),DATA!$N:$N,"<="&DATE($I$2,O$4,O$5)) | P27: =SUM(D27:O27)
A28: 12 | B28: GENTHERM VIETNAM CO., LTD | C28: Kế hoạch | D28: =SUMIFS(DATA!$I:$I,DATA!$C:$C,$B28,DATA!$J:$J,">="&DATE($I$2,D$4,1),DATA!$J:$J,"<="&DATE($I$2,D$4,D$5)) | E28: =SUMIFS(DATA!$I:$I,DATA!$C:$C,$B28,DATA!$J:$J,">="&DATE($I$2,E$4,1),DATA!$J:$J,"<="&DATE($I$2,E$4,E$5)) | F28: =SUMIFS(DATA!$I:$I,DATA!$C:$C,$B28,DATA!$J:$J,">="&DATE($I$2,F$4,1),DATA!$J:$J,"<="&DATE($I$2,F$4,F$5)) | G28: =SUMIFS(DATA!$I:$I,DATA!$C:$C,$B28,DATA!$J:$J,">="&DATE($I$2,G$4,1),DATA!$J:$J,"<="&DATE($I$2,G$4,G$5)) | H28: =SUMIFS(DATA!$I:$I,DATA!$C:$C,$B28,DATA!$J:$J,">="&DATE($I$2,H$4,1),DATA!$J:$J,"<="&DATE($I$2,H$4,H$5)) | I28: =SUMIFS(DATA!$I:$I,DATA!$C:$C,$B28,DATA!$J:$J,">="&DATE($I$2,I$4,1),DATA!$J:$J,"<="&DATE($I$2,I$4,I$5)) | J28: =SUMIFS(DATA!$I:$I,DATA!$C:$C,$B28,DATA!$J:$J,">="&DATE($I$2,J$4,1),DATA!$J:$J,"<="&DATE($I$2,J$4,J$5)) | K28: =SUMIFS(DATA!$I:$I,DATA!$C:$C,$B28,DATA!$J:$J,">="&DATE($I$2,K$4,1),DATA!$J:$J,"<="&DATE($I$2,K$4,K$5)) | ... O28: =SUMIFS(DATA!$I:$I,DATA!$C:$C,$B28,DATA!$J:$J,">="&DATE($I$2,O$4,1),DATA!$J:$J,"<="&DATE($I$2,O$4,O$5)) | P28: =SUM(D28:O28)
C29: Thực tế | D29: =SUMIFS(DATA!$M:$M,DATA!$C:$C,$B28,DATA!$N:$N,">="&DATE($I$2,D$4,1),DATA!$N:$N,"<="&DATE($I$2,D$4,D$5)) | E29: =SUMIFS(DATA!$M:$M,DATA!$C:$C,$B28,DATA!$N:$N,">="&DATE($I$2,E$4,1),DATA!$N:$N,"<="&DATE($I$2,E$4,E$5)) | F29: =SUMIFS(DATA!$M:$M,DATA!$C:$C,$B28,DATA!$N:$N,">="&DATE($I$2,F$4,1),DATA!$N:$N,"<="&DATE($I$2,F$4,F$5)) | G29: =SUMIFS(DATA!$M:$M,DATA!$C:$C,$B28,DATA!$N:$N,">="&DATE($I$2,G$4,1),DATA!$N:$N,"<="&DATE($I$2,G$4,G$5)) | H29: =SUMIFS(DATA!$M:$M,DATA!$C:$C,$B28,DATA!$N:$N,">="&DATE($I$2,H$4,1),DATA!$N:$N,"<="&DATE($I$2,H$4,H$5)) | I29: =SUMIFS(DATA!$M:$M,DATA!$C:$C,$B28,DATA!$N:$N,">="&DATE($I$2,I$4,1),DATA!$N:$N,"<="&DATE($I$2,I$4,I$5)) | J29: =SUMIFS(DATA!$M:$M,DATA!$C:$C,$B28,DATA!$N:$N,">="&DATE($I$2,J$4,1),DATA!$N:$N,"<="&DATE($I$2,J$4,J$5)) | K29: =SUMIFS(DATA!$M:$M,DATA!$C:$C,$B28,DATA!$N:$N,">="&DATE($I$2,K$4,1),DATA!$N:$N,"<="&DATE($I$2,K$4,K$5)) | ... O29: =SUMIFS(DATA!$M:$M,DATA!$C:$C,$B28,DATA!$N:$N,">="&DATE($I$2,O$4,1),DATA!$N:$N,"<="&DATE($I$2,O$4,O$5)) | P29: =SUM(D29:O29)
A30: 13 | B30: FALCON VIETNAM | C30: Kế hoạch | D30: =SUMIFS(DATA!$I:$I,DATA!$C:$C,$B30,DATA!$J:$J,">="&DATE($I$2,D$4,1),DATA!$J:$J,"<="&DATE($I$2,D$4,D$5)) | E30: =SUMIFS(DATA!$I:$I,DATA!$C:$C,$B30,DATA!$J:$J,">="&DATE($I$2,E$4,1),DATA!$J:$J,"<="&DATE($I$2,E$4,E$5)) | F30: =SUMIFS(DATA!$I:$I,DATA!$C:$C,$B30,DATA!$J:$J,">="&DATE($I$2,F$4,1),DATA!$J:$J,"<="&DATE($I$2,F$4,F$5)) | G30: =SUMIFS(DATA!$I:$I,DATA!$C:$C,$B30,DATA!$J:$J,">="&DATE($I$2,G$4,1),DATA!$J:$J,"<="&DATE($I$2,G$4,G$5)) | H30: =SUMIFS(DATA!$I:$I,DATA!$C:$C,$B30,DATA!$J:$J,">="&DATE($I$2,H$4,1),DATA!$J:$J,"<="&DATE($I$2,H$4,H$5)) | I30: =SUMIFS(DATA!$I:$I,DATA!$C:$C,$B30,DATA!$J:$J,">="&DATE($I$2,I$4,1),DATA!$J:$J,"<="&DATE($I$2,I$4,I$5)) | J30: =SUMIFS(DATA!$I:$I,DATA!$C:$C,$B30,DATA!$J:$J,">="&DATE($I$2,J$4,1),DATA!$J:$J,"<="&DATE($I$2,J$4,J$5)) | K30: =SUMIFS(DATA!$I:$I,DATA!$C:$C,$B30,DATA!$J:$J,">="&DATE($I$2,K$4,1),DATA!$J:$J,"<="&DATE($I$2,K$4,K$5)) | ... O30: =SUMIFS(DATA!$I:$I,DATA!$C:$C,$B30,DATA!$J:$J,">="&DATE($I$2,O$4,1),DATA!$J:$J,"<="&DATE($I$2,O$4,O$5)) | P30: =SUM(D30:O30)
C31: Thực tế | D31: =SUMIFS(DATA!$M:$M,DATA!$C:$C,$B30,DATA!$N:$N,">="&DATE($I$2,D$4,1),DATA!$N:$N,"<="&DATE($I$2,D$4,D$5)) | E31: =SUMIFS(DATA!$M:$M,DATA!$C:$C,$B30,DATA!$N:$N,">="&DATE($I$2,E$4,1),DATA!$N:$N,"<="&DATE($I$2,E$4,E$5)) | F31: =SUMIFS(DATA!$M:$M,DATA!$C:$C,$B30,DATA!$N:$N,">="&DATE($I$2,F$4,1),DATA!$N:$N,"<="&DATE($I$2,F$4,F$5)) | G31: =SUMIFS(DATA!$M:$M,DATA!$C:$C,$B30,DATA!$N:$N,">="&DATE($I$2,G$4,1),DATA!$N:$N,"<="&DATE($I$2,G$4,G$5)) | H31: =SUMIFS(DATA!$M:$M,DATA!$C:$C,$B30,DATA!$N:$N,">="&DATE($I$2,H$4,1),DATA!$N:$N,"<="&DATE($I$2,H$4,H$5)) | I31: =SUMIFS(DATA!$M:$M,DATA!$C:$C,$B30,DATA!$N:$N,">="&DATE($I$2,I$4,1),DATA!$N:$N,"<="&DATE($I$2,I$4,I$5)) | J31: =SUMIFS(DATA!$M:$M,DATA!$C:$C,$B30,DATA!$N:$N,">="&DATE($I$2,J$4,1),DATA!$N:$N,"<="&DATE($I$2,J$4,J$5)) | K31: =SUMIFS(DATA!$M:$M,DATA!$C:$C,$B30,DATA!$N:$N,">="&DATE($I$2,K$4,1),DATA!$N:$N,"<="&DATE($I$2,K$4,K$5)) | ... O31: =SUMIFS(DATA!$M:$M,DATA!$C:$C,$B30,DATA!$N:$N,">="&DATE($I$2,O$4,1),DATA!$N:$N,"<="&DATE($I$2,O$4,O$5)) | P31: =SUM(D31:O31)
A32: 14 | B32: HORISON TOWER | C32: Kế hoạch | D32: =SUMIFS(DATA!$I:$I,DATA!$C:$C,$B32,DATA!$J:$J,">="&DATE($I$2,D$4,1),DATA!$J:$J,"<="&DATE($I$2,D$4,D$5)) | E32: =SUMIFS(DATA!$I:$I,DATA!$C:$C,$B32,DATA!$J:$J,">="&DATE($I$2,E$4,1),DATA!$J:$J,"<="&DATE($I$2,E$4,E$5)) | F32: =SUMIFS(DATA!$I:$I,DATA!$C:$C,$B32,DATA!$J:$J,">="&DATE($I$2,F$4,1),DATA!$J:$J,"<="&DATE($I$2,F$4,F$5)) | G32: =SUMIFS(DATA!$I:$I,DATA!$C:$C,$B32,DATA!$J:$J,">="&DATE($I$2,G$4,1),DATA!$J:$J,"<="&DATE($I$2,G$4,G$5)) | H32: =SUMIFS(DATA!$I:$I,DATA!$C:$C,$B32,DATA!$J:$J,">="&DATE($I$2,H$4,1),DATA!$J:$J,"<="&DATE($I$2,H$4,H$5)) | I32: =SUMIFS(DATA!$I:$I,DATA!$C:$C,$B32,DATA!$J:$J,">="&DATE($I$2,I$4,1),DATA!$J:$J,"<="&DATE($I$2,I$4,I$5)) | J32: =SUMIFS(DATA!$I:$I,DATA!$C:$C,$B32,DATA!$J:$J,">="&DATE($I$2,J$4,1),DATA!$J:$J,"<="&DATE($I$2,J$4,J$5)) | K32: =SUMIFS(DATA!$I:$I,DATA!$C:$C,$B32,DATA!$J:$J,">="&DATE($I$2,K$4,1),DATA!$J:$J,"<="&DATE($I$2,K$4,K$5)) | ... O32: =SUMIFS(DATA!$I:$I,DATA!$C:$C,$B32,DATA!$J:$J,">="&DATE($I$2,O$4,1),DATA!$J:$J,"<="&DATE($I$2,O$4,O$5)) | P32: =SUM(D32:O32)
C33: Thực tế | D33: =SUMIFS(DATA!$M:$M,DATA!$C:$C,$B32,DATA!$N:$N,">="&DATE($I$2,D$4,1),DATA!$N:$N,"<="&DATE($I$2,D$4,D$5)) | E33: =SUMIFS(DATA!$M:$M,DATA!$C:$C,$B32,DATA!$N:$N,">="&DATE($I$2,E$4,1),DATA!$N:$N,"<="&DATE($I$2,E$4,E$5)) | F33: =SUMIFS(DATA!$M:$M,DATA!$C:$C,$B32,DATA!$N:$N,">="&DATE($I$2,F$4,1),DATA!$N:$N,"<="&DATE($I$2,F$4,F$5)) | G33: =SUMIFS(DATA!$M:$M,DATA!$C:$C,$B32,DATA!$N:$N,">="&DATE($I$2,G$4,1),DATA!$N:$N,"<="&DATE($I$2,G$4,G$5)) | H33: =SUMIFS(DATA!$M:$M,DATA!$C:$C,$B32,DATA!$N:$N,">="&DATE($I$2,H$4,1),DATA!$N:$N,"<="&DATE($I$2,H$4,H$5)) | I33: =SUMIFS(DATA!$M:$M,DATA!$C:$C,$B32,DATA!$N:$N,">="&DATE($I$2,I$4,1),DATA!$N:$N,"<="&DATE($I$2,I$4,I$5)) | J33: =SUMIFS(DATA!$M:$M,DATA!$C:$C,$B32,DATA!$N:$N,">="&DATE($I$2,J$4,1),DATA!$N:$N,"<="&DATE($I$2,J$4,J$5)) | K33: =SUMIFS(DATA!$M:$M,DATA!$C:$C,$B32,DATA!$N:$N,">="&DATE($I$2,K$4,1),DATA!$N:$N,"<="&DATE($I$2,K$4,K$5)) | ... O33: =SUMIFS(DATA!$M:$M,DATA!$C:$C,$B32,DATA!$N:$N,">="&DATE($I$2,O$4,1),DATA!$N:$N,"<="&DATE($I$2,O$4,O$5)) | P33: =SUM(D33:O33)
A34: 15 | B34: EMBASSY OF FRANCE | C34: Kế hoạch | D34: =SUMIFS(DATA!$I:$I,DATA!$C:$C,$B34,DATA!$J:$J,">="&DATE($I$2,D$4,1),DATA!$J:$J,"<="&DATE($I$2,D$4,D$5)) | E34: =SUMIFS(DATA!$I:$I,DATA!$C:$C,$B34,DATA!$J:$J,">="&DATE($I$2,E$4,1),DATA!$J:$J,"<="&DATE($I$2,E$4,E$5)) | F34: =SUMIFS(DATA!$I:$I,DATA!$C:$C,$B34,DATA!$J:$J,">="&DATE($I$2,F$4,1),DATA!$J:$J,"<="&DATE($I$2,F$4,F$5)) | G34: =SUMIFS(DATA!$I:$I,DATA!$C:$C,$B34,DATA!$J:$J,">="&DATE($I$2,G$4,1),DATA!$J:$J,"<="&DATE($I$2,G$4,G$5)) | H34: =SUMIFS(DATA!$I:$I,DATA!$C:$C,$B34,DATA!$J:$J,">="&DATE($I$2,H$4,1),DATA!$J:$J,"<="&DATE($I$2,H$4,H$5)) | I34: =SUMIFS(DATA!$I:$I,DATA!$C:$C,$B34,DATA!$J:$J,">="&DATE($I$2,I$4,1),DATA!$J:$J,"<="&DATE($I$2,I$4,I$5)) | J34: =SUMIFS(DATA!$I:$I,DATA!$C:$C,$B34,DATA!$J:$J,">="&DATE($I$2,J$4,1),DATA!$J:$J,"<="&DATE($I$2,J$4,J$5)) | K34: =SUMIFS(DATA!$I:$I,DATA!$C:$C,$B34,DATA!$J:$J,">="&DATE($I$2,K$4,1),DATA!$J:$J,"<="&DATE($I$2,K$4,K$5)) | ... O34: =SUMIFS(DATA!$I:$I,DATA!$C:$C,$B34,DATA!$J:$J,">="&DATE($I$2,O$4,1),DATA!$J:$J,"<="&DATE($I$2,O$4,O$5)) | P34: =SUM(D34:O34)
C35: Thực tế | D35: =SUMIFS(DATA!$M:$M,DATA!$C:$C,$B34,DATA!$N:$N,">="&DATE($I$2,D$4,1),DATA!$N:$N,"<="&DATE($I$2,D$4,D$5)) | E35: =SUMIFS(DATA!$M:$M,DATA!$C:$C,$B34,DATA!$N:$N,">="&DATE($I$2,E$4,1),DATA!$N:$N,"<="&DATE($I$2,E$4,E$5)) | F35: =SUMIFS(DATA!$M:$M,DATA!$C:$C,$B34,DATA!$N:$N,">="&DATE($I$2,F$4,1),DATA!$N:$N,"<="&DATE($I$2,F$4,F$5)) | G35: =SUMIFS(DATA!$M:$M,DATA!$C:$C,$B34,DATA!$N:$N,">="&DATE($I$2,G$4,1),DATA!$N:$N,"<="&DATE($I$2,G$4,G$5)) | H35: =SUMIFS(DATA!$M:$M,DATA!$C:$C,$B34,DATA!$N:$N,">="&DATE($I$2,H$4,1),DATA!$N:$N,"<="&DATE($I$2,H$4,H$5)) | I35: =SUMIFS(DATA!$M:$M,DATA!$C:$C,$B34,DATA!$N:$N,">="&DATE($I$2,I$4,1),DATA!$N:$N,"<="&DATE($I$2,I$4,I$5)) | J35: =SUMIFS(DATA!$M:$M,DATA!$C:$C,$B34,DATA!$N:$N,">="&DATE($I$2,J$4,1),DATA!$N:$N,"<="&DATE($I$2,J$4,J$5)) | K35: =SUMIFS(DATA!$M:$M,DATA!$C:$C,$B34,DATA!$N:$N,">="&DATE($I$2,K$4,1),DATA!$N:$N,"<="&DATE($I$2,K$4,K$5)) | ... O35: =SUMIFS(DATA!$M:$M,DATA!$C:$C,$B34,DATA!$N:$N,">="&DATE($I$2,O$4,1),DATA!$N:$N,"<="&DATE($I$2,O$4,O$5)) | P35: =SUM(D35:O35)
A36: 16 | B36: PHC COMPLEX | C36: Kế hoạch | D36: =SUMIFS(DATA!$I:$I,DATA!$C:$C,$B36,DATA!$J:$J,">="&DATE($I$2,D$4,1),DATA!$J:$J,"<="&DATE($I$2,D$4,D$5)) | E36: =SUMIFS(DATA!$I:$I,DATA!$C:$C,$B36,DATA!$J:$J,">="&DATE($I$2,E$4,1),DATA!$J:$J,"<="&DATE($I$2,E$4,E$5)) | F36: =SUMIFS(DATA!$I:$I,DATA!$C:$C,$B36,DATA!$J:$J,">="&DATE($I$2,F$4,1),DATA!$J:$J,"<="&DATE($I$2,F$4,F$5)) | G36: =SUMIFS(DATA!$I:$I,DATA!$C:$C,$B36,DATA!$J:$J,">="&DATE($I$2,G$4,1),DATA!$J:$J,"<="&DATE($I$2,G$4,G$5)) | H36: =SUMIFS(DATA!$I:$I,DATA!$C:$C,$B36,DATA!$J:$J,">="&DATE($I$2,H$4,1),DATA!$J:$J,"<="&DATE($I$2,H$4,H$5)) | I36: =SUMIFS(DATA!$I:$I,DATA!$C:$C,$B36,DATA!$J:$J,">="&DATE($I$2,I$4,1),DATA!$J:$J,"<="&DATE($I$2,I$4,I$5)) | J36: =SUMIFS(DATA!$I:$I,DATA!$C:$C,$B36,DATA!$J:$J,">="&DATE($I$2,J$4,1),DATA!$J:$J,"<="&DATE($I$2,J$4,J$5)) | K36: =SUMIFS(DATA!$I:$I,DATA!$C:$C,$B36,DATA!$J:$J,">="&DATE($I$2,K$4,1),DATA!$J:$J,"<="&DATE($I$2,K$4,K$5)) | ... O36: =SUMIFS(DATA!$I:$I,DATA!$C:$C,$B36,DATA!$J:$J,">="&DATE($I$2,O$4,1),DATA!$J:$J,"<="&DATE($I$2,O$4,O$5)) | P36: =SUM(D36:O36)
C37: Thực tế | D37: =SUMIFS(DATA!$M:$M,DATA!$C:$C,$B36,DATA!$N:$N,">="&DATE($I$2,D$4,1),DATA!$N:$N,"<="&DATE($I$2,D$4,D$5)) | E37: =SUMIFS(DATA!$M:$M,DATA!$C:$C,$B36,DATA!$N:$N,">="&DATE($I$2,E$4,1),DATA!$N:$N,"<="&DATE($I$2,E$4,E$5)) | F37: =SUMIFS(DATA!$M:$M,DATA!$C:$C,$B36,DATA!$N:$N,">="&DATE($I$2,F$4,1),DATA!$N:$N,"<="&DATE($I$2,F$4,F$5)) | G37: =SUMIFS(DATA!$M:$M,DATA!$C:$C,$B36,DATA!$N:$N,">="&DATE($I$2,G$4,1),DATA!$N:$N,"<="&DATE($I$2,G$4,G$5)) | H37: =SUMIFS(DATA!$M:$M,DATA!$C:$C,$B36,DATA!$N:$N,">="&DATE($I$2,H$4,1),DATA!$N:$N,"<="&DATE($I$2,H$4,H$5)) | I37: =SUMIFS(DATA!$M:$M,DATA!$C:$C,$B36,DATA!$N:$N,">="&DATE($I$2,I$4,1),DATA!$N:$N,"<="&DATE($I$2,I$4,I$5)) | J37: =SUMIFS(DATA!$M:$M,DATA!$C:$C,$B36,DATA!$N:$N,">="&DATE($I$2,J$4,1),DATA!$N:$N,"<="&DATE($I$2,J$4,J$5)) | K37: =SUMIFS(DATA!$M:$M,DATA!$C:$C,$B36,DATA!$N:$N,">="&DATE($I$2,K$4,1),DATA!$N:$N,"<="&DATE($I$2,K$4,K$5)) | ... O37: =SUMIFS(DATA!$M:$M,DATA!$C:$C,$B36,DATA!$N:$N,">="&DATE($I$2,O$4,1),DATA!$N:$N,"<="&DATE($I$2,O$4,O$5)) | P37: =SUM(D37:O37)
A38: 17 | B38: FSOFT - DUY TÂN | C38: Kế hoạch | D38: =SUMIFS(DATA!$I:$I,DATA!$C:$C,$B38,DATA!$J:$J,">="&DATE($I$2,D$4,1),DATA!$J:$J,"<="&DATE($I$2,D$4,D$5)) | E38: =SUMIFS(DATA!$I:$I,DATA!$C:$C,$B38,DATA!$J:$J,">="&DATE($I$2,E$4,1),DATA!$J:$J,"<="&DATE($I$2,E$4,E$5)) | F38: =SUMIFS(DATA!$I:$I,DATA!$C:$C,$B38,DATA!$J:$J,">="&DATE($I$2,F$4,1),DATA!$J:$J,"<="&DATE($I$2,F$4,F$5)) | G38: =SUMIFS(DATA!$I:$I,DATA!$C:$C,$B38,DATA!$J:$J,">="&DATE($I$2,G$4,1),DATA!$J:$J,"<="&DATE($I$2,G$4,G$5)) | H38: =SUMIFS(DATA!$I:$I,DATA!$C:$C,$B38,DATA!$J:$J,">="&DATE($I$2,H$4,1),DATA!$J:$J,"<="&DATE($I$2,H$4,H$5)) | I38: =SUMIFS(DATA!$I:$I,DATA!$C:$C,$B38,DATA!$J:$J,">="&DATE($I$2,I$4,1),DATA!$J:$J,"<="&DATE($I$2,I$4,I$5)) | J38: =SUMIFS(DATA!$I:$I,DATA!$C:$C,$B38,DATA!$J:$J,">="&DATE($I$2,J$4,1),DATA!$J:$J,"<="&DATE($I$2,J$4,J$5)) | K38: =SUMIFS(DATA!$I:$I,DATA!$C:$C,$B38,DATA!$J:$J,">="&DATE($I$2,K$4,1),DATA!$J:$J,"<="&DATE($I$2,K$4,K$5)) | ... O38: =SUMIFS(DATA!$I:$I,DATA!$C:$C,$B38,DATA!$J:$J,">="&DATE($I$2,O$4,1),DATA!$J:$J,"<="&DATE($I$2,O$4,O$5)) | P38: =SUM(D38:O38)
C39: Thực tế | D39: =SUMIFS(DATA!$M:$M,DATA!$C:$C,$B38,DATA!$N:$N,">="&DATE($I$2,D$4,1),DATA!$N:$N,"<="&DATE($I$2,D$4,D$5)) | E39: =SUMIFS(DATA!$M:$M,DATA!$C:$C,$B38,DATA!$N:$N,">="&DATE($I$2,E$4,1),DATA!$N:$N,"<="&DATE($I$2,E$4,E$5)) | F39: =SUMIFS(DATA!$M:$M,DATA!$C:$C,$B38,DATA!$N:$N,">="&DATE($I$2,F$4,1),DATA!$N:$N,"<="&DATE($I$2,F$4,F$5)) | G39: =SUMIFS(DATA!$M:$M,DATA!$C:$C,$B38,DATA!$N:$N,">="&DATE($I$2,G$4,1),DATA!$N:$N,"<="&DATE($I$2,G$4,G$5)) | H39: =SUMIFS(DATA!$M:$M,DATA!$C:$C,$B38,DATA!$N:$N,">="&DATE($I$2,H$4,1),DATA!$N:$N,"<="&DATE($I$2,H$4,H$5)) | I39: =SUMIFS(DATA!$M:$M,DATA!$C:$C,$B38,DATA!$N:$N,">="&DATE($I$2,I$4,1),DATA!$N:$N,"<="&DATE($I$2,I$4,I$5)) | J39: =SUMIFS(DATA!$M:$M,DATA!$C:$C,$B38,DATA!$N:$N,">="&DATE($I$2,J$4,1),DATA!$N:$N,"<="&DATE($I$2,J$4,J$5)) | K39: =SUMIFS(DATA!$M:$M,DATA!$C:$C,$B38,DATA!$N:$N,">="&DATE($I$2,K$4,1),DATA!$N:$N,"<="&DATE($I$2,K$4,K$5)) | ... O39: =SUMIFS(DATA!$M:$M,DATA!$C:$C,$B38,DATA!$N:$N,">="&DATE($I$2,O$4,1),DATA!$N:$N,"<="&DATE($I$2,O$4,O$5)) | P39: =SUM(D39:O39)
A40: 18 | B40: US EMBASSY HANOI | C40: Kế hoạch | D40: =SUMIFS(DATA!$I:$I,DATA!$C:$C,$B40,DATA!$J:$J,">="&DATE($I$2,D$4,1),DATA!$J:$J,"<="&DATE($I$2,D$4,D$5)) | E40: =SUMIFS(DATA!$I:$I,DATA!$C:$C,$B40,DATA!$J:$J,">="&DATE($I$2,E$4,1),DATA!$J:$J,"<="&DATE($I$2,E$4,E$5)) | F40: =SUMIFS(DATA!$I:$I,DATA!$C:$C,$B40,DATA!$J:$J,">="&DATE($I$2,F$4,1),DATA!$J:$J,"<="&DATE($I$2,F$4,F$5)) | G40: =SUMIFS(DATA!$I:$I,DATA!$C:$C,$B40,DATA!$J:$J,">="&DATE($I$2,G$4,1),DATA!$J:$J,"<="&DATE($I$2,G$4,G$5)) | H40: =SUMIFS(DATA!$I:$I,DATA!$C:$C,$B40,DATA!$J:$J,">="&DATE($I$2,H$4,1),DATA!$J:$J,"<="&DATE($I$2,H$4,H$5)) | I40: =SUMIFS(DATA!$I:$I,DATA!$C:$C,$B40,DATA!$J:$J,">="&DATE($I$2,I$4,1),DATA!$J:$J,"<="&DATE($I$2,I$4,I$5)) | J40: =SUMIFS(DATA!$I:$I,DATA!$C:$C,$B40,DATA!$J:$J,">="&DATE($I$2,J$4,1),DATA!$J:$J,"<="&DATE($I$2,J$4,J$5)) | K40: =SUMIFS(DATA!$I:$I,DATA!$C:$C,$B40,DATA!$J:$J,">="&DATE($I$2,K$4,1),DATA!$J:$J,"<="&DATE($I$2,K$4,K$5)) | ... O40: =SUMIFS(DATA!$I:$I,DATA!$C:$C,$B40,DATA!$J:$J,">="&DATE($I$2,O$4,1),DATA!$J:$J,"<="&DATE($I$2,O$4,O$5)) | P40: =SUM(D40:O40)
C41: Thực tế | D41: =SUMIFS(DATA!$M:$M,DATA!$C:$C,$B40,DATA!$N:$N,">="&DATE($I$2,D$4,1),DATA!$N:$N,"<="&DATE($I$2,D$4,D$5)) | E41: =SUMIFS(DATA!$M:$M,DATA!$C:$C,$B40,DATA!$N:$N,">="&DATE($I$2,E$4,1),DATA!$N:$N,"<="&DATE($I$2,E$4,E$5)) | F41: =SUMIFS(DATA!$M:$M,DATA!$C:$C,$B40,DATA!$N:$N,">="&DATE($I$2,F$4,1),DATA!$N:$N,"<="&DATE($I$2,F$4,F$5)) | G41: =SUMIFS(DATA!$M:$M,DATA!$C:$C,$B40,DATA!$N:$N,">="&DATE($I$2,G$4,1),DATA!$N:$N,"<="&DATE($I$2,G$4,G$5)) | H41: =SUMIFS(DATA!$M:$M,DATA!$C:$C,$B40,DATA!$N:$N,">="&DATE($I$2,H$4,1),DATA!$N:$N,"<="&DATE($I$2,H$4,H$5)) | I41: =SUMIFS(DATA!$M:$M,DATA!$C:$C,$B40,DATA!$N:$N,">="&DATE($I$2,I$4,1),DATA!$N:$N,"<="&DATE($I$2,I$4,I$5)) | J41: =SUMIFS(DATA!$M:$M,DATA!$C:$C,$B40,DATA!$N:$N,">="&DATE($I$2,J$4,1),DATA!$N:$N,"<="&DATE($I$2,J$4,J$5)) | K41: =SUMIFS(DATA!$M:$M,DATA!$C:$C,$B40,DATA!$N:$N,">="&DATE($I$2,K$4,1),DATA!$N:$N,"<="&DATE($I$2,K$4,K$5)) | ... O41: =SUMIFS(DATA!$M:$M,DATA!$C:$C,$B40,DATA!$N:$N,">="&DATE($I$2,O$4,1),DATA!$N:$N,"<="&DATE($I$2,O$4,O$5)) | P41: =SUM(D41:O41)
...

Sheet Annual
E2: BÁO CÁO DOANH THU NĂM
E3: ANNUAL TURN-OVER REPORT | I3: UPDATED ON | J3: =TODAY()
J4: VND
A5: No | B5: Tên Khách hàng Client Name | C5: =D5-1 | D5: =E5-1 | E5: =F5-1 | F5: =G5-1 | G5: =H5-1 | H5: =I5-1 | I5: =YEAR(TODAY()) | J5: Tổng Total | K5: %
A6: 1 | B6: VNPT IDC - NAM THANG LONG(Inactive) | C6: =SUMIFS(DATA!$M:$M,DATA!$C:$C,$B6,DATA!$N:$N,">="&DATE(C$5,1,1),DATA!$N:$N,"<="&DATE(C$5,12,31)) | D6: =SUMIFS(DATA!$M:$M,DATA!$C:$C,$B6,DATA!$N:$N,">="&DATE(D$5,1,1),DATA!$N:$N,"<="&DATE(D$5,12,31)) | E6: =SUMIFS(DATA!$M:$M,DATA!$C:$C,$B6,DATA!$N:$N,">="&DATE(E$5,1,1),DATA!$N:$N,"<="&DATE(E$5,12,31)) | F6: =SUMIFS(DATA!$M:$M,DATA!$C:$C,$B6,DATA!$N:$N,">="&DATE(F$5,1,1),DATA!$N:$N,"<="&DATE(F$5,12,31)) | G6: =SUMIFS(DATA!$M:$M,DATA!$C:$C,$B6,DATA!$N:$N,">="&DATE(G$5,1,1),DATA!$N:$N,"<="&DATE(G$5,12,31)) | H6: =SUMIFS(DATA!$M:$M,DATA!$C:$C,$B6,DATA!$N:$N,">="&DATE(H$5,1,1),DATA!$N:$N,"<="&DATE(H$5,12,31)) | I6: =SUMIFS(DATA!$M:$M,DATA!$C:$C,$B6,DATA!$N:$N,">="&DATE(I$5,1,1),DATA!$N:$N,"<="&DATE(I$5,12,31)) | J6: =SUM(C6:I6) | K6: =J6/$J$506
A7: 2 | B7: EMBASSY OF AUSTRALIA | C7: =SUMIFS(DATA!$M:$M,DATA!$C:$C,$B7,DATA!$N:$N,">="&DATE(C$5,1,1),DATA!$N:$N,"<="&DATE(C$5,12,31)) | D7: =SUMIFS(DATA!$M:$M,DATA!$C:$C,$B7,DATA!$N:$N,">="&DATE(D$5,1,1),DATA!$N:$N,"<="&DATE(D$5,12,31)) | E7: =SUMIFS(DATA!$M:$M,DATA!$C:$C,$B7,DATA!$N:$N,">="&DATE(E$5,1,1),DATA!$N:$N,"<="&DATE(E$5,12,31)) | F7: =SUMIFS(DATA!$M:$M,DATA!$C:$C,$B7,DATA!$N:$N,">="&DATE(F$5,1,1),DATA!$N:$N,"<="&DATE(F$5,12,31)) | G7: =SUMIFS(DATA!$M:$M,DATA!$C:$C,$B7,DATA!$N:$N,">="&DATE(G$5,1,1),DATA!$N:$N,"<="&DATE(G$5,12,31)) | H7: =SUMIFS(DATA!$M:$M,DATA!$C:$C,$B7,DATA!$N:$N,">="&DATE(H$5,1,1),DATA!$N:$N,"<="&DATE(H$5,12,31)) | I7: =SUMIFS(DATA!$M:$M,DATA!$C:$C,$B7,DATA!$N:$N,">="&DATE(I$5,1,1),DATA!$N:$N,"<="&DATE(I$5,12,31)) | J7: =SUM(C7:I7) | K7: =J7/$J$506
A8: 3 | B8: YAMAHA MOTOR VIETNAM | C8: =SUMIFS(DATA!$M:$M,DATA!$C:$C,$B8,DATA!$N:$N,">="&DATE(C$5,1,1),DATA!$N:$N,"<="&DATE(C$5,12,31)) | D8: =SUMIFS(DATA!$M:$M,DATA!$C:$C,$B8,DATA!$N:$N,">="&DATE(D$5,1,1),DATA!$N:$N,"<="&DATE(D$5,12,31)) | E8: =SUMIFS(DATA!$M:$M,DATA!$C:$C,$B8,DATA!$N:$N,">="&DATE(E$5,1,1),DATA!$N:$N,"<="&DATE(E$5,12,31)) | F8: =SUMIFS(DATA!$M:$M,DATA!$C:$C,$B8,DATA!$N:$N,">="&DATE(F$5,1,1),DATA!$N:$N,"<="&DATE(F$5,12,31)) | G8: =SUMIFS(DATA!$M:$M,DATA!$C:$C,$B8,DATA!$N:$N,">="&DATE(G$5,1,1),DATA!$N:$N,"<="&DATE(G$5,12,31)) | H8: =SUMIFS(DATA!$M:$M,DATA!$C:$C,$B8,DATA!$N:$N,">="&DATE(H$5,1,1),DATA!$N:$N,"<="&DATE(H$5,12,31)) | I8: =SUMIFS(DATA!$M:$M,DATA!$C:$C,$B8,DATA!$N:$N,">="&DATE(I$5,1,1),DATA!$N:$N,"<="&DATE(I$5,12,31)) | J8: =SUM(C8:I8) | K8: =J8/$J$506
A9: 4 | B9: CÔNG TY TNHH THÁP LÁNG HẠ | C9: =SUMIFS(DATA!$M:$M,DATA!$C:$C,$B9,DATA!$N:$N,">="&DATE(C$5,1,1),DATA!$N:$N,"<="&DATE(C$5,12,31)) | D9: =SUMIFS(DATA!$M:$M,DATA!$C:$C,$B9,DATA!$N:$N,">="&DATE(D$5,1,1),DATA!$N:$N,"<="&DATE(D$5,12,31)) | E9: =SUMIFS(DATA!$M:$M,DATA!$C:$C,$B9,DATA!$N:$N,">="&DATE(E$5,1,1),DATA!$N:$N,"<="&DATE(E$5,12,31)) | F9: =SUMIFS(DATA!$M:$M,DATA!$C:$C,$B9,DATA!$N:$N,">="&DATE(F$5,1,1),DATA!$N:$N,"<="&DATE(F$5,12,31)) | G9: =SUMIFS(DATA!$M:$M,DATA!$C:$C,$B9,DATA!$N:$N,">="&DATE(G$5,1,1),DATA!$N:$N,"<="&DATE(G$5,12,31)) | H9: =SUMIFS(DATA!$M:$M,DATA!$C:$C,$B9,DATA!$N:$N,">="&DATE(H$5,1,1),DATA!$N:$N,"<="&DATE(H$5,12,31)) | I9: =SUMIFS(DATA!$M:$M,DATA!$C:$C,$B9,DATA!$N:$N,">="&DATE(I$5,1,1),DATA!$N:$N,"<="&DATE(I$5,12,31)) | J9: =SUM(C9:I9) | K9: =J9/$J$506
A10: 5 | B10: TRUNG TÂM HẠ TẦNG IDC - CÔNG TY CÔNG NGHỆ THÔNG TIN VNPT (VNPT-IT) | C10: =SUMIFS(DATA!$M:$M,DATA!$C:$C,$B10,DATA!$N:$N,">="&DATE(C$5,1,1),DATA!$N:$N,"<="&DATE(C$5,12,31)) | D10: =SUMIFS(DATA!$M:$M,DATA!$C:$C,$B10,DATA!$N:$N,">="&DATE(D$5,1,1),DATA!$N:$N,"<="&DATE(D$5,12,31)) | E10: =SUMIFS(DATA!$M:$M,DATA!$C:$C,$B10,DATA!$N:$N,">="&DATE(E$5,1,1),DATA!$N:$N,"<="&DATE(E$5,12,31)) | F10: =SUMIFS(DATA!$M:$M,DATA!$C:$C,$B10,DATA!$N:$N,">="&DATE(F$5,1,1),DATA!$N:$N,"<="&DATE(F$5,12,31)) | G10: =SUMIFS(DATA!$M:$M,DATA!$C:$C,$B10,DATA!$N:$N,">="&DATE(G$5,1,1),DATA!$N:$N,"<="&DATE(G$5,12,31)) | H10: =SUMIFS(DATA!$M:$M,DATA!$C:$C,$B10,DATA!$N:$N,">="&DATE(H$5,1,1),DATA!$N:$N,"<="&DATE(H$5,12,31)) | I10: =SUMIFS(DATA!$M:$M,DATA!$C:$C,$B10,DATA!$N:$N,">="&DATE(I$5,1,1),DATA!$N:$N,"<="&DATE(I$5,12,31)) | J10: =SUM(C10:I10) | K10: =J10/$J$506
A11: 6 | B11: CRYSTAL MARTIN VIETNAM | C11: =SUMIFS(DATA!$M:$M,DATA!$C:$C,$B11,DATA!$N:$N,">="&DATE(C$5,1,1),DATA!$N:$N,"<="&DATE(C$5,12,31)) | D11: =SUMIFS(DATA!$M:$M,DATA!$C:$C,$B11,DATA!$N:$N,">="&DATE(D$5,1,1),DATA!$N:$N,"<="&DATE(D$5,12,31)) | E11: =SUMIFS(DATA!$M:$M,DATA!$C:$C,$B11,DATA!$N:$N,">="&DATE(E$5,1,1),DATA!$N:$N,"<="&DATE(E$5,12,31)) | F11: =SUMIFS(DATA!$M:$M,DATA!$C:$C,$B11,DATA!$N:$N,">="&DATE(F$5,1,1),DATA!$N:$N,"<="&DATE(F$5,12,31)) | G11: =SUMIFS(DATA!$M:$M,DATA!$C:$C,$B11,DATA!$N:$N,">="&DATE(G$5,1,1),DATA!$N:$N,"<="&DATE(G$5,12,31)) | H11: =SUMIFS(DATA!$M:$M,DATA!$C:$C,$B11,DATA!$N:$N,">="&DATE(H$5,1,1),DATA!$N:$N,"<="&DATE(H$5,12,31)) | I11: =SUMIFS(DATA!$M:$M,DATA!$C:$C,$B11,DATA!$N:$N,">="&DATE(I$5,1,1),DATA!$N:$N,"<="&DATE(I$5,12,31)) | J11: =SUM(C11:I11) | K11: =J11/$J$506
A12: 7 | B12: RMIT UNIVERSITY | C12: =SUMIFS(DATA!$M:$M,DATA!$C:$C,$B12,DATA!$N:$N,">="&DATE(C$5,1,1),DATA!$N:$N,"<="&DATE(C$5,12,31)) | D12: =SUMIFS(DATA!$M:$M,DATA!$C:$C,$B12,DATA!$N:$N,">="&DATE(D$5,1,1),DATA!$N:$N,"<="&DATE(D$5,12,31)) | E12: =SUMIFS(DATA!$M:$M,DATA!$C:$C,$B12,DATA!$N:$N,">="&DATE(E$5,1,1),DATA!$N:$N,"<="&DATE(E$5,12,31)) | F12: =SUMIFS(DATA!$M:$M,DATA!$C:$C,$B12,DATA!$N:$N,">="&DATE(F$5,1,1),DATA!$N:$N,"<="&DATE(F$5,12,31)) | G12: =SUMIFS(DATA!$M:$M,DATA!$C:$C,$B12,DATA!$N:$N,">="&DATE(G$5,1,1),DATA!$N:$N,"<="&DATE(G$5,12,31)) | H12: =SUMIFS(DATA!$M:$M,DATA!$C:$C,$B12,DATA!$N:$N,">="&DATE(H$5,1,1),DATA!$N:$N,"<="&DATE(H$5,12,31)) | I12: =SUMIFS(DATA!$M:$M,DATA!$C:$C,$B12,DATA!$N:$N,">="&DATE(I$5,1,1),DATA!$N:$N,"<="&DATE(I$5,12,31)) | J12: =SUM(C12:I12) | K12: =J12/$J$506
A13: 8 | B13: GOLDEN PALACE MỄ TRÌ | C13: =SUMIFS(DATA!$M:$M,DATA!$C:$C,$B13,DATA!$N:$N,">="&DATE(C$5,1,1),DATA!$N:$N,"<="&DATE(C$5,12,31)) | D13: =SUMIFS(DATA!$M:$M,DATA!$C:$C,$B13,DATA!$N:$N,">="&DATE(D$5,1,1),DATA!$N:$N,"<="&DATE(D$5,12,31)) | E13: =SUMIFS(DATA!$M:$M,DATA!$C:$C,$B13,DATA!$N:$N,">="&DATE(E$5,1,1),DATA!$N:$N,"<="&DATE(E$5,12,31)) | F13: =SUMIFS(DATA!$M:$M,DATA!$C:$C,$B13,DATA!$N:$N,">="&DATE(F$5,1,1),DATA!$N:$N,"<="&DATE(F$5,12,31)) | G13: =SUMIFS(DATA!$M:$M,DATA!$C:$C,$B13,DATA!$N:$N,">="&DATE(G$5,1,1),DATA!$N:$N,"<="&DATE(G$5,12,31)) | H13: =SUMIFS(DATA!$M:$M,DATA!$C:$C,$B13,DATA!$N:$N,">="&DATE(H$5,1,1),DATA!$N:$N,"<="&DATE(H$5,12,31)) | I13: =SUMIFS(DATA!$M:$M,DATA!$C:$C,$B13,DATA!$N:$N,">="&DATE(I$5,1,1),DATA!$N:$N,"<="&DATE(I$5,12,31)) | J13: =SUM(C13:I13) | K13: =J13/$J$506
A14: 9 | B14: U.S. PEACE CORPS | C14: =SUMIFS(DATA!$M:$M,DATA!$C:$C,$B14,DATA!$N:$N,">="&DATE(C$5,1,1),DATA!$N:$N,"<="&DATE(C$5,12,31)) | D14: =SUMIFS(DATA!$M:$M,DATA!$C:$C,$B14,DATA!$N:$N,">="&DATE(D$5,1,1),DATA!$N:$N,"<="&DATE(D$5,12,31)) | E14: =SUMIFS(DATA!$M:$M,DATA!$C:$C,$B14,DATA!$N:$N,">="&DATE(E$5,1,1),DATA!$N:$N,"<="&DATE(E$5,12,31)) | F14: =SUMIFS(DATA!$M:$M,DATA!$C:$C,$B14,DATA!$N:$N,">="&DATE(F$5,1,1),DATA!$N:$N,"<="&DATE(F$5,12,31)) | G14: =SUMIFS(DATA!$M:$M,DATA!$C:$C,$B14,DATA!$N:$N,">="&DATE(G$5,1,1),DATA!$N:$N,"<="&DATE(G$5,12,31)) | H14: =SUMIFS(DATA!$M:$M,DATA!$C:$C,$B14,DATA!$N:$N,">="&DATE(H$5,1,1),DATA!$N:$N,"<="&DATE(H$5,12,31)) | I14: =SUMIFS(DATA!$M:$M,DATA!$C:$C,$B14,DATA!$N:$N,">="&DATE(I$5,1,1),DATA!$N:$N,"<="&DATE(I$5,12,31)) | J14: =SUM(C14:I14) | K14: =J14/$J$506
A15: 10 | B15: DETECH TOWER II | C15: =SUMIFS(DATA!$M:$M,DATA!$C:$C,$B15,DATA!$N:$N,">="&DATE(C$5,1,1),DATA!$N:$N,"<="&DATE(C$5,12,31)) | D15: =SUMIFS(DATA!$M:$M,DATA!$C:$C,$B15,DATA!$N:$N,">="&DATE(D$5,1,1),DATA!$N:$N,"<="&DATE(D$5,12,31)) | E15: =SUMIFS(DATA!$M:$M,DATA!$C:$C,$B15,DATA!$N:$N,">="&DATE(E$5,1,1),DATA!$N:$N,"<="&DATE(E$5,12,31)) | F15: =SUMIFS(DATA!$M:$M,DATA!$C:$C,$B15,DATA!$N:$N,">="&DATE(F$5,1,1),DATA!$N:$N,"<="&DATE(F$5,12,31)) | G15: =SUMIFS(DATA!$M:$M,DATA!$C:$C,$B15,DATA!$N:$N,">="&DATE(G$5,1,1),DATA!$N:$N,"<="&DATE(G$5,12,31)) | H15: =SUMIFS(DATA!$M:$M,DATA!$C:$C,$B15,DATA!$N:$N,">="&DATE(H$5,1,1),DATA!$N:$N,"<="&DATE(H$5,12,31)) | I15: =SUMIFS(DATA!$M:$M,DATA!$C:$C,$B15,DATA!$N:$N,">="&DATE(I$5,1,1),DATA!$N:$N,"<="&DATE(I$5,12,31)) | J15: =SUM(C15:I15) | K15: =J15/$J$506
A16: 11 | B16: WIDIA SHINKI VIETNAM | C16: =SUMIFS(DATA!$M:$M,DATA!$C:$C,$B16,DATA!$N:$N,">="&DATE(C$5,1,1),DATA!$N:$N,"<="&DATE(C$5,12,31)) | D16: =SUMIFS(DATA!$M:$M,DATA!$C:$C,$B16,DATA!$N:$N,">="&DATE(D$5,1,1),DATA!$N:$N,"<="&DATE(D$5,12,31)) | E16: =SUMIFS(DATA!$M:$M,DATA!$C:$C,$B16,DATA!$N:$N,">="&DATE(E$5,1,1),DATA!$N:$N,"<="&DATE(E$5,12,31)) | F16: =SUMIFS(DATA!$M:$M,DATA!$C:$C,$B16,DATA!$N:$N,">="&DATE(F$5,1,1),DATA!$N:$N,"<="&DATE(F$5,12,31)) | G16: =SUMIFS(DATA!$M:$M,DATA!$C:$C,$B16,DATA!$N:$N,">="&DATE(G$5,1,1),DATA!$N:$N,"<="&DATE(G$5,12,31)) | H16: =SUMIFS(DATA!$M:$M,DATA!$C:$C,$B16,DATA!$N:$N,">="&DATE(H$5,1,1),DATA!$N:$N,"<="&DATE(H$5,12,31)) | I16: =SUMIFS(DATA!$M:$M,DATA!$C:$C,$B16,DATA!$N:$N,">="&DATE(I$5,1,1),DATA!$N:$N,"<="&DATE(I$5,12,31)) | J16: =SUM(C16:I16) | K16: =J16/$J$506
A17: 12 | B17: GENTHERM VIETNAM CO., LTD | C17: =SUMIFS(DATA!$M:$M,DATA!$C:$C,$B17,DATA!$N:$N,">="&DATE(C$5,1,1),DATA!$N:$N,"<="&DATE(C$5,12,31)) | D17: =SUMIFS(DATA!$M:$M,DATA!$C:$C,$B17,DATA!$N:$N,">="&DATE(D$5,1,1),DATA!$N:$N,"<="&DATE(D$5,12,31)) | E17: =SUMIFS(DATA!$M:$M,DATA!$C:$C,$B17,DATA!$N:$N,">="&DATE(E$5,1,1),DATA!$N:$N,"<="&DATE(E$5,12,31)) | F17: =SUMIFS(DATA!$M:$M,DATA!$C:$C,$B17,DATA!$N:$N,">="&DATE(F$5,1,1),DATA!$N:$N,"<="&DATE(F$5,12,31)) | G17: =SUMIFS(DATA!$M:$M,DATA!$C:$C,$B17,DATA!$N:$N,">="&DATE(G$5,1,1),DATA!$N:$N,"<="&DATE(G$5,12,31)) | H17: =SUMIFS(DATA!$M:$M,DATA!$C:$C,$B17,DATA!$N:$N,">="&DATE(H$5,1,1),DATA!$N:$N,"<="&DATE(H$5,12,31)) | I17: =SUMIFS(DATA!$M:$M,DATA!$C:$C,$B17,DATA!$N:$N,">="&DATE(I$5,1,1),DATA!$N:$N,"<="&DATE(I$5,12,31)) | J17: =SUM(C17:I17) | K17: =J17/$J$506
... A161: 156 | B161: CÔNG TY TNHH TƯ VẤN & XÂY LẮP PCCC NTK | C161: =SUMIFS(DATA!$M:$M,DATA!$C:$C,$B161,DATA!$N:$N,">="&DATE(C$5,1,1),DATA!$N:$N,"<="&DATE(C$5,12,31)) | D161: =SUMIFS(DATA!$M:$M,DATA!$C:$C,$B161,DATA!$N:$N,">="&DATE(D$5,1,1),DATA!$N:$N,"<="&DATE(D$5,12,31)) | E161: =SUMIFS(DATA!$M:$M,DATA!$C:$C,$B161,DATA!$N:$N,">="&DATE(E$5,1,1),DATA!$N:$N,"<="&DATE(E$5,12,31)) | F161: =SUMIFS(DATA!$M:$M,DATA!$C:$C,$B161,DATA!$N:$N,">="&DATE(F$5,1,1),DATA!$N:$N,"<="&DATE(F$5,12,31)) | G161: =SUMIFS(DATA!$M:$M,DATA!$C:$C,$B161,DATA!$N:$N,">="&DATE(G$5,1,1),DATA!$N:$N,"<="&DATE(G$5,12,31)) | H161: =SUMIFS(DATA!$M:$M,DATA!$C:$C,$B161,DATA!$N:$N,">="&DATE(H$5,1,1),DATA!$N:$N,"<="&DATE(H$5,12,31)) | I161: =SUMIFS(DATA!$M:$M,DATA!$C:$C,$B161,DATA!$N:$N,">="&DATE(I$5,1,1),DATA!$N:$N,"<="&DATE(I$5,12,31)) | J161: =SUM(C161:I161) | K161: =J161/$J$506
A162: 157 | C162: =SUMIFS(DATA!$M:$M,DATA!$C:$C,$B162,DATA!$N:$N,">="&DATE(C$5,1,1),DATA!$N:$N,"<="&DATE(C$5,12,31)) | D162: =SUMIFS(DATA!$M:$M,DATA!$C:$C,$B162,DATA!$N:$N,">="&DATE(D$5,1,1),DATA!$N:$N,"<="&DATE(D$5,12,31)) | E162: =SUMIFS(DATA!$M:$M,DATA!$C:$C,$B162,DATA!$N:$N,">="&DATE(E$5,1,1),DATA!$N:$N,"<="&DATE(E$5,12,31)) | F162: =SUMIFS(DATA!$M:$M,DATA!$C:$C,$B162,DATA!$N:$N,">="&DATE(F$5,1,1),DATA!$N:$N,"<="&DATE(F$5,12,31)) | G162: =SUMIFS(DATA!$M:$M,DATA!$C:$C,$B162,DATA!$N:$N,">="&DATE(G$5,1,1),DATA!$N:$N,"<="&DATE(G$5,12,31)) | H162: =SUMIFS(DATA!$M:$M,DATA!$C:$C,$B162,DATA!$N:$N,">="&DATE(H$5,1,1),DATA!$N:$N,"<="&DATE(H$5,12,31)) | I162: =SUMIFS(DATA!$M:$M,DATA!$C:$C,$B162,DATA!$N:$N,">="&DATE(I$5,1,1),DATA!$N:$N,"<="&DATE(I$5,12,31)) | J162: =SUM(C162:I162) | K162: =J162/$J$506
A163: 158 | C163: =SUMIFS(DATA!$M:$M,DATA!$C:$C,$B163,DATA!$N:$N,">="&DATE(C$5,1,1),DATA!$N:$N,"<="&DATE(C$5,12,31)) | D163: =SUMIFS(DATA!$M:$M,DATA!$C:$C,$B163,DATA!$N:$N,">="&DATE(D$5,1,1),DATA!$N:$N,"<="&DATE(D$5,12,31)) | E163: =SUMIFS(DATA!$M:$M,DATA!$C:$C,$B163,DATA!$N:$N,">="&DATE(E$5,1,1),DATA!$N:$N,"<="&DATE(E$5,12,31)) | F163: =SUMIFS(DATA!$M:$M,DATA!$C:$C,$B163,DATA!$N:$N,">="&DATE(F$5,1,1),DATA!$N:$N,"<="&DATE(F$5,12,31)) | G163: =SUMIFS(DATA!$M:$M,DATA!$C:$C,$B163,DATA!$N:$N,">="&DATE(G$5,1,1),DATA!$N:$N,"<="&DATE(G$5,12,31)) | H163: =SUMIFS(DATA!$M:$M,DATA!$C:$C,$B163,DATA!$N:$N,">="&DATE(H$5,1,1),DATA!$N:$N,"<="&DATE(H$5,12,31)) | I163: =SUMIFS(DATA!$M:$M,DATA!$C:$C,$B163,DATA!$N:$N,">="&DATE(I$5,1,1),DATA!$N:$N,"<="&DATE(I$5,12,31)) | J163: =SUM(C163:I163) | K163: =J163/$J$506
A164: 159 | C164: =SUMIFS(DATA!$M:$M,DATA!$C:$C,$B164,DATA!$N:$N,">="&DATE(C$5,1,1),DATA!$N:$N,"<="&DATE(C$5,12,31)) | D164: =SUMIFS(DATA!$M:$M,DATA!$C:$C,$B164,DATA!$N:$N,">="&DATE(D$5,1,1),DATA!$N:$N,"<="&DATE(D$5,12,31)) | E164: =SUMIFS(DATA!$M:$M,DATA!$C:$C,$B164,DATA!$N:$N,">="&DATE(E$5,1,1),DATA!$N:$N,"<="&DATE(E$5,12,31)) | F164: =SUMIFS(DATA!$M:$M,DATA!$C:$C,$B164,DATA!$N:$N,">="&DATE(F$5,1,1),DATA!$N:$N,"<="&DATE(F$5,12,31)) | G164: =SUMIFS(DATA!$M:$M,DATA!$C:$C,$B164,DATA!$N:$N,">="&DATE(G$5,1,1),DATA!$N:$N,"<="&DATE(G$5,12,31)) | H164: =SUMIFS(DATA!$M:$M,DATA!$C:$C,$B164,DATA!$N:$N,">="&DATE(H$5,1,1),DATA!$N:$N,"<="&DATE(H$5,12,31)) | I164: =SUMIFS(DATA!$M:$M,DATA!$C:$C,$B164,DATA!$N:$N,">="&DATE(I$5,1,1),DATA!$N:$N,"<="&DATE(I$5,12,31)) | J164: =SUM(C164:I164) | K164: =J164/$J$506
A165: 160 | C165: =SUMIFS(DATA!$M:$M,DATA!$C:$C,$B165,DATA!$N:$N,">="&DATE(C$5,1,1),DATA!$N:$N,"<="&DATE(C$5,12,31)) | D165: =SUMIFS(DATA!$M:$M,DATA!$C:$C,$B165,DATA!$N:$N,">="&DATE(D$5,1,1),DATA!$N:$N,"<="&DATE(D$5,12,31)) | E165: =SUMIFS(DATA!$M:$M,DATA!$C:$C,$B165,DATA!$N:$N,">="&DATE(E$5,1,1),DATA!$N:$N,"<="&DATE(E$5,12,31)) | F165: =SUMIFS(DATA!$M:$M,DATA!$C:$C,$B165,DATA!$N:$N,">="&DATE(F$5,1,1),DATA!$N:$N,"<="&DATE(F$5,12,31)) | G165: =SUMIFS(DATA!$M:$M,DATA!$C:$C,$B165,DATA!$N:$N,">="&DATE(G$5,1,1),DATA!$N:$N,"<="&DATE(G$5,12,31)) | H165: =SUMIFS(DATA!$M:$M,DATA!$C:$C,$B165,DATA!$N:$N,">="&DATE(H$5,1,1),DATA!$N:$N,"<="&DATE(H$5,12,31)) | I165: =SUMIFS(DATA!$M:$M,DATA!$C:$C,$B165,DATA!$N:$N,">="&DATE(I$5,1,1),DATA!$N:$N,"<="&DATE(I$5,12,31)) | J165: =SUM(C165:I165) | K165: =J165/$J$506
A166: 161 | C166: =SUMIFS(DATA!$M:$M,DATA!$C:$C,$B166,DATA!$N:$N,">="&DATE(C$5,1,1),DATA!$N:$N,"<="&DATE(C$5,12,31)) | D166: =SUMIFS(DATA!$M:$M,DATA!$C:$C,$B166,DATA!$N:$N,">="&DATE(D$5,1,1),DATA!$N:$N,"<="&DATE(D$5,12,31)) | E166: =SUMIFS(DATA!$M:$M,DATA!$C:$C,$B166,DATA!$N:$N,">="&DATE(E$5,1,1),DATA!$N:$N,"<="&DATE(E$5,12,31)) | F166: =SUMIFS(DATA!$M:$M,DATA!$C:$C,$B166,DATA!$N:$N,">="&DATE(F$5,1,1),DATA!$N:$N,"<="&DATE(F$5,12,31)) | G166: =SUMIFS(DATA!$M:$M,DATA!$C:$C,$B166,DATA!$N:$N,">="&DATE(G$5,1,1),DATA!$N:$N,"<="&DATE(G$5,12,31)) | H166: =SUMIFS(DATA!$M:$M,DATA!$C:$C,$B166,DATA!$N:$N,">="&DATE(H$5,1,1),DATA!$N:$N,"<="&DATE(H$5,12,31)) | I166: =SUMIFS(DATA!$M:$M,DATA!$C:$C,$B166,DATA!$N:$N,">="&DATE(I$5,1,1),DATA!$N:$N,"<="&DATE(I$5,12,31)) | J166: =SUM(C166:I166) | K166: =J166/$J$506
A167: 162 | C167: =SUMIFS(DATA!$M:$M,DATA!$C:$C,$B167,DATA!$N:$N,">="&DATE(C$5,1,1),DATA!$N:$N,"<="&DATE(C$5,12,31)) | D167: =SUMIFS(DATA!$M:$M,DATA!$C:$C,$B167,DATA!$N:$N,">="&DATE(D$5,1,1),DATA!$N:$N,"<="&DATE(D$5,12,31)) | E167: =SUMIFS(DATA!$M:$M,DATA!$C:$C,$B167,DATA!$N:$N,">="&DATE(E$5,1,1),DATA!$N:$N,"<="&DATE(E$5,12,31)) | F167: =SUMIFS(DATA!$M:$M,DATA!$C:$C,$B167,DATA!$N:$N,">="&DATE(F$5,1,1),DATA!$N:$N,"<="&DATE(F$5,12,31)) | G167: =SUMIFS(DATA!$M:$M,DATA!$C:$C,$B167,DATA!$N:$N,">="&DATE(G$5,1,1),DATA!$N:$N,"<="&DATE(G$5,12,31)) | H167: =SUMIFS(DATA!$M:$M,DATA!$C:$C,$B167,DATA!$N:$N,">="&DATE(H$5,1,1),DATA!$N:$N,"<="&DATE(H$5,12,31)) | I167: =SUMIFS(DATA!$M:$M,DATA!$C:$C,$B167,DATA!$N:$N,">="&DATE(I$5,1,1),DATA!$N:$N,"<="&DATE(I$5,12,31)) | J167: =SUM(C167:I167) | K167: =J167/$J$506
A168: 163 | C168: =SUMIFS(DATA!$M:$M,DATA!$C:$C,$B168,DATA!$N:$N,">="&DATE(C$5,1,1),DATA!$N:$N,"<="&DATE(C$5,12,31)) | D168: =SUMIFS(DATA!$M:$M,DATA!$C:$C,$B168,DATA!$N:$N,">="&DATE(D$5,1,1),DATA!$N:$N,"<="&DATE(D$5,12,31)) | E168: =SUMIFS(DATA!$M:$M,DATA!$C:$C,$B168,DATA!$N:$N,">="&DATE(E$5,1,1),DATA!$N:$N,"<="&DATE(E$5,12,31)) | F168: =SUMIFS(DATA!$M:$M,DATA!$C:$C,$B168,DATA!$N:$N,">="&DATE(F$5,1,1),DATA!$N:$N,"<="&DATE(F$5,12,31)) | G168: =SUMIFS(DATA!$M:$M,DATA!$C:$C,$B168,DATA!$N:$N,">="&DATE(G$5,1,1),DATA!$N:$N,"<="&DATE(G$5,12,31)) | H168: =SUMIFS(DATA!$M:$M,DATA!$C:$C,$B168,DATA!$N:$N,">="&DATE(H$5,1,1),DATA!$N:$N,"<="&DATE(H$5,12,31)) | I168: =SUMIFS(DATA!$M:$M,DATA!$C:$C,$B168,DATA!$N:$N,">="&DATE(I$5,1,1),DATA!$N:$N,"<="&DATE(I$5,12,31)) | J168: =SUM(C168:I168) | K168: =J168/$J$506
A169: 164 | C169: =SUMIFS(DATA!$M:$M,DATA!$C:$C,$B169,DATA!$N:$N,">="&DATE(C$5,1,1),DATA!$N:$N,"<="&DATE(C$5,12,31)) | D169: =SUMIFS(DATA!$M:$M,DATA!$C:$C,$B169,DATA!$N:$N,">="&DATE(D$5,1,1),DATA!$N:$N,"<="&DATE(D$5,12,31)) | E169: =SUMIFS(DATA!$M:$M,DATA!$C:$C,$B169,DATA!$N:$N,">="&DATE(E$5,1,1),DATA!$N:$N,"<="&DATE(E$5,12,31)) | F169: =SUMIFS(DATA!$M:$M,DATA!$C:$C,$B169,DATA!$N:$N,">="&DATE(F$5,1,1),DATA!$N:$N,"<="&DATE(F$5,12,31)) | G169: =SUMIFS(DATA!$M:$M,DATA!$C:$C,$B169,DATA!$N:$N,">="&DATE(G$5,1,1),DATA!$N:$N,"<="&DATE(G$5,12,31)) | H169: =SUMIFS(DATA!$M:$M,DATA!$C:$C,$B169,DATA!$N:$N,">="&DATE(H$5,1,1),DATA!$N:$N,"<="&DATE(H$5,12,31)) | I169: =SUMIFS(DATA!$M:$M,DATA!$C:$C,$B169,DATA!$N:$N,">="&DATE(I$5,1,1),DATA!$N:$N,"<="&DATE(I$5,12,31)) | J169: =SUM(C169:I169) | K169: =J169/$J$506
A170: 165 | C170: =SUMIFS(DATA!$M:$M,DATA!$C:$C,$B170,DATA!$N:$N,">="&DATE(C$5,1,1),DATA!$N:$N,"<="&DATE(C$5,12,31)) | D170: =SUMIFS(DATA!$M:$M,DATA!$C:$C,$B170,DATA!$N:$N,">="&DATE(D$5,1,1),DATA!$N:$N,"<="&DATE(D$5,12,31)) | E170: =SUMIFS(DATA!$M:$M,DATA!$C:$C,$B170,DATA!$N:$N,">="&DATE(E$5,1,1),DATA!$N:$N,"<="&DATE(E$5,12,31)) | F170: =SUMIFS(DATA!$M:$M,DATA!$C:$C,$B170,DATA!$N:$N,">="&DATE(F$5,1,1),DATA!$N:$N,"<="&DATE(F$5,12,31)) | G170: =SUMIFS(DATA!$M:$M,DATA!$C:$C,$B170,DATA!$N:$N,">="&DATE(G$5,1,1),DATA!$N:$N,"<="&DATE(G$5,12,31)) | H170: =SUMIFS(DATA!$M:$M,DATA!$C:$C,$B170,DATA!$N:$N,">="&DATE(H$5,1,1),DATA!$N:$N,"<="&DATE(H$5,12,31)) | I170: =SUMIFS(DATA!$M:$M,DATA!$C:$C,$B170,DATA!$N:$N,">="&DATE(I$5,1,1),DATA!$N:$N,"<="&DATE(I$5,12,31)) | J170: =SUM(C170:I170) | K170: =J170/$J$506
