Workbook

Sheet DATA
E1: PROJECT COMPLETED REPORT FOLLOW UP
B2: 1. Pending report (báo cáo chưa hoàn thiện) (P): Công việc chưa thực hiện được (do KH chưa sắp lịch, bộ phận chưa/quên sắp lịch)...hoặc thực hiện chưa xong/ Works haven't been done
A3: NOTE: | B3: 2. Missing report (báo cáo thiếu) (M): Công việc đã thực hiện (chưa nộp báo cáo về VP/ KH chưa ký/ mất báo cáo…)/ Works done but Report havent been submitted to Office
B4: 3. Cancel report: CV không thực hiện do KH hủy ko yêu cầu/ Works cancel because client not require
B5: 4. Các dự án đã thực hiện xong, không có báo cáo do KH không gửi trả lại: đóng dự án và ghi nhận mức "Không hài lòng" khi đủ 3 yếu tố: - KH đã thanh toán xong - Dự án hết thời hạn bảo hành/ hết hiệu lực hợp đồng - BOD đã xem xét
A6: Tên khách hàng | B6: Địa điểm thực hiện dịch vụ | C6: Mã số dự án | D6: Mã số dự án | E6: Tên dự án | F6: Phân loại | G6: Tính or miễn phí | H6: Kế hoạch Planed | J6: Thực tế Actual | L6: Tình trạng chung | M6: Ý kiến của KH (nếu có) | N6: P.trách dự án | O6: Hành động khắc phục | P6: Mức hài lòng | Q6: Ghi chú | R6: PIC - Leader | S6: Tháng đóng dự án | T6: Mức hài lòng không được đo đếm đối với các mã gộp
A7: Customer name | B7: Service Location | C7: Project number | D7: Project number | E7: Project name | F7: Classify | G7: Charge / Free services | H7: Ngày bắt đầu Start date | I7: Ngày kết thúc Finish date | J7: Ngày hoàn thành / ngày kí báo cáo Date signed report | K7: Ngày nhận báo cáo / Received report date | L7: General Status | M7: Customer's comment (if any | N7: P.I.C | O7: Follow up action | P7: Satisfaction feedback | Q7: Remarks

Sheet General
G1: CHỈ SỐ HÀI LÒNG CỦA KHÁCH HÀNG | N1: Prepared by: | O1: Hang.ntt
G2: Customer Satisfaction Report | N2: Checked by: | O2: Phuc.vx
A3: SPS SERVICES.,JSC | F3: YEAR: | G3: 2023 | N3: Updated to: | O3: =TODAY() -> 46004
B4: Công thức trung gian lọc ra ngày cuối tháng | D4: 31 | E4: =DAY(EOMONTH(DATE(G3,E5,1),0)) -> 28 | F4: 31 | G4: 30 | H4: 31 | I4: 30 | J4: 31 | K4: 31 | L4: 30 | M4: 31 | N4: 30 | O4: 31
B5: THÁNG / MONTH | C5: Phân loại | D5: 1 | E5: 2 | F5: 3 | G5: 4 | H5: 5 | I5: 6 | J5: 7 | K5: 8 | L5: 9 | M5: 10 | N5: 11 | O5: 12 | P5: TOTAL | Q5: %
A6: REPORT | B6: SỐ BÁO CÁO THEO KẾ HOẠCH NUMBER OF REPORTS AS SCHEDULED | D6: =COUNTIFS(DATA!$I:$I,">="&DATE($G$3,D$5,1),DATA!$I:$I,"<="&DATE($G$3,D$5,D$4)) -> 0 | E6: =COUNTIFS(DATA!$I:$I,">="&DATE($G$3,E$5,1),DATA!$I:$I,"<="&DATE($G$3,E$5,E$4)) -> 0 | F6: =COUNTIFS(DATA!$I:$I,">="&DATE($G$3,F$5,1),DATA!$I:$I,"<="&DATE($G$3,F$5,F$4)) -> 0 | G6: =COUNTIFS(DATA!$I:$I,">="&DATE($G$3,G$5,1),DATA!$I:$I,"<="&DATE($G$3,G$5,G$4)) -> 0 | H6: =COUNTIFS(DATA!$I:$I,">="&DATE($G$3,H$5,1),DATA!$I:$I,"<="&DATE($G$3,H$5,H$4)) -> 0 | I6: =COUNTIFS(DATA!$I:$I,">="&DATE($G$3,I$5,1),DATA!$I:$I,"<="&DATE($G$3,I$5,I$4)) -> 0 | J6: =COUNTIFS(DATA!$I:$I,">="&DATE($G$3,J$5,1),DATA!$I:$I,"<="&DATE($G$3,J$5,J$4)) -> 0 | K6: =COUNTIFS(DATA!$I:$I,">="&DATE($G$3,K$5,1),DATA!$I:$I,"<="&DATE($G$3,K$5,K$4)) -> 0 | ... O6: =COUNTIFS(DATA!$I:$I,">="&DATE($G$3,O$5,1),DATA!$I:$I,"<="&DATE($G$3,O$5,O$4)) -> 0 | P6: =SUM(D6:O6) -> 0 | Q6: 1
B7: SỐ BÁO CÁO ĐÃ NHẬN VỀ RECEIVED REPORTS | D7: =COUNTIFS(DATA!$K:$K,">0",DATA!$I:$I,">="&DATE($G$3,D$5,1),DATA!$I:$I,"<="&DATE($G$3,D$5,D$4)) -> 0 | E7: =COUNTIFS(DATA!$K:$K,">0",DATA!$I:$I,">="&DATE($G$3,E$5,1),DATA!$I:$I,"<="&DATE($G$3,E$5,E$4)) -> 0 | F7: =COUNTIFS(DATA!$K:$K,">0",DATA!$I:$I,">="&DATE($G$3,F$5,1),DATA!$I:$I,"<="&DATE($G$3,F$5,F$4)) -> 0 | G7: =COUNTIFS(DATA!$K:$K,">0",DATA!$I:$I,">="&DATE($G$3,G$5,1),DATA!$I:$I,"<="&DATE($G$3,G$5,G$4)) -> 0 | H7: =COUNTIFS(DATA!$K:$K,">0",DATA!$I:$I,">="&DATE($G$3,H$5,1),DATA!$I:$I,"<="&DATE($G$3,H$5,H$4)) -> 0 | I7: =COUNTIFS(DATA!$K:$K,">0",DATA!$I:$I,">="&DATE($G$3,I$5,1),DATA!$I:$I,"<="&DATE($G$3,I$5,I$4)) -> 0 | J7: =COUNTIFS(DATA!$K:$K,">0",DATA!$I:$I,">="&DATE($G$3,J$5,1),DATA!$I:$I,"<="&DATE($G$3,J$5,J$4)) -> 0 | K7: =COUNTIFS(DATA!$K:$K,">0",DATA!$I:$I,">="&DATE($G$3,K$5,1),DATA!$I:$I,"<="&DATE($G$3,K$5,K$4)) -> 0 | ... O7: =COUNTIFS(DATA!$K:$K,">0",DATA!$I:$I,">="&DATE($G$3,O$5,1),DATA!$I:$I,"<="&DATE($G$3,O$5,O$4)) -> 0 | P7: =SUM(D7:O7) -> 0 | Q7: =P7/P6 -> #DIV/0!
B8: SỐ HẠNG MỤC CHƯA HOÀN THÀNH PENDING ITEMS | D8: =IF(TODAY()>DATE($G$3,D5,D4),D6-D7,0) -> 0 | E8: =IF(TODAY()>DATE($G$3,E5,E4),E6-E7,0) -> 0 | F8: =IF(TODAY()>DATE($G$3,F5,F4),F6-F7,0) -> 0 | G8: =IF(TODAY()>DATE($G$3,G5,G4),G6-G7,0) -> 0 | H8: =IF(TODAY()>DATE($G$3,H5,H4),H6-H7,0) -> 0 | I8: =IF(TODAY()>DATE($G$3,I5,I4),I6-I7,0) -> 0 | J8: =IF(TODAY()>DATE($G$3,J5,J4),J6-J7,0) -> 0 | K8: =IF(TODAY()>DATE($G$3,K5,K4),K6-K7,0) -> 0 | ... O8: =IF(TODAY()>DATE($G$3,O5,O4),O6-O7,0) -> 0 | P8: =SUM(D8:O8) -> 0 | Q8: =P8/P7 -> #DIV/0!
A9: CLIENT FEED BACK | B9: SỐ BÁO CÁO CÓ PHẢN HỒI KHÁCH HÀNG NUMBER OF REPORTS WITH CUSTOMER'S FEED BACK | D9: =SUM(D10:D13) -> 0 | E9: =SUM(E10:E13) -> 0 | F9: =SUM(F10:F13) -> 0 | G9: =SUM(G10:G13) -> 0 | H9: =SUM(H10:H13) -> 0 | I9: =SUM(I10:I13) -> 0 | J9: =SUM(J10:J13) -> 0 | K9: =SUM(K10:K13) -> 0 | ... O9: =SUM(O10:O13) -> 0 | P9: =SUM(D9:O9) -> 0 | Q9: =P9/P7 -> #DIV/0!
B10: RẤT HÀI LÒNG EXCEEDED SATISFY | C10: E | D10: =COUNTIFS(DATA!$P:$P,"=E",DATA!$K:$K,">="&DATE($G$3,D$5,1),DATA!$K:$K,"<="&DATE($G$3,D$5,D$4)) -> 0 | E10: =COUNTIFS(DATA!$P:$P,"=E",DATA!$K:$K,">="&DATE($G$3,E$5,1),DATA!$K:$K,"<="&DATE($G$3,E$5,E$4)) -> 0 | F10: =COUNTIFS(DATA!$P:$P,"=E",DATA!$K:$K,">="&DATE($G$3,F$5,1),DATA!$K:$K,"<="&DATE($G$3,F$5,F$4)) -> 0 | G10: =COUNTIFS(DATA!$P:$P,"=E",DATA!$K:$K,">="&DATE($G$3,G$5,1),DATA!$K:$K,"<="&DATE($G$3,G$5,G$4)) -> 0 | H10: =COUNTIFS(DATA!$P:$P,"=E",DATA!$K:$K,">="&DATE($G$3,H$5,1),DATA!$K:$K,"<="&DATE($G$3,H$5,H$4)) -> 0 | I10: =COUNTIFS(DATA!$P:$P,"=E",DATA!$K:$K,">="&DATE($G$3,I$5,1),DATA!$K:$K,"<="&DATE($G$3,I$5,I$4)) -> 0 | J10: =COUNTIFS(DATA!$P:$P,"=E",DATA!$K:$K,">="&DATE($G$3,J$5,1),DATA!$K:$K,"<="&DATE($G$3,J$5,J$4)) -> 0 | K10: =COUNTIFS(DATA!$P:$P,"=E",DATA!$K:$K,">="&DATE($G$3,K$5,1),DATA!$K:$K,"<="&DATE($G$3,K$5,K$4)) -> 0 | ... O10: =COUNTIFS(DATA!$P:$P,"=E",DATA!$K:$K,">="&DATE($G$3,O$5,1),DATA!$K:$K,"<="&DATE($G$3,O$5,O$4)) -> 0 | P10: =SUM(D10:O10) -> 0 | Q10: =P10/$P$9 -> #DIV/0!
B11: HÀI LÒNG SATISFIED | C11: S | D11: =COUNTIFS(DATA!$P:$P,"=S",DATA!$K:$K,">="&DATE($G$3,D$5,1),DATA!$K:$K,"<="&DATE($G$3,D$5,D$4)) -> 0 | E11: =COUNTIFS(DATA!$P:$P,"=S",DATA!$K:$K,">="&DATE($G$3,E$5,1),DATA!$K:$K,"<="&DATE($G$3,E$5,E$4)) -> 0 | F11: =COUNTIFS(DATA!$P:$P,"=S",DATA!$K:$K,">="&DATE($G$3,F$5,1),DATA!$K:$K,"<="&DATE($G$3,F$5,F$4)) -> 0 | G11: =COUNTIFS(DATA!$P:$P,"=S",DATA!$K:$K,">="&DATE($G$3,G$5,1),DATA!$K:$K,"<="&DATE($G$3,G$5,G$4)) -> 0 | H11: =COUNTIFS(DATA!$P:$P,"=S",DATA!$K:$K,">="&DATE($G$3,H$5,1),DATA!$K:$K,"<="&DATE($G$3,H$5,H$4)) -> 0 | I11: =COUNTIFS(DATA!$P:$P,"=S",DATA!$K:$K,">="&DATE($G$3,I$5,1),DATA!$K:$K,"<="&DATE($G$3,I$5,I$4)) -> 0 | J11: =COUNTIFS(DATA!$P:$P,"=S",DATA!$K:$K,">="&DATE($G$3,J$5,1),DATA!$K:$K,"<="&DATE($G$3,J$5,J$4)) -> 0 | K11: =COUNTIFS(DATA!$P:$P,"=S",DATA!$K:$K,">="&DATE($G$3,K$5,1),DATA!$K:$K,"<="&DATE($G$3,K$5,K$4)) -> 0 | ... O11: =COUNTIFS(DATA!$P:$P,"=S",DATA!$K:$K,">="&DATE($G$3,O$5,1),DATA!$K:$K,"<="&DATE($G$3,O$5,O$4)) -> 0 | P11: =SUM(D11:O11) -> 0 | Q11: =P11/$P$9 -> #DIV/0!
B12: CHẤP NHẬN ACCEPTABLE | C12: A | D12: =COUNTIFS(DATA!$P:$P,"=A",DATA!$K:$K,">="&DATE($G$3,D$5,1),DATA!$K:$K,"<="&DATE($G$3,D$5,D$4)) -> 0 | E12: =COUNTIFS(DATA!$P:$P,"=A",DATA!$K:$K,">="&DATE($G$3,E$5,1),DATA!$K:$K,"<="&DATE($G$3,E$5,E$4)) -> 0 | F12: =COUNTIFS(DATA!$P:$P,"=A",DATA!$K:$K,">="&DATE($G$3,F$5,1),DATA!$K:$K,"<="&DATE($G$3,F$5,F$4)) -> 0 | G12: =COUNTIFS(DATA!$P:$P,"=A",DATA!$K:$K,">="&DATE($G$3,G$5,1),DATA!$K:$K,"<="&DATE($G$3,G$5,G$4)) -> 0 | H12: =COUNTIFS(DATA!$P:$P,"=A",DATA!$K:$K,">="&DATE($G$3,H$5,1),DATA!$K:$K,"<="&DATE($G$3,H$5,H$4)) -> 0 | I12: =COUNTIFS(DATA!$P:$P,"=A",DATA!$K:$K,">="&DATE($G$3,I$5,1),DATA!$K:$K,"<="&DATE($G$3,I$5,I$4)) -> 0 | J12: =COUNTIFS(DATA!$P:$P,"=A",DATA!$K:$K,">="&DATE($G$3,J$5,1),DATA!$K:$K,"<="&DATE($G$3,J$5,J$4)) -> 0 | K12: =COUNTIFS(DATA!$P:$P,"=A",DATA!$K:$K,">="&DATE($G$3,K$5,1),DATA!$K:$K,"<="&DATE($G$3,K$5,K$4)) -> 0 | ... O12: =COUNTIFS(DATA!$P:$P,"=A",DATA!$K:$K,">="&DATE($G$3,O$5,1),DATA!$K:$K,"<="&DATE($G$3,O$5,O$4)) -> 0 | P12: =SUM(D12:O12) -> 0 | Q12: =P12/$P$9 -> #DIV/0!
B13: KHÔNG HÀI LÒNG DISSATISFIED | C13: D | D13: =COUNTIFS(DATA!$P:$P,"=D",DATA!$K:$K,">="&DATE($G$3,D$5,1),DATA!$K:$K,"<="&DATE($G$3,D$5,D$4)) -> 0 | E13: =COUNTIFS(DATA!$P:$P,"=D",DATA!$K:$K,">="&DATE($G$3,E$5,1),DATA!$K:$K,"<="&DATE($G$3,E$5,E$4)) -> 0 | F13: =COUNTIFS(DATA!$P:$P,"=D",DATA!$K:$K,">="&DATE($G$3,F$5,1),DATA!$K:$K,"<="&DATE($G$3,F$5,F$4)) -> 0 | G13: =COUNTIFS(DATA!$P:$P,"=D",DATA!$K:$K,">="&DATE($G$3,G$5,1),DATA!$K:$K,"<="&DATE($G$3,G$5,G$4)) -> 0 | H13: =COUNTIFS(DATA!$P:$P,"=D",DATA!$K:$K,">="&DATE($G$3,H$5,1),DATA!$K:$K,"<="&DATE($G$3,H$5,H$4)) -> 0 | I13: =COUNTIFS(DATA!$P:$P,"=D",DATA!$K:$K,">="&DATE($G$3,I$5,1),DATA!$K:$K,"<="&DATE($G$3,I$5,I$4)) -> 0 | J13: =COUNTIFS(DATA!$P:$P,"=D",DATA!$K:$K,">="&DATE($G$3,J$5,1),DATA!$K:$K,"<="&DATE($G$3,J$5,J$4)) -> 0 | K13: =COUNTIFS(DATA!$P:$P,"=D",DATA!$K:$K,">="&DATE($G$3,K$5,1),DATA!$K:$K,"<="&DATE($G$3,K$5,K$4)) -> 0 | ... O13: =COUNTIFS(DATA!$P:$P,"=D",DATA!$K:$K,">="&DATE($G$3,O$5,1),DATA!$K:$K,"<="&DATE($G$3,O$5,O$4)) -> 0 | P13: =SUM(D13:O13) -> 0 | Q13: =P13/$P$9 -> #DIV/0!
A14: PERCENTAGE | B14: MỤC TIÊU MỨC ĐỘ HÀI LÒNG TARGET OF SATISFIED LEVEL | D14: 0.95 | E14: =$D$14 -> 0.95 | F14: =$D$14 -> 0.95 | G14: =$D$14 -> 0.95 | H14: =$D$14 -> 0.95 | I14: =$D$14 -> 0.95 | J14: =$D$14 -> 0.95 | K14: =$D$14 -> 0.95 | L14: =$D$14 -> 0.95 | ... P14: =$D$14 -> 0.95
B15: % MỨC ĐỘ HÀI LÒNG PERCENTAGE OF SATISFIED LEVEL | D15: =IF(D9>0,(D11+D10)/D9,"") | E15: =IF(E9>0,(E11+E10)/E9,"") | F15: =IF(F9>0,(F11+F10)/F9,"") | G15: =IF(G9>0,(G11+G10)/G9,"") | H15: =IF(H9>0,(H11+H10)/H9,"") | I15: =IF(I9>0,(I11+I10)/I9,"") | J15: =IF(J9>0,(J11+J10)/J9,"") | K15: =IF(K9>0,(K11+K10)/K9,"") | ... P15: =IF(P9>0,(P11+P10)/P9,"")
P16: =P15

Sheet Yearly Staff Satisfaction
F1: CHỈ SỐ HÀI LÒNG CỦA KHÁCH HÀNG ĐỐI VỚI NHÂN VIÊN | M1: Prepared by: | N1: Hang.ntt
F2: ASSESSMENT OF CUSTOMER SATISFACTION FOR EACH EMPLOYEES | M2: Checked by: | N2: Phuc.vx
A3: SPS SERVICES.,JSC | E3: YEAR: | F3: 2025 | M3: Updated to: | N3: =TODAY() -> 46004
B5: Công thức trung gian lọc ra ngày cuối tháng | C5: 31 | D5: =DAY(EOMONTH(DATE(F3,D6,1),0)) -> 28 | E5: 31 | F5: 30 | G5: 31 | H5: 30 | I5: 31 | J5: 31 | K5: 30 | L5: 31 | M5: 30 | N5: 31
A6: STT No. | B6: Tên nhân viên Full name | C6: 1 | D6: 2 | E6: 3 | F6: 4 | G6: 5 | H6: 6 | I6: 7 | J6: 8 | K6: 9 | L6: 10 | M6: 11 | N6: 12 | O6: TOTAL | Q6: Ký kiệu trung gian cho công thức tự động
A7: STT No. | B7: Tên nhân viên Full name | C7: JAN | D7: FEB | E7: MAR | F7: APR | G7: MAY | H7: JUN | I7: JUL | J7: AUG | K7: SEP | L7: OCT | M7: NOV | N7: DEC | O7: TOTAL | Q7: Ký kiệu trung gian cho công thức tự động
A8: 13 | B8: =VLOOKUP(Q8, StaffList!B:C,2,FALSE) -> Nguyễn Văn Đức | C8: =(COUNTIFS(DATA!$P:$P,"=E",DATA!$K:$K,">="&DATE($F$3,C$6,1),DATA!$K:$K,"<="&DATE($F$3,C$6,C$5),DATA!$N:$N,$Q8)*10)+COUNTIFS(DATA!$P:$P,"=S",DATA!$K:$K,">="&DATE($F$3,C$6,1),DATA!$K:$K,"<="&DATE($F$3,C$6,C$5),DATA!$N:$N,$Q8) -> 0 | D8: =(COUNTIFS(DATA!$P:$P,"=E",DATA!$K:$K,">="&DATE($F$3,D$6,1),DATA!$K:$K,"<="&DATE($F$3,D$6,D$5),DATA!$N:$N,$Q8)*10)+COUNTIFS(DATA!$P:$P,"=S",DATA!$K:$K,">="&DATE($F$3,D$6,1),DATA!$K:$K,"<="&DATE($F$3,D$6,D$5),DATA!$N:$N,$Q8) -> 0 | E8: =(COUNTIFS(DATA!$P:$P,"=E",DATA!$K:$K,">="&DATE($F$3,E$6,1),DATA!$K:$K,"<="&DATE($F$3,E$6,E$5),DATA!$N:$N,$Q8)*10)+COUNTIFS(DATA!$P:$P,"=S",DATA!$K:$K,">="&DATE($F$3,E$6,1),DATA!$K:$K,"<="&DATE($F$3,E$6,E$5),DATA!$N:$N,$Q8) -> 0 | F8: =(COUNTIFS(DATA!$P:$P,"=E",DATA!$K:$K,">="&DATE($F$3,F$6,1),DATA!$K:$K,"<="&DATE($F$3,F$6,F$5),DATA!$N:$N,$Q8)*10)+COUNTIFS(DATA!$P:$P,"=S",DATA!$K:$K,">="&DATE($F$3,F$6,1),DATA!$K:$K,"<="&DATE($F$3,F$6,F$5),DATA!$N:$N,$Q8) -> 0 | G8: =(COUNTIFS(DATA!$P:$P,"=E",DATA!$K:$K,">="&DATE($F$3,G$6,1),DATA!$K:$K,"<="&DATE($F$3,G$6,G$5),DATA!$N:$N,$Q8)*10)+COUNTIFS(DATA!$P:$P,"=S",DATA!$K:$K,">="&DATE($F$3,G$6,1),DATA!$K:$K,"<="&DATE($F$3,G$6,G$5),DATA!$N:$N,$Q8) -> 0 | H8: =(COUNTIFS(DATA!$P:$P,"=E",DATA!$K:$K,">="&DATE($F$3,H$6,1),DATA!$K:$K,"<="&DATE($F$3,H$6,H$5),DATA!$N:$N,$Q8)*10)+COUNTIFS(DATA!$P:$P,"=S",DATA!$K:$K,">="&DATE($F$3,H$6,1),DATA!$K:$K,"<="&DATE($F$3,H$6,H$5),DATA!$N:$N,$Q8) -> 0 | I8: =(COUNTIFS(DATA!$P:$P,"=E",DATA!$K:$K,">="&DATE($F$3,I$6,1),DATA!$K:$K,"<="&DATE($F$3,I$6,I$5),DATA!$N:$N,$Q8)*10)+COUNTIFS(DATA!$P:$P,"=S",DATA!$K:$K,">="&DATE($F$3,I$6,1),DATA!$K:$K,"<="&DATE($F$3,I$6,I$5),DATA!$N:$N,$Q8) -> 0 | J8: =(COUNTIFS(DATA!$P:$P,"=E",DATA!$K:$K,">="&DATE($F$3,J$6,1),DATA!$K:$K,"<="&DATE($F$3,J$6,J$5),DATA!$N:$N,$Q8)*10)+COUNTIFS(DATA!$P:$P,"=S",DATA!$K:$K,">="&DATE($F$3,J$6,1),DATA!$K:$K,"<="&DATE($F$3,J$6,J$5),DATA!$N:$N,$Q8) -> 0 | ... N8: =(COUNTIFS(DATA!$P:$P,"=E",DATA!$K:$K,">="&DATE($F$3,N$6,1),DATA!$K:$K,"<="&DATE($F$3,N$6,N$5),DATA!$N:$N,$Q8)*10)+COUNTIFS(DATA!$P:$P,"=S",DATA!$K:$K,">="&DATE($F$3,N$6,1),DATA!$K:$K,"<="&DATE($F$3,N$6,N$5),DATA!$N:$N,$Q8) -> 0 | O8: =SUM(C8:N8) -> 0 | Q8: ="*"&StaffList!B17&"*" -> *Duc.nv*
A9: 11 | B9: =VLOOKUP(Q9, StaffList!B:C,2,FALSE) -> Đỗ Văn Cường | C9: =(COUNTIFS(DATA!$P:$P,"=E",DATA!$K:$K,">="&DATE($F$3,C$6,1),DATA!$K:$K,"<="&DATE($F$3,C$6,C$5),DATA!$N:$N,$Q9)*10)+COUNTIFS(DATA!$P:$P,"=S",DATA!$K:$K,">="&DATE($F$3,C$6,1),DATA!$K:$K,"<="&DATE($F$3,C$6,C$5),DATA!$N:$N,$Q9) -> 0 | D9: =(COUNTIFS(DATA!$P:$P,"=E",DATA!$K:$K,">="&DATE($F$3,D$6,1),DATA!$K:$K,"<="&DATE($F$3,D$6,D$5),DATA!$N:$N,$Q9)*10)+COUNTIFS(DATA!$P:$P,"=S",DATA!$K:$K,">="&DATE($F$3,D$6,1),DATA!$K:$K,"<="&DATE($F$3,D$6,D$5),DATA!$N:$N,$Q9) -> 0 | E9: =(COUNTIFS(DATA!$P:$P,"=E",DATA!$K:$K,">="&DATE($F$3,E$6,1),DATA!$K:$K,"<="&DATE($F$3,E$6,E$5),DATA!$N:$N,$Q9)*10)+COUNTIFS(DATA!$P:$P,"=S",DATA!$K:$K,">="&DATE($F$3,E$6,1),DATA!$K:$K,"<="&DATE($F$3,E$6,E$5),DATA!$N:$N,$Q9) -> 0 | F9: =(COUNTIFS(DATA!$P:$P,"=E",DATA!$K:$K,">="&DATE($F$3,F$6,1),DATA!$K:$K,"<="&DATE($F$3,F$6,F$5),DATA!$N:$N,$Q9)*10)+COUNTIFS(DATA!$P:$P,"=S",DATA!$K:$K,">="&DATE($F$3,F$6,1),DATA!$K:$K,"<="&DATE($F$3,F$6,F$5),DATA!$N:$N,$Q9) -> 0 | G9: =(COUNTIFS(DATA!$P:$P,"=E",DATA!$K:$K,">="&DATE($F$3,G$6,1),DATA!$K:$K,"<="&DATE($F$3,G$6,G$5),DATA!$N:$N,$Q9)*10)+COUNTIFS(DATA!$P:$P,"=S",DATA!$K:$K,">="&DATE($F$3,G$6,1),DATA!$K:$K,"<="&DATE($F$3,G$6,G$5),DATA!$N:$N,$Q9) -> 0 | H9: =(COUNTIFS(DATA!$P:$P,"=E",DATA!$K:$K,">="&DATE($F$3,H$6,1),DATA!$K:$K,"<="&DATE($F$3,H$6,H$5),DATA!$N:$N,$Q9)*10)+COUNTIFS(DATA!$P:$P,"=S",DATA!$K:$K,">="&DATE($F$3,H$6,1),DATA!$K:$K,"<="&DATE($F$3,H$6,H$5),DATA!$N:$N,$Q9) -> 0 | I9: =(COUNTIFS(DATA!$P:$P,"=E",DATA!$K:$K,">="&DATE($F$3,I$6,1),DATA!$K:$K,"<="&DATE($F$3,I$6,I$5),DATA!$N:$N,$Q9)*10)+COUNTIFS(DATA!$P:$P,"=S",DATA!$K:$K,">="&DATE($F$3,I$6,1),DATA!$K:$K,"<="&DATE($F$3,I$6,I$5),DATA!$N:$N,$Q9) -> 0 | J9: =(COUNTIFS(DATA!$P:$P,"=E",DATA!$K:$K,">="&DATE($F$3,J$6,1),DATA!$K:$K,"<="&DATE($F$3,J$6,J$5),DATA!$N:$N,$Q9)*10)+COUNTIFS(DATA!$P:$P,"=S",DATA!$K:$K,">="&DATE($F$3,J$6,1),DATA!$K:$K,"<="&DATE($F$3,J$6,J$5),DATA!$N:$N,$Q9) -> 0 | ... N9: =(COUNTIFS(DATA!$P:$P,"=E",DATA!$K:$K,">="&DATE($F$3,N$6,1),DATA!$K:$K,"<="&DATE($F$3,N$6,N$5),DATA!$N:$N,$Q9)*10)+COUNTIFS(DATA!$P:$P,"=S",DATA!$K:$K,">="&DATE($F$3,N$6,1),DATA!$K:$K,"<="&DATE($F$3,N$6,N$5),DATA!$N:$N,$Q9) -> 0 | O9: =SUM(C9:N9) -> 0 | Q9: ="*"&StaffList!B15&"*" -> *Cuong.dv*
A10: 27 | B10: =VLOOKUP(Q10, StaffList!B:C,2,FALSE) -> Mai Văn Tuấn | C10: =(COUNTIFS(DATA!$P:$P,"=E",DATA!$K:$K,">="&DATE($F$3,C$6,1),DATA!$K:$K,"<="&DATE($F$3,C$6,C$5),DATA!$N:$N,$Q10)*10)+COUNTIFS(DATA!$P:$P,"=S",DATA!$K:$K,">="&DATE($F$3,C$6,1),DATA!$K:$K,"<="&DATE($F$3,C$6,C$5),DATA!$N:$N,$Q10) -> 0 | D10: =(COUNTIFS(DATA!$P:$P,"=E",DATA!$K:$K,">="&DATE($F$3,D$6,1),DATA!$K:$K,"<="&DATE($F$3,D$6,D$5),DATA!$N:$N,$Q10)*10)+COUNTIFS(DATA!$P:$P,"=S",DATA!$K:$K,">="&DATE($F$3,D$6,1),DATA!$K:$K,"<="&DATE($F$3,D$6,D$5),DATA!$N:$N,$Q10) -> 0 | E10: =(COUNTIFS(DATA!$P:$P,"=E",DATA!$K:$K,">="&DATE($F$3,E$6,1),DATA!$K:$K,"<="&DATE($F$3,E$6,E$5),DATA!$N:$N,$Q10)*10)+COUNTIFS(DATA!$P:$P,"=S",DATA!$K:$K,">="&DATE($F$3,E$6,1),DATA!$K:$K,"<="&DATE($F$3,E$6,E$5),DATA!$N:$N,$Q10) -> 0 | F10: =(COUNTIFS(DATA!$P:$P,"=E",DATA!$K:$K,">="&DATE($F$3,F$6,1),DATA!$K:$K,"<="&DATE($F$3,F$6,F$5),DATA!$N:$N,$Q10)*10)+COUNTIFS(DATA!$P:$P,"=S",DATA!$K:$K,">="&DATE($F$3,F$6,1),DATA!$K:$K,"<="&DATE($F$3,F$6,F$5),DATA!$N:$N,$Q10) -> 0 | G10: =(COUNTIFS(DATA!$P:$P,"=E",DATA!$K:$K,">="&DATE($F$3,G$6,1),DATA!$K:$K,"<="&DATE($F$3,G$6,G$5),DATA!$N:$N,$Q10)*10)+COUNTIFS(DATA!$P:$P,"=S",DATA!$K:$K,">="&DATE($F$3,G$6,1),DATA!$K:$K,"<="&DATE($F$3,G$6,G$5),DATA!$N:$N,$Q10) -> 0 | H10: =(COUNTIFS(DATA!$P:$P,"=E",DATA!$K:$K,">="&DATE($F$3,H$6,1),DATA!$K:$K,"<="&DATE($F$3,H$6,H$5),DATA!$N:$N,$Q10)*10)+COUNTIFS(DATA!$P:$P,"=S",DATA!$K:$K,">="&DATE($F$3,H$6,1),DATA!$K:$K,"<="&DATE($F$3,H$6,H$5),DATA!$N:$N,$Q10) -> 0 | I10: =(COUNTIFS(DATA!$P:$P,"=E",DATA!$K:$K,">="&DATE($F$3,I$6,1),DATA!$K:$K,"<="&DATE($F$3,I$6,I$5),DATA!$N:$N,$Q10)*10)+COUNTIFS(DATA!$P:$P,"=S",DATA!$K:$K,">="&DATE($F$3,I$6,1),DATA!$K:$K,"<="&DATE($F$3,I$6,I$5),DATA!$N:$N,$Q10) -> 0 | J10: =(COUNTIFS(DATA!$P:$P,"=E",DATA!$K:$K,">="&DATE($F$3,J$6,1),DATA!$K:$K,"<="&DATE($F$3,J$6,J$5),DATA!$N:$N,$Q10)*10)+COUNTIFS(DATA!$P:$P,"=S",DATA!$K:$K,">="&DATE($F$3,J$6,1),DATA!$K:$K,"<="&DATE($F$3,J$6,J$5),DATA!$N:$N,$Q10) -> 0 | ... N10: =(COUNTIFS(DATA!$P:$P,"=E",DATA!$K:$K,">="&DATE($F$3,N$6,1),DATA!$K:$K,"<="&DATE($F$3,N$6,N$5),DATA!$N:$N,$Q10)*10)+COUNTIFS(DATA!$P:$P,"=S",DATA!$K:$K,">="&DATE($F$3,N$6,1),DATA!$K:$K,"<="&DATE($F$3,N$6,N$5),DATA!$N:$N,$Q10) -> 0 | O10: =SUM(C10:N10) -> 0 | Q10: ="*"&StaffList!B31&"*" -> *Tuan.mv*
A11: 5 | B11: =VLOOKUP(Q11, StaffList!B:C,2,FALSE) -> Hồ Sỹ Hiệp | C11: =(COUNTIFS(DATA!$P:$P,"=E",DATA!$K:$K,">="&DATE($F$3,C$6,1),DATA!$K:$K,"<="&DATE($F$3,C$6,C$5),DATA!$N:$N,$Q11)*10)+COUNTIFS(DATA!$P:$P,"=S",DATA!$K:$K,">="&DATE($F$3,C$6,1),DATA!$K:$K,"<="&DATE($F$3,C$6,C$5),DATA!$N:$N,$Q11) -> 0 | D11: =(COUNTIFS(DATA!$P:$P,"=E",DATA!$K:$K,">="&DATE($F$3,D$6,1),DATA!$K:$K,"<="&DATE($F$3,D$6,D$5),DATA!$N:$N,$Q11)*10)+COUNTIFS(DATA!$P:$P,"=S",DATA!$K:$K,">="&DATE($F$3,D$6,1),DATA!$K:$K,"<="&DATE($F$3,D$6,D$5),DATA!$N:$N,$Q11) -> 0 | E11: =(COUNTIFS(DATA!$P:$P,"=E",DATA!$K:$K,">="&DATE($F$3,E$6,1),DATA!$K:$K,"<="&DATE($F$3,E$6,E$5),DATA!$N:$N,$Q11)*10)+COUNTIFS(DATA!$P:$P,"=S",DATA!$K:$K,">="&DATE($F$3,E$6,1),DATA!$K:$K,"<="&DATE($F$3,E$6,E$5),DATA!$N:$N,$Q11) -> 0 | F11: =(COUNTIFS(DATA!$P:$P,"=E",DATA!$K:$K,">="&DATE($F$3,F$6,1),DATA!$K:$K,"<="&DATE($F$3,F$6,F$5),DATA!$N:$N,$Q11)*10)+COUNTIFS(DATA!$P:$P,"=S",DATA!$K:$K,">="&DATE($F$3,F$6,1),DATA!$K:$K,"<="&DATE($F$3,F$6,F$5),DATA!$N:$N,$Q11) -> 0 | G11: =(COUNTIFS(DATA!$P:$P,"=E",DATA!$K:$K,">="&DATE($F$3,G$6,1),DATA!$K:$K,"<="&DATE($F$3,G$6,G$5),DATA!$N:$N,$Q11)*10)+COUNTIFS(DATA!$P:$P,"=S",DATA!$K:$K,">="&DATE($F$3,G$6,1),DATA!$K:$K,"<="&DATE($F$3,G$6,G$5),DATA!$N:$N,$Q11) -> 0 | H11: =(COUNTIFS(DATA!$P:$P,"=E",DATA!$K:$K,">="&DATE($F$3,H$6,1),DATA!$K:$K,"<="&DATE($F$3,H$6,H$5),DATA!$N:$N,$Q11)*10)+COUNTIFS(DATA!$P:$P,"=S",DATA!$K:$K,">="&DATE($F$3,H$6,1),DATA!$K:$K,"<="&DATE($F$3,H$6,H$5),DATA!$N:$N,$Q11) -> 0 | I11: =(COUNTIFS(DATA!$P:$P,"=E",DATA!$K:$K,">="&DATE($F$3,I$6,1),DATA!$K:$K,"<="&DATE($F$3,I$6,I$5),DATA!$N:$N,$Q11)*10)+COUNTIFS(DATA!$P:$P,"=S",DATA!$K:$K,">="&DATE($F$3,I$6,1),DATA!$K:$K,"<="&DATE($F$3,I$6,I$5),DATA!$N:$N,$Q11) -> 0 | J11: =(COUNTIFS(DATA!$P:$P,"=E",DATA!$K:$K,">="&DATE($F$3,J$6,1),DATA!$K:$K,"<="&DATE($F$3,J$6,J$5),DATA!$N:$N,$Q11)*10)+COUNTIFS(DATA!$P:$P,"=S",DATA!$K:$K,">="&DATE($F$3,J$6,1),DATA!$K:$K,"<="&DATE($F$3,J$6,J$5),DATA!$N:$N,$Q11) -> 0 | ... N11: =(COUNTIFS(DATA!$P:$P,"=E",DATA!$K:$K,">="&DATE($F$3,N$6,1),DATA!$K:$K,"<="&DATE($F$3,N$6,N$5),DATA!$N:$N,$Q11)*10)+COUNTIFS(DATA!$P:$P,"=S",DATA!$K:$K,">="&DATE($F$3,N$6,1),DATA!$K:$K,"<="&DATE($F$3,N$6,N$5),DATA!$N:$N,$Q11) -> 0 | O11: =SUM(C11:N11) -> 0 | Q11: ="*"&StaffList!B9&"*" -> *Hiep.hs*
A12: 14 | B12: =VLOOKUP(Q12, StaffList!B:C,2,FALSE) -> Vũ Xuân Trường | C12: =(COUNTIFS(DATA!$P:$P,"=E",DATA!$K:$K,">="&DATE($F$3,C$6,1),DATA!$K:$K,"<="&DATE($F$3,C$6,C$5),DATA!$N:$N,$Q12)*10)+COUNTIFS(DATA!$P:$P,"=S",DATA!$K:$K,">="&DATE($F$3,C$6,1),DATA!$K:$K,"<="&DATE($F$3,C$6,C$5),DATA!$N:$N,$Q12) -> 0 | D12: =(COUNTIFS(DATA!$P:$P,"=E",DATA!$K:$K,">="&DATE($F$3,D$6,1),DATA!$K:$K,"<="&DATE($F$3,D$6,D$5),DATA!$N:$N,$Q12)*10)+COUNTIFS(DATA!$P:$P,"=S",DATA!$K:$K,">="&DATE($F$3,D$6,1),DATA!$K:$K,"<="&DATE($F$3,D$6,D$5),DATA!$N:$N,$Q12) -> 0 | E12: =(COUNTIFS(DATA!$P:$P,"=E",DATA!$K:$K,">="&DATE($F$3,E$6,1),DATA!$K:$K,"<="&DATE($F$3,E$6,E$5),DATA!$N:$N,$Q12)*10)+COUNTIFS(DATA!$P:$P,"=S",DATA!$K:$K,">="&DATE($F$3,E$6,1),DATA!$K:$K,"<="&DATE($F$3,E$6,E$5),DATA!$N:$N,$Q12) -> 0 | F12: =(COUNTIFS(DATA!$P:$P,"=E",DATA!$K:$K,">="&DATE($F$3,F$6,1),DATA!$K:$K,"<="&DATE($F$3,F$6,F$5),DATA!$N:$N,$Q12)*10)+COUNTIFS(DATA!$P:$P,"=S",DATA!$K:$K,">="&DATE($F$3,F$6,1),DATA!$K:$K,"<="&DATE($F$3,F$6,F$5),DATA!$N:$N,$Q12) -> 0 | G12: =(COUNTIFS(DATA!$P:$P,"=E",DATA!$K:$K,">="&DATE($F$3,G$6,1),DATA!$K:$K,"<="&DATE($F$3,G$6,G$5),DATA!$N:$N,$Q12)*10)+COUNTIFS(DATA!$P:$P,"=S",DATA!$K:$K,">="&DATE($F$3,G$6,1),DATA!$K:$K,"<="&DATE($F$3,G$6,G$5),DATA!$N:$N,$Q12) -> 0 | H12: =(COUNTIFS(DATA!$P:$P,"=E",DATA!$K:$K,">="&DATE($F$3,H$6,1),DATA!$K:$K,"<="&DATE($F$3,H$6,H$5),DATA!$N:$N,$Q12)*10)+COUNTIFS(DATA!$P:$P,"=S",DATA!$K:$K,">="&DATE($F$3,H$6,1),DATA!$K:$K,"<="&DATE($F$3,H$6,H$5),DATA!$N:$N,$Q12) -> 0 | I12: =(COUNTIFS(DATA!$P:$P,"=E",DATA!$K:$K,">="&DATE($F$3,I$6,1),DATA!$K:$K,"<="&DATE($F$3,I$6,I$5),DATA!$N:$N,$Q12)*10)+COUNTIFS(DATA!$P:$P,"=S",DATA!$K:$K,">="&DATE($F$3,I$6,1),DATA!$K:$K,"<="&DATE($F$3,I$6,I$5),DATA!$N:$N,$Q12) -> 0 | J12: =(COUNTIFS(DATA!$P:$P,"=E",DATA!$K:$K,">="&DATE($F$3,J$6,1),DATA!$K:$K,"<="&DATE($F$3,J$6,J$5),DATA!$N:$N,$Q12)*10)+COUNTIFS(DATA!$P:$P,"=S",DATA!$K:$K,">="&DATE($F$3,J$6,1),DATA!$K:$K,"<="&DATE($F$3,J$6,J$5),DATA!$N:$N,$Q12) -> 0 | ... N12: =(COUNTIFS(DATA!$P:$P,"=E",DATA!$K:$K,">="&DATE($F$3,N$6,1),DATA!$K:$K,"<="&DATE($F$3,N$6,N$5),DATA!$N:$N,$Q12)*10)+COUNTIFS(DATA!$P:$P,"=S",DATA!$K:$K,">="&DATE($F$3,N$6,1),DATA!$K:$K,"<="&DATE($F$3,N$6,N$5),DATA!$N:$N,$Q12) -> 0 | O12: =SUM(C12:N12) -> 0 | Q12: ="*"&StaffList!B18&"*" -> *Truong.vx*
A13: 16 | B13: =VLOOKUP(Q13, StaffList!B:C,2,FALSE) -> Lê Minh Đức | C13: =(COUNTIFS(DATA!$P:$P,"=E",DATA!$K:$K,">="&DATE($F$3,C$6,1),DATA!$K:$K,"<="&DATE($F$3,C$6,C$5),DATA!$N:$N,$Q13)*10)+COUNTIFS(DATA!$P:$P,"=S",DATA!$K:$K,">="&DATE($F$3,C$6,1),DATA!$K:$K,"<="&DATE($F$3,C$6,C$5),DATA!$N:$N,$Q13) -> 0 | D13: =(COUNTIFS(DATA!$P:$P,"=E",DATA!$K:$K,">="&DATE($F$3,D$6,1),DATA!$K:$K,"<="&DATE($F$3,D$6,D$5),DATA!$N:$N,$Q13)*10)+COUNTIFS(DATA!$P:$P,"=S",DATA!$K:$K,">="&DATE($F$3,D$6,1),DATA!$K:$K,"<="&DATE($F$3,D$6,D$5),DATA!$N:$N,$Q13) -> 0 | E13: =(COUNTIFS(DATA!$P:$P,"=E",DATA!$K:$K,">="&DATE($F$3,E$6,1),DATA!$K:$K,"<="&DATE($F$3,E$6,E$5),DATA!$N:$N,$Q13)*10)+COUNTIFS(DATA!$P:$P,"=S",DATA!$K:$K,">="&DATE($F$3,E$6,1),DATA!$K:$K,"<="&DATE($F$3,E$6,E$5),DATA!$N:$N,$Q13) -> 0 | F13: =(COUNTIFS(DATA!$P:$P,"=E",DATA!$K:$K,">="&DATE($F$3,F$6,1),DATA!$K:$K,"<="&DATE($F$3,F$6,F$5),DATA!$N:$N,$Q13)*10)+COUNTIFS(DATA!$P:$P,"=S",DATA!$K:$K,">="&DATE($F$3,F$6,1),DATA!$K:$K,"<="&DATE($F$3,F$6,F$5),DATA!$N:$N,$Q13) -> 0 | G13: =(COUNTIFS(DATA!$P:$P,"=E",DATA!$K:$K,">="&DATE($F$3,G$6,1),DATA!$K:$K,"<="&DATE($F$3,G$6,G$5),DATA!$N:$N,$Q13)*10)+COUNTIFS(DATA!$P:$P,"=S",DATA!$K:$K,">="&DATE($F$3,G$6,1),DATA!$K:$K,"<="&DATE($F$3,G$6,G$5),DATA!$N:$N,$Q13) -> 0 | H13: =(COUNTIFS(DATA!$P:$P,"=E",DATA!$K:$K,">="&DATE($F$3,H$6,1),DATA!$K:$K,"<="&DATE($F$3,H$6,H$5),DATA!$N:$N,$Q13)*10)+COUNTIFS(DATA!$P:$P,"=S",DATA!$K:$K,">="&DATE($F$3,H$6,1),DATA!$K:$K,"<="&DATE($F$3,H$6,H$5),DATA!$N:$N,$Q13) -> 0 | I13: =(COUNTIFS(DATA!$P:$P,"=E",DATA!$K:$K,">="&DATE($F$3,I$6,1),DATA!$K:$K,"<="&DATE($F$3,I$6,I$5),DATA!$N:$N,$Q13)*10)+COUNTIFS(DATA!$P:$P,"=S",DATA!$K:$K,">="&DATE($F$3,I$6,1),DATA!$K:$K,"<="&DATE($F$3,I$6,I$5),DATA!$N:$N,$Q13) -> 0 | J13: =(COUNTIFS(DATA!$P:$P,"=E",DATA!$K:$K,">="&DATE($F$3,J$6,1),DATA!$K:$K,"<="&DATE($F$3,J$6,J$5),DATA!$N:$N,$Q13)*10)+COUNTIFS(DATA!$P:$P,"=S",DATA!$K:$K,">="&DATE($F$3,J$6,1),DATA!$K:$K,"<="&DATE($F$3,J$6,J$5),DATA!$N:$N,$Q13) -> 0 | ... N13: =(COUNTIFS(DATA!$P:$P,"=E",DATA!$K:$K,">="&DATE($F$3,N$6,1),DATA!$K:$K,"<="&DATE($F$3,N$6,N$5),DATA!$N:$N,$Q13)*10)+COUNTIFS(DATA!$P:$P,"=S",DATA!$K:$K,">="&DATE($F$3,N$6,1),DATA!$K:$K,"<="&DATE($F$3,N$6,N$5),DATA!$N:$N,$Q13) -> 0 | O13: =SUM(C13:N13) -> 0 | Q13: ="*"&StaffList!B20&"*" -> *Duc.lm*
A14: 7 | B14: =VLOOKUP(Q14, StaffList!B:C,2,FALSE) -> Mông Văn Thương | C14: =(COUNTIFS(DATA!$P:$P,"=E",DATA!$K:$K,">="&DATE($F$3,C$6,1),DATA!$K:$K,"<="&DATE($F$3,C$6,C$5),DATA!$N:$N,$Q14)*10)+COUNTIFS(DATA!$P:$P,"=S",DATA!$K:$K,">="&DATE($F$3,C$6,1),DATA!$K:$K,"<="&DATE($F$3,C$6,C$5),DATA!$N:$N,$Q14) -> 0 | D14: =(COUNTIFS(DATA!$P:$P,"=E",DATA!$K:$K,">="&DATE($F$3,D$6,1),DATA!$K:$K,"<="&DATE($F$3,D$6,D$5),DATA!$N:$N,$Q14)*10)+COUNTIFS(DATA!$P:$P,"=S",DATA!$K:$K,">="&DATE($F$3,D$6,1),DATA!$K:$K,"<="&DATE($F$3,D$6,D$5),DATA!$N:$N,$Q14) -> 0 | E14: =(COUNTIFS(DATA!$P:$P,"=E",DATA!$K:$K,">="&DATE($F$3,E$6,1),DATA!$K:$K,"<="&DATE($F$3,E$6,E$5),DATA!$N:$N,$Q14)*10)+COUNTIFS(DATA!$P:$P,"=S",DATA!$K:$K,">="&DATE($F$3,E$6,1),DATA!$K:$K,"<="&DATE($F$3,E$6,E$5),DATA!$N:$N,$Q14) -> 0 | F14: =(COUNTIFS(DATA!$P:$P,"=E",DATA!$K:$K,">="&DATE($F$3,F$6,1),DATA!$K:$K,"<="&DATE($F$3,F$6,F$5),DATA!$N:$N,$Q14)*10)+COUNTIFS(DATA!$P:$P,"=S",DATA!$K:$K,">="&DATE($F$3,F$6,1),DATA!$K:$K,"<="&DATE($F$3,F$6,F$5),DATA!$N:$N,$Q14) -> 0 | G14: =(COUNTIFS(DATA!$P:$P,"=E",DATA!$K:$K,">="&DATE($F$3,G$6,1),DATA!$K:$K,"<="&DATE($F$3,G$6,G$5),DATA!$N:$N,$Q14)*10)+COUNTIFS(DATA!$P:$P,"=S",DATA!$K:$K,">="&DATE($F$3,G$6,1),DATA!$K:$K,"<="&DATE($F$3,G$6,G$5),DATA!$N:$N,$Q14) -> 0 | H14: =(COUNTIFS(DATA!$P:$P,"=E",DATA!$K:$K,">="&DATE($F$3,H$6,1),DATA!$K:$K,"<="&DATE($F$3,H$6,H$5),DATA!$N:$N,$Q14)*10)+COUNTIFS(DATA!$P:$P,"=S",DATA!$K:$K,">="&DATE($F$3,H$6,1),DATA!$K:$K,"<="&DATE($F$3,H$6,H$5),DATA!$N:$N,$Q14) -> 0 | I14: =(COUNTIFS(DATA!$P:$P,"=E",DATA!$K:$K,">="&DATE($F$3,I$6,1),DATA!$K:$K,"<="&DATE($F$3,I$6,I$5),DATA!$N:$N,$Q14)*10)+COUNTIFS(DATA!$P:$P,"=S",DATA!$K:$K,">="&DATE($F$3,I$6,1),DATA!$K:$K,"<="&DATE($F$3,I$6,I$5),DATA!$N:$N,$Q14) -> 0 | J14: =(COUNTIFS(DATA!$P:$P,"=E",DATA!$K:$K,">="&DATE($F$3,J$6,1),DATA!$K:$K,"<="&DATE($F$3,J$6,J$5),DATA!$N:$N,$Q14)*10)+COUNTIFS(DATA!$P:$P,"=S",DATA!$K:$K,">="&DATE($F$3,J$6,1),DATA!$K:$K,"<="&DATE($F$3,J$6,J$5),DATA!$N:$N,$Q14) -> 0 | ... N14: =(COUNTIFS(DATA!$P:$P,"=E",DATA!$K:$K,">="&DATE($F$3,N$6,1),DATA!$K:$K,"<="&DATE($F$3,N$6,N$5),DATA!$N:$N,$Q14)*10)+COUNTIFS(DATA!$P:$P,"=S",DATA!$K:$K,">="&DATE($F$3,N$6,1),DATA!$K:$K,"<="&DATE($F$3,N$6,N$5),DATA!$N:$N,$Q14) -> 0 | O14: =SUM(C14:N14) -> 0 | Q14: ="*"&StaffList!B11&"*" -> *Thuong.mv*
A15: 8 | B15: =VLOOKUP(Q15, StaffList!B:C,2,FALSE) -> Chu Tiến Dũng | C15: =(COUNTIFS(DATA!$P:$P,"=E",DATA!$K:$K,">="&DATE($F$3,C$6,1),DATA!$K:$K,"<="&DATE($F$3,C$6,C$5),DATA!$N:$N,$Q15)*10)+COUNTIFS(DATA!$P:$P,"=S",DATA!$K:$K,">="&DATE($F$3,C$6,1),DATA!$K:$K,"<="&DATE($F$3,C$6,C$5),DATA!$N:$N,$Q15) -> 0 | D15: =(COUNTIFS(DATA!$P:$P,"=E",DATA!$K:$K,">="&DATE($F$3,D$6,1),DATA!$K:$K,"<="&DATE($F$3,D$6,D$5),DATA!$N:$N,$Q15)*10)+COUNTIFS(DATA!$P:$P,"=S",DATA!$K:$K,">="&DATE($F$3,D$6,1),DATA!$K:$K,"<="&DATE($F$3,D$6,D$5),DATA!$N:$N,$Q15) -> 0 | E15: =(COUNTIFS(DATA!$P:$P,"=E",DATA!$K:$K,">="&DATE($F$3,E$6,1),DATA!$K:$K,"<="&DATE($F$3,E$6,E$5),DATA!$N:$N,$Q15)*10)+COUNTIFS(DATA!$P:$P,"=S",DATA!$K:$K,">="&DATE($F$3,E$6,1),DATA!$K:$K,"<="&DATE($F$3,E$6,E$5),DATA!$N:$N,$Q15) -> 0 | F15: =(COUNTIFS(DATA!$P:$P,"=E",DATA!$K:$K,">="&DATE($F$3,F$6,1),DATA!$K:$K,"<="&DATE($F$3,F$6,F$5),DATA!$N:$N,$Q15)*10)+COUNTIFS(DATA!$P:$P,"=S",DATA!$K:$K,">="&DATE($F$3,F$6,1),DATA!$K:$K,"<="&DATE($F$3,F$6,F$5),DATA!$N:$N,$Q15) -> 0 | G15: =(COUNTIFS(DATA!$P:$P,"=E",DATA!$K:$K,">="&DATE($F$3,G$6,1),DATA!$K:$K,"<="&DATE($F$3,G$6,G$5),DATA!$N:$N,$Q15)*10)+COUNTIFS(DATA!$P:$P,"=S",DATA!$K:$K,">="&DATE($F$3,G$6,1),DATA!$K:$K,"<="&DATE($F$3,G$6,G$5),DATA!$N:$N,$Q15) -> 0 | H15: =(COUNTIFS(DATA!$P:$P,"=E",DATA!$K:$K,">="&DATE($F$3,H$6,1),DATA!$K:$K,"<="&DATE($F$3,H$6,H$5),DATA!$N:$N,$Q15)*10)+COUNTIFS(DATA!$P:$P,"=S",DATA!$K:$K,">="&DATE($F$3,H$6,1),DATA!$K:$K,"<="&DATE($F$3,H$6,H$5),DATA!$N:$N,$Q15) -> 0 | I15: =(COUNTIFS(DATA!$P:$P,"=E",DATA!$K:$K,">="&DATE($F$3,I$6,1),DATA!$K:$K,"<="&DATE($F$3,I$6,I$5),DATA!$N:$N,$Q15)*10)+COUNTIFS(DATA!$P:$P,"=S",DATA!$K:$K,">="&DATE($F$3,I$6,1),DATA!$K:$K,"<="&DATE($F$3,I$6,I$5),DATA!$N:$N,$Q15) -> 0 | J15: =(COUNTIFS(DATA!$P:$P,"=E",DATA!$K:$K,">="&DATE($F$3,J$6,1),DATA!$K:$K,"<="&DATE($F$3,J$6,J$5),DATA!$N:$N,$Q15)*10)+COUNTIFS(DATA!$P:$P,"=S",DATA!$K:$K,">="&DATE($F$3,J$6,1),DATA!$K:$K,"<="&DATE($F$3,J$6,J$5),DATA!$N:$N,$Q15) -> 0 | ... N15: =(COUNTIFS(DATA!$P:$P,"=E",DATA!$K:$K,">="&DATE($F$3,N$6,1),DATA!$K:$K,"<="&DATE($F$3,N$6,N$5),DATA!$N:$N,$Q15)*10)+COUNTIFS(DATA!$P:$P,"=S",DATA!$K:$K,">="&DATE($F$3,N$6,1),DATA!$K:$K,"<="&DATE($F$3,N$6,N$5),DATA!$N:$N,$Q15) -> 0 | O15: =SUM(C15:N15) -> 0 | Q15: ="*"&StaffList!B12&"*" -> *Dung.ct*
A16: 17 | B16: =VLOOKUP(Q16, StaffList!B:C,2,FALSE) -> Phan Xuân Lương | C16: =(COUNTIFS(DATA!$P:$P,"=E",DATA!$K:$K,">="&DATE($F$3,C$6,1),DATA!$K:$K,"<="&DATE($F$3,C$6,C$5),DATA!$N:$N,$Q16)*10)+COUNTIFS(DATA!$P:$P,"=S",DATA!$K:$K,">="&DATE($F$3,C$6,1),DATA!$K:$K,"<="&DATE($F$3,C$6,C$5),DATA!$N:$N,$Q16) -> 0 | D16: =(COUNTIFS(DATA!$P:$P,"=E",DATA!$K:$K,">="&DATE($F$3,D$6,1),DATA!$K:$K,"<="&DATE($F$3,D$6,D$5),DATA!$N:$N,$Q16)*10)+COUNTIFS(DATA!$P:$P,"=S",DATA!$K:$K,">="&DATE($F$3,D$6,1),DATA!$K:$K,"<="&DATE($F$3,D$6,D$5),DATA!$N:$N,$Q16) -> 0 | E16: =(COUNTIFS(DATA!$P:$P,"=E",DATA!$K:$K,">="&DATE($F$3,E$6,1),DATA!$K:$K,"<="&DATE($F$3,E$6,E$5),DATA!$N:$N,$Q16)*10)+COUNTIFS(DATA!$P:$P,"=S",DATA!$K:$K,">="&DATE($F$3,E$6,1),DATA!$K:$K,"<="&DATE($F$3,E$6,E$5),DATA!$N:$N,$Q16) -> 0 | F16: =(COUNTIFS(DATA!$P:$P,"=E",DATA!$K:$K,">="&DATE($F$3,F$6,1),DATA!$K:$K,"<="&DATE($F$3,F$6,F$5),DATA!$N:$N,$Q16)*10)+COUNTIFS(DATA!$P:$P,"=S",DATA!$K:$K,">="&DATE($F$3,F$6,1),DATA!$K:$K,"<="&DATE($F$3,F$6,F$5),DATA!$N:$N,$Q16) -> 0 | G16: =(COUNTIFS(DATA!$P:$P,"=E",DATA!$K:$K,">="&DATE($F$3,G$6,1),DATA!$K:$K,"<="&DATE($F$3,G$6,G$5),DATA!$N:$N,$Q16)*10)+COUNTIFS(DATA!$P:$P,"=S",DATA!$K:$K,">="&DATE($F$3,G$6,1),DATA!$K:$K,"<="&DATE($F$3,G$6,G$5),DATA!$N:$N,$Q16) -> 0 | H16: =(COUNTIFS(DATA!$P:$P,"=E",DATA!$K:$K,">="&DATE($F$3,H$6,1),DATA!$K:$K,"<="&DATE($F$3,H$6,H$5),DATA!$N:$N,$Q16)*10)+COUNTIFS(DATA!$P:$P,"=S",DATA!$K:$K,">="&DATE($F$3,H$6,1),DATA!$K:$K,"<="&DATE($F$3,H$6,H$5),DATA!$N:$N,$Q16) -> 0 | I16: =(COUNTIFS(DATA!$P:$P,"=E",DATA!$K:$K,">="&DATE($F$3,I$6,1),DATA!$K:$K,"<="&DATE($F$3,I$6,I$5),DATA!$N:$N,$Q16)*10)+COUNTIFS(DATA!$P:$P,"=S",DATA!$K:$K,">="&DATE($F$3,I$6,1),DATA!$K:$K,"<="&DATE($F$3,I$6,I$5),DATA!$N:$N,$Q16) -> 0 | J16: =(COUNTIFS(DATA!$P:$P,"=E",DATA!$K:$K,">="&DATE($F$3,J$6,1),DATA!$K:$K,"<="&DATE($F$3,J$6,J$5),DATA!$N:$N,$Q16)*10)+COUNTIFS(DATA!$P:$P,"=S",DATA!$K:$K,">="&DATE($F$3,J$6,1),DATA!$K:$K,"<="&DATE($F$3,J$6,J$5),DATA!$N:$N,$Q16) -> 0 | ... N16: =(COUNTIFS(DATA!$P:$P,"=E",DATA!$K:$K,">="&DATE($F$3,N$6,1),DATA!$K:$K,"<="&DATE($F$3,N$6,N$5),DATA!$N:$N,$Q16)*10)+COUNTIFS(DATA!$P:$P,"=S",DATA!$K:$K,">="&DATE($F$3,N$6,1),DATA!$K:$K,"<="&DATE($F$3,N$6,N$5),DATA!$N:$N,$Q16) -> 0 | O16: =SUM(C16:N16) -> 0 | Q16: ="*"&StaffList!B21&"*" -> *Luong.px*
A17: 10 | B17: =VLOOKUP(Q17, StaffList!B:C,2,FALSE) -> Hoàng Việt Thao | C17: =(COUNTIFS(DATA!$P:$P,"=E",DATA!$K:$K,">="&DATE($F$3,C$6,1),DATA!$K:$K,"<="&DATE($F$3,C$6,C$5),DATA!$N:$N,$Q17)*10)+COUNTIFS(DATA!$P:$P,"=S",DATA!$K:$K,">="&DATE($F$3,C$6,1),DATA!$K:$K,"<="&DATE($F$3,C$6,C$5),DATA!$N:$N,$Q17) -> 0 | D17: =(COUNTIFS(DATA!$P:$P,"=E",DATA!$K:$K,">="&DATE($F$3,D$6,1),DATA!$K:$K,"<="&DATE($F$3,D$6,D$5),DATA!$N:$N,$Q17)*10)+COUNTIFS(DATA!$P:$P,"=S",DATA!$K:$K,">="&DATE($F$3,D$6,1),DATA!$K:$K,"<="&DATE($F$3,D$6,D$5),DATA!$N:$N,$Q17) -> 0 | E17: =(COUNTIFS(DATA!$P:$P,"=E",DATA!$K:$K,">="&DATE($F$3,E$6,1),DATA!$K:$K,"<="&DATE($F$3,E$6,E$5),DATA!$N:$N,$Q17)*10)+COUNTIFS(DATA!$P:$P,"=S",DATA!$K:$K,">="&DATE($F$3,E$6,1),DATA!$K:$K,"<="&DATE($F$3,E$6,E$5),DATA!$N:$N,$Q17) -> 0 | F17: =(COUNTIFS(DATA!$P:$P,"=E",DATA!$K:$K,">="&DATE($F$3,F$6,1),DATA!$K:$K,"<="&DATE($F$3,F$6,F$5),DATA!$N:$N,$Q17)*10)+COUNTIFS(DATA!$P:$P,"=S",DATA!$K:$K,">="&DATE($F$3,F$6,1),DATA!$K:$K,"<="&DATE($F$3,F$6,F$5),DATA!$N:$N,$Q17) -> 0 | G17: =(COUNTIFS(DATA!$P:$P,"=E",DATA!$K:$K,">="&DATE($F$3,G$6,1),DATA!$K:$K,"<="&DATE($F$3,G$6,G$5),DATA!$N:$N,$Q17)*10)+COUNTIFS(DATA!$P:$P,"=S",DATA!$K:$K,">="&DATE($F$3,G$6,1),DATA!$K:$K,"<="&DATE($F$3,G$6,G$5),DATA!$N:$N,$Q17) -> 0 | H17: =(COUNTIFS(DATA!$P:$P,"=E",DATA!$K:$K,">="&DATE($F$3,H$6,1),DATA!$K:$K,"<="&DATE($F$3,H$6,H$5),DATA!$N:$N,$Q17)*10)+COUNTIFS(DATA!$P:$P,"=S",DATA!$K:$K,">="&DATE($F$3,H$6,1),DATA!$K:$K,"<="&DATE($F$3,H$6,H$5),DATA!$N:$N,$Q17) -> 0 | I17: =(COUNTIFS(DATA!$P:$P,"=E",DATA!$K:$K,">="&DATE($F$3,I$6,1),DATA!$K:$K,"<="&DATE($F$3,I$6,I$5),DATA!$N:$N,$Q17)*10)+COUNTIFS(DATA!$P:$P,"=S",DATA!$K:$K,">="&DATE($F$3,I$6,1),DATA!$K:$K,"<="&DATE($F$3,I$6,I$5),DATA!$N:$N,$Q17) -> 0 | J17: =(COUNTIFS(DATA!$P:$P,"=E",DATA!$K:$K,">="&DATE($F$3,J$6,1),DATA!$K:$K,"<="&DATE($F$3,J$6,J$5),DATA!$N:$N,$Q17)*10)+COUNTIFS(DATA!$P:$P,"=S",DATA!$K:$K,">="&DATE($F$3,J$6,1),DATA!$K:$K,"<="&DATE($F$3,J$6,J$5),DATA!$N:$N,$Q17) -> 0 | ... N17: =(COUNTIFS(DATA!$P:$P,"=E",DATA!$K:$K,">="&DATE($F$3,N$6,1),DATA!$K:$K,"<="&DATE($F$3,N$6,N$5),DATA!$N:$N,$Q17)*10)+COUNTIFS(DATA!$P:$P,"=S",DATA!$K:$K,">="&DATE($F$3,N$6,1),DATA!$K:$K,"<="&DATE($F$3,N$6,N$5),DATA!$N:$N,$Q17) -> 0 | O17: =SUM(C17:N17) -> 0 | Q17: ="*"&StaffList!B14&"*" -> *Thao.hv*
A18: 6 | B18: =VLOOKUP(Q18, StaffList!B:C,2,FALSE) -> Chu Trọng Thao | C18: =(COUNTIFS(DATA!$P:$P,"=E",DATA!$K:$K,">="&DATE($F$3,C$6,1),DATA!$K:$K,"<="&DATE($F$3,C$6,C$5),DATA!$N:$N,$Q18)*10)+COUNTIFS(DATA!$P:$P,"=S",DATA!$K:$K,">="&DATE($F$3,C$6,1),DATA!$K:$K,"<="&DATE($F$3,C$6,C$5),DATA!$N:$N,$Q18) -> 0 | D18: =(COUNTIFS(DATA!$P:$P,"=E",DATA!$K:$K,">="&DATE($F$3,D$6,1),DATA!$K:$K,"<="&DATE($F$3,D$6,D$5),DATA!$N:$N,$Q18)*10)+COUNTIFS(DATA!$P:$P,"=S",DATA!$K:$K,">="&DATE($F$3,D$6,1),DATA!$K:$K,"<="&DATE($F$3,D$6,D$5),DATA!$N:$N,$Q18) -> 0 | E18: =(COUNTIFS(DATA!$P:$P,"=E",DATA!$K:$K,">="&DATE($F$3,E$6,1),DATA!$K:$K,"<="&DATE($F$3,E$6,E$5),DATA!$N:$N,$Q18)*10)+COUNTIFS(DATA!$P:$P,"=S",DATA!$K:$K,">="&DATE($F$3,E$6,1),DATA!$K:$K,"<="&DATE($F$3,E$6,E$5),DATA!$N:$N,$Q18) -> 0 | F18: =(COUNTIFS(DATA!$P:$P,"=E",DATA!$K:$K,">="&DATE($F$3,F$6,1),DATA!$K:$K,"<="&DATE($F$3,F$6,F$5),DATA!$N:$N,$Q18)*10)+COUNTIFS(DATA!$P:$P,"=S",DATA!$K:$K,">="&DATE($F$3,F$6,1),DATA!$K:$K,"<="&DATE($F$3,F$6,F$5),DATA!$N:$N,$Q18) -> 0 | G18: =(COUNTIFS(DATA!$P:$P,"=E",DATA!$K:$K,">="&DATE($F$3,G$6,1),DATA!$K:$K,"<="&DATE($F$3,G$6,G$5),DATA!$N:$N,$Q18)*10)+COUNTIFS(DATA!$P:$P,"=S",DATA!$K:$K,">="&DATE($F$3,G$6,1),DATA!$K:$K,"<="&DATE($F$3,G$6,G$5),DATA!$N:$N,$Q18) -> 0 | H18: =(COUNTIFS(DATA!$P:$P,"=E",DATA!$K:$K,">="&DATE($F$3,H$6,1),DATA!$K:$K,"<="&DATE($F$3,H$6,H$5),DATA!$N:$N,$Q18)*10)+COUNTIFS(DATA!$P:$P,"=S",DATA!$K:$K,">="&DATE($F$3,H$6,1),DATA!$K:$K,"<="&DATE($F$3,H$6,H$5),DATA!$N:$N,$Q18) -> 0 | I18: =(COUNTIFS(DATA!$P:$P,"=E",DATA!$K:$K,">="&DATE($F$3,I$6,1),DATA!$K:$K,"<="&DATE($F$3,I$6,I$5),DATA!$N:$N,$Q18)*10)+COUNTIFS(DATA!$P:$P,"=S",DATA!$K:$K,">="&DATE($F$3,I$6,1),DATA!$K:$K,"<="&DATE($F$3,I$6,I$5),DATA!$N:$N,$Q18) -> 0 | J18: =(COUNTIFS(DATA!$P:$P,"=E",DATA!$K:$K,">="&DATE($F$3,J$6,1),DATA!$K:$K,"<="&DATE($F$3,J$6,J$5),DATA!$N:$N,$Q18)*10)+COUNTIFS(DATA!$P:$P,"=S",DATA!$K:$K,">="&DATE($F$3,J$6,1),DATA!$K:$K,"<="&DATE($F$3,J$6,J$5),DATA!$N:$N,$Q18) -> 0 | ... N18: =(COUNTIFS(DATA!$P:$P,"=E",DATA!$K:$K,">="&DATE($F$3,N$6,1),DATA!$K:$K,"<="&DATE($F$3,N$6,N$5),DATA!$N:$N,$Q18)*10)+COUNTIFS(DATA!$P:$P,"=S",DATA!$K:$K,">="&DATE($F$3,N$6,1),DATA!$K:$K,"<="&DATE($F$3,N$6,N$5),DATA!$N:$N,$Q18) -> 0 | O18: =SUM(C18:N18) -> 0 | Q18: ="*"&StaffList!B10&"*" -> *Thao.ct*
A19: 24 | B19: =VLOOKUP(Q19, StaffList!B:C,2,FALSE) -> Khúc Thành Đạt | C19: =(COUNTIFS(DATA!$P:$P,"=E",DATA!$K:$K,">="&DATE($F$3,C$6,1),DATA!$K:$K,"<="&DATE($F$3,C$6,C$5),DATA!$N:$N,$Q19)*10)+COUNTIFS(DATA!$P:$P,"=S",DATA!$K:$K,">="&DATE($F$3,C$6,1),DATA!$K:$K,"<="&DATE($F$3,C$6,C$5),DATA!$N:$N,$Q19) -> 0 | D19: =(COUNTIFS(DATA!$P:$P,"=E",DATA!$K:$K,">="&DATE($F$3,D$6,1),DATA!$K:$K,"<="&DATE($F$3,D$6,D$5),DATA!$N:$N,$Q19)*10)+COUNTIFS(DATA!$P:$P,"=S",DATA!$K:$K,">="&DATE($F$3,D$6,1),DATA!$K:$K,"<="&DATE($F$3,D$6,D$5),DATA!$N:$N,$Q19) -> 0 | E19: =(COUNTIFS(DATA!$P:$P,"=E",DATA!$K:$K,">="&DATE($F$3,E$6,1),DATA!$K:$K,"<="&DATE($F$3,E$6,E$5),DATA!$N:$N,$Q19)*10)+COUNTIFS(DATA!$P:$P,"=S",DATA!$K:$K,">="&DATE($F$3,E$6,1),DATA!$K:$K,"<="&DATE($F$3,E$6,E$5),DATA!$N:$N,$Q19) -> 0 | F19: =(COUNTIFS(DATA!$P:$P,"=E",DATA!$K:$K,">="&DATE($F$3,F$6,1),DATA!$K:$K,"<="&DATE($F$3,F$6,F$5),DATA!$N:$N,$Q19)*10)+COUNTIFS(DATA!$P:$P,"=S",DATA!$K:$K,">="&DATE($F$3,F$6,1),DATA!$K:$K,"<="&DATE($F$3,F$6,F$5),DATA!$N:$N,$Q19) -> 0 | G19: =(COUNTIFS(DATA!$P:$P,"=E",DATA!$K:$K,">="&DATE($F$3,G$6,1),DATA!$K:$K,"<="&DATE($F$3,G$6,G$5),DATA!$N:$N,$Q19)*10)+COUNTIFS(DATA!$P:$P,"=S",DATA!$K:$K,">="&DATE($F$3,G$6,1),DATA!$K:$K,"<="&DATE($F$3,G$6,G$5),DATA!$N:$N,$Q19) -> 0 | H19: =(COUNTIFS(DATA!$P:$P,"=E",DATA!$K:$K,">="&DATE($F$3,H$6,1),DATA!$K:$K,"<="&DATE($F$3,H$6,H$5),DATA!$N:$N,$Q19)*10)+COUNTIFS(DATA!$P:$P,"=S",DATA!$K:$K,">="&DATE($F$3,H$6,1),DATA!$K:$K,"<="&DATE($F$3,H$6,H$5),DATA!$N:$N,$Q19) -> 0 | I19: =(COUNTIFS(DATA!$P:$P,"=E",DATA!$K:$K,">="&DATE($F$3,I$6,1),DATA!$K:$K,"<="&DATE($F$3,I$6,I$5),DATA!$N:$N,$Q19)*10)+COUNTIFS(DATA!$P:$P,"=S",DATA!$K:$K,">="&DATE($F$3,I$6,1),DATA!$K:$K,"<="&DATE($F$3,I$6,I$5),DATA!$N:$N,$Q19) -> 0 | J19: =(COUNTIFS(DATA!$P:$P,"=E",DATA!$K:$K,">="&DATE($F$3,J$6,1),DATA!$K:$K,"<="&DATE($F$3,J$6,J$5),DATA!$N:$N,$Q19)*10)+COUNTIFS(DATA!$P:$P,"=S",DATA!$K:$K,">="&DATE($F$3,J$6,1),DATA!$K:$K,"<="&DATE($F$3,J$6,J$5),DATA!$N:$N,$Q19) -> 0 | ... N19: =(COUNTIFS(DATA!$P:$P,"=E",DATA!$K:$K,">="&DATE($F$3,N$6,1),DATA!$K:$K,"<="&DATE($F$3,N$6,N$5),DATA!$N:$N,$Q19)*10)+COUNTIFS(DATA!$P:$P,"=S",DATA!$K:$K,">="&DATE($F$3,N$6,1),DATA!$K:$K,"<="&DATE($F$3,N$6,N$5),DATA!$N:$N,$Q19) -> 0 | O19: =SUM(C19:N19) -> 0 | Q19: ="*"&StaffList!B28&"*" -> *Dat.kt*
A20: 19 | B20: =VLOOKUP(Q20, StaffList!B:C,2,FALSE) -> Đỗ Văn Long | C20: =(COUNTIFS(DATA!$P:$P,"=E",DATA!$K:$K,">="&DATE($F$3,C$6,1),DATA!$K:$K,"<="&DATE($F$3,C$6,C$5),DATA!$N:$N,$Q20)*10)+COUNTIFS(DATA!$P:$P,"=S",DATA!$K:$K,">="&DATE($F$3,C$6,1),DATA!$K:$K,"<="&DATE($F$3,C$6,C$5),DATA!$N:$N,$Q20) -> 0 | D20: =(COUNTIFS(DATA!$P:$P,"=E",DATA!$K:$K,">="&DATE($F$3,D$6,1),DATA!$K:$K,"<="&DATE($F$3,D$6,D$5),DATA!$N:$N,$Q20)*10)+COUNTIFS(DATA!$P:$P,"=S",DATA!$K:$K,">="&DATE($F$3,D$6,1),DATA!$K:$K,"<="&DATE($F$3,D$6,D$5),DATA!$N:$N,$Q20) -> 0 | E20: =(COUNTIFS(DATA!$P:$P,"=E",DATA!$K:$K,">="&DATE($F$3,E$6,1),DATA!$K:$K,"<="&DATE($F$3,E$6,E$5),DATA!$N:$N,$Q20)*10)+COUNTIFS(DATA!$P:$P,"=S",DATA!$K:$K,">="&DATE($F$3,E$6,1),DATA!$K:$K,"<="&DATE($F$3,E$6,E$5),DATA!$N:$N,$Q20) -> 0 | F20: =(COUNTIFS(DATA!$P:$P,"=E",DATA!$K:$K,">="&DATE($F$3,F$6,1),DATA!$K:$K,"<="&DATE($F$3,F$6,F$5),DATA!$N:$N,$Q20)*10)+COUNTIFS(DATA!$P:$P,"=S",DATA!$K:$K,">="&DATE($F$3,F$6,1),DATA!$K:$K,"<="&DATE($F$3,F$6,F$5),DATA!$N:$N,$Q20) -> 0 | G20: =(COUNTIFS(DATA!$P:$P,"=E",DATA!$K:$K,">="&DATE($F$3,G$6,1),DATA!$K:$K,"<="&DATE($F$3,G$6,G$5),DATA!$N:$N,$Q20)*10)+COUNTIFS(DATA!$P:$P,"=S",DATA!$K:$K,">="&DATE($F$3,G$6,1),DATA!$K:$K,"<="&DATE($F$3,G$6,G$5),DATA!$N:$N,$Q20) -> 0 | H20: =(COUNTIFS(DATA!$P:$P,"=E",DATA!$K:$K,">="&DATE($F$3,H$6,1),DATA!$K:$K,"<="&DATE($F$3,H$6,H$5),DATA!$N:$N,$Q20)*10)+COUNTIFS(DATA!$P:$P,"=S",DATA!$K:$K,">="&DATE($F$3,H$6,1),DATA!$K:$K,"<="&DATE($F$3,H$6,H$5),DATA!$N:$N,$Q20) -> 0 | I20: =(COUNTIFS(DATA!$P:$P,"=E",DATA!$K:$K,">="&DATE($F$3,I$6,1),DATA!$K:$K,"<="&DATE($F$3,I$6,I$5),DATA!$N:$N,$Q20)*10)+COUNTIFS(DATA!$P:$P,"=S",DATA!$K:$K,">="&DATE($F$3,I$6,1),DATA!$K:$K,"<="&DATE($F$3,I$6,I$5),DATA!$N:$N,$Q20) -> 0 | J20: =(COUNTIFS(DATA!$P:$P,"=E",DATA!$K:$K,">="&DATE($F$3,J$6,1),DATA!$K:$K,"<="&DATE($F$3,J$6,J$5),DATA!$N:$N,$Q20)*10)+COUNTIFS(DATA!$P:$P,"=S",DATA!$K:$K,">="&DATE($F$3,J$6,1),DATA!$K:$K,"<="&DATE($F$3,J$6,J$5),DATA!$N:$N,$Q20) -> 0 | ... N20: =(COUNTIFS(DATA!$P:$P,"=E",DATA!$K:$K,">="&DATE($F$3,N$6,1),DATA!$K:$K,"<="&DATE($F$3,N$6,N$5),DATA!$N:$N,$Q20)*10)+COUNTIFS(DATA!$P:$P,"=S",DATA!$K:$K,">="&DATE($F$3,N$6,1),DATA!$K:$K,"<="&DATE($F$3,N$6,N$5),DATA!$N:$N,$Q20) -> 0 | O20: =SUM(C20:N20) -> 0 | Q20: ="*"&StaffList!B23&"*" -> *Long.dv*
A21: 2 | B21: =VLOOKUP(Q21, StaffList!B:C,2,FALSE) -> Hà Đình Diên | C21: =(COUNTIFS(DATA!$P:$P,"=E",DATA!$K:$K,">="&DATE($F$3,C$6,1),DATA!$K:$K,"<="&DATE($F$3,C$6,C$5),DATA!$N:$N,$Q21)*10)+COUNTIFS(DATA!$P:$P,"=S",DATA!$K:$K,">="&DATE($F$3,C$6,1),DATA!$K:$K,"<="&DATE($F$3,C$6,C$5),DATA!$N:$N,$Q21) -> 0 | D21: =(COUNTIFS(DATA!$P:$P,"=E",DATA!$K:$K,">="&DATE($F$3,D$6,1),DATA!$K:$K,"<="&DATE($F$3,D$6,D$5),DATA!$N:$N,$Q21)*10)+COUNTIFS(DATA!$P:$P,"=S",DATA!$K:$K,">="&DATE($F$3,D$6,1),DATA!$K:$K,"<="&DATE($F$3,D$6,D$5),DATA!$N:$N,$Q21) -> 0 | E21: =(COUNTIFS(DATA!$P:$P,"=E",DATA!$K:$K,">="&DATE($F$3,E$6,1),DATA!$K:$K,"<="&DATE($F$3,E$6,E$5),DATA!$N:$N,$Q21)*10)+COUNTIFS(DATA!$P:$P,"=S",DATA!$K:$K,">="&DATE($F$3,E$6,1),DATA!$K:$K,"<="&DATE($F$3,E$6,E$5),DATA!$N:$N,$Q21) -> 0 | F21: =(COUNTIFS(DATA!$P:$P,"=E",DATA!$K:$K,">="&DATE($F$3,F$6,1),DATA!$K:$K,"<="&DATE($F$3,F$6,F$5),DATA!$N:$N,$Q21)*10)+COUNTIFS(DATA!$P:$P,"=S",DATA!$K:$K,">="&DATE($F$3,F$6,1),DATA!$K:$K,"<="&DATE($F$3,F$6,F$5),DATA!$N:$N,$Q21) -> 0 | G21: =(COUNTIFS(DATA!$P:$P,"=E",DATA!$K:$K,">="&DATE($F$3,G$6,1),DATA!$K:$K,"<="&DATE($F$3,G$6,G$5),DATA!$N:$N,$Q21)*10)+COUNTIFS(DATA!$P:$P,"=S",DATA!$K:$K,">="&DATE($F$3,G$6,1),DATA!$K:$K,"<="&DATE($F$3,G$6,G$5),DATA!$N:$N,$Q21) -> 0 | H21: =(COUNTIFS(DATA!$P:$P,"=E",DATA!$K:$K,">="&DATE($F$3,H$6,1),DATA!$K:$K,"<="&DATE($F$3,H$6,H$5),DATA!$N:$N,$Q21)*10)+COUNTIFS(DATA!$P:$P,"=S",DATA!$K:$K,">="&DATE($F$3,H$6,1),DATA!$K:$K,"<="&DATE($F$3,H$6,H$5),DATA!$N:$N,$Q21) -> 0 | I21: =(COUNTIFS(DATA!$P:$P,"=E",DATA!$K:$K,">="&DATE($F$3,I$6,1),DATA!$K:$K,"<="&DATE($F$3,I$6,I$5),DATA!$N:$N,$Q21)*10)+COUNTIFS(DATA!$P:$P,"=S",DATA!$K:$K,">="&DATE($F$3,I$6,1),DATA!$K:$K,"<="&DATE($F$3,I$6,I$5),DATA!$N:$N,$Q21) -> 0 | J21: =(COUNTIFS(DATA!$P:$P,"=E",DATA!$K:$K,">="&DATE($F$3,J$6,1),DATA!$K:$K,"<="&DATE($F$3,J$6,J$5),DATA!$N:$N,$Q21)*10)+COUNTIFS(DATA!$P:$P,"=S",DATA!$K:$K,">="&DATE($F$3,J$6,1),DATA!$K:$K,"<="&DATE($F$3,J$6,J$5),DATA!$N:$N,$Q21) -> 0 | ... N21: =(COUNTIFS(DATA!$P:$P,"=E",DATA!$K:$K,">="&DATE($F$3,N$6,1),DATA!$K:$K,"<="&DATE($F$3,N$6,N$5),DATA!$N:$N,$Q21)*10)+COUNTIFS(DATA!$P:$P,"=S",DATA!$K:$K,">="&DATE($F$3,N$6,1),DATA!$K:$K,"<="&DATE($F$3,N$6,N$5),DATA!$N:$N,$Q21) -> 0 | O21: =SUM(C21:N21) -> 0 | Q21: ="*"&StaffList!B6&"*" -> *Dien.hd*
A22: 12 | B22: =VLOOKUP(Q22, StaffList!B:C,2,FALSE) -> Mai Văn Hoàng | C22: =(COUNTIFS(DATA!$P:$P,"=E",DATA!$K:$K,">="&DATE($F$3,C$6,1),DATA!$K:$K,"<="&DATE($F$3,C$6,C$5),DATA!$N:$N,$Q22)*10)+COUNTIFS(DATA!$P:$P,"=S",DATA!$K:$K,">="&DATE($F$3,C$6,1),DATA!$K:$K,"<="&DATE($F$3,C$6,C$5),DATA!$N:$N,$Q22) -> 0 | D22: =(COUNTIFS(DATA!$P:$P,"=E",DATA!$K:$K,">="&DATE($F$3,D$6,1),DATA!$K:$K,"<="&DATE($F$3,D$6,D$5),DATA!$N:$N,$Q22)*10)+COUNTIFS(DATA!$P:$P,"=S",DATA!$K:$K,">="&DATE($F$3,D$6,1),DATA!$K:$K,"<="&DATE($F$3,D$6,D$5),DATA!$N:$N,$Q22) -> 0 | E22: =(COUNTIFS(DATA!$P:$P,"=E",DATA!$K:$K,">="&DATE($F$3,E$6,1),DATA!$K:$K,"<="&DATE($F$3,E$6,E$5),DATA!$N:$N,$Q22)*10)+COUNTIFS(DATA!$P:$P,"=S",DATA!$K:$K,">="&DATE($F$3,E$6,1),DATA!$K:$K,"<="&DATE($F$3,E$6,E$5),DATA!$N:$N,$Q22) -> 0 | F22: =(COUNTIFS(DATA!$P:$P,"=E",DATA!$K:$K,">="&DATE($F$3,F$6,1),DATA!$K:$K,"<="&DATE($F$3,F$6,F$5),DATA!$N:$N,$Q22)*10)+COUNTIFS(DATA!$P:$P,"=S",DATA!$K:$K,">="&DATE($F$3,F$6,1),DATA!$K:$K,"<="&DATE($F$3,F$6,F$5),DATA!$N:$N,$Q22) -> 0 | G22: =(COUNTIFS(DATA!$P:$P,"=E",DATA!$K:$K,">="&DATE($F$3,G$6,1),DATA!$K:$K,"<="&DATE($F$3,G$6,G$5),DATA!$N:$N,$Q22)*10)+COUNTIFS(DATA!$P:$P,"=S",DATA!$K:$K,">="&DATE($F$3,G$6,1),DATA!$K:$K,"<="&DATE($F$3,G$6,G$5),DATA!$N:$N,$Q22) -> 0 | H22: =(COUNTIFS(DATA!$P:$P,"=E",DATA!$K:$K,">="&DATE($F$3,H$6,1),DATA!$K:$K,"<="&DATE($F$3,H$6,H$5),DATA!$N:$N,$Q22)*10)+COUNTIFS(DATA!$P:$P,"=S",DATA!$K:$K,">="&DATE($F$3,H$6,1),DATA!$K:$K,"<="&DATE($F$3,H$6,H$5),DATA!$N:$N,$Q22) -> 0 | I22: =(COUNTIFS(DATA!$P:$P,"=E",DATA!$K:$K,">="&DATE($F$3,I$6,1),DATA!$K:$K,"<="&DATE($F$3,I$6,I$5),DATA!$N:$N,$Q22)*10)+COUNTIFS(DATA!$P:$P,"=S",DATA!$K:$K,">="&DATE($F$3,I$6,1),DATA!$K:$K,"<="&DATE($F$3,I$6,I$5),DATA!$N:$N,$Q22) -> 0 | J22: =(COUNTIFS(DATA!$P:$P,"=E",DATA!$K:$K,">="&DATE($F$3,J$6,1),DATA!$K:$K,"<="&DATE($F$3,J$6,J$5),DATA!$N:$N,$Q22)*10)+COUNTIFS(DATA!$P:$P,"=S",DATA!$K:$K,">="&DATE($F$3,J$6,1),DATA!$K:$K,"<="&DATE($F$3,J$6,J$5),DATA!$N:$N,$Q22) -> 0 | ... N22: =(COUNTIFS(DATA!$P:$P,"=E",DATA!$K:$K,">="&DATE($F$3,N$6,1),DATA!$K:$K,"<="&DATE($F$3,N$6,N$5),DATA!$N:$N,$Q22)*10)+COUNTIFS(DATA!$P:$P,"=S",DATA!$K:$K,">="&DATE($F$3,N$6,1),DATA!$K:$K,"<="&DATE($F$3,N$6,N$5),DATA!$N:$N,$Q22) -> 0 | O22: =SUM(C22:N22) -> 0 | Q22: ="*"&StaffList!B16&"*" -> *Hoang.mv*
A23: 4 | B23: =VLOOKUP(Q23, StaffList!B:C,2,FALSE) -> Vũ Hoàng | C23: =(COUNTIFS(DATA!$P:$P,"=E",DATA!$K:$K,">="&DATE($F$3,C$6,1),DATA!$K:$K,"<="&DATE($F$3,C$6,C$5),DATA!$N:$N,$Q23)*10)+COUNTIFS(DATA!$P:$P,"=S",DATA!$K:$K,">="&DATE($F$3,C$6,1),DATA!$K:$K,"<="&DATE($F$3,C$6,C$5),DATA!$N:$N,$Q23) -> 0 | D23: =(COUNTIFS(DATA!$P:$P,"=E",DATA!$K:$K,">="&DATE($F$3,D$6,1),DATA!$K:$K,"<="&DATE($F$3,D$6,D$5),DATA!$N:$N,$Q23)*10)+COUNTIFS(DATA!$P:$P,"=S",DATA!$K:$K,">="&DATE($F$3,D$6,1),DATA!$K:$K,"<="&DATE($F$3,D$6,D$5),DATA!$N:$N,$Q23) -> 0 | E23: =(COUNTIFS(DATA!$P:$P,"=E",DATA!$K:$K,">="&DATE($F$3,E$6,1),DATA!$K:$K,"<="&DATE($F$3,E$6,E$5),DATA!$N:$N,$Q23)*10)+COUNTIFS(DATA!$P:$P,"=S",DATA!$K:$K,">="&DATE($F$3,E$6,1),DATA!$K:$K,"<="&DATE($F$3,E$6,E$5),DATA!$N:$N,$Q23) -> 0 | F23: =(COUNTIFS(DATA!$P:$P,"=E",DATA!$K:$K,">="&DATE($F$3,F$6,1),DATA!$K:$K,"<="&DATE($F$3,F$6,F$5),DATA!$N:$N,$Q23)*10)+COUNTIFS(DATA!$P:$P,"=S",DATA!$K:$K,">="&DATE($F$3,F$6,1),DATA!$K:$K,"<="&DATE($F$3,F$6,F$5),DATA!$N:$N,$Q23) -> 0 | G23: =(COUNTIFS(DATA!$P:$P,"=E",DATA!$K:$K,">="&DATE($F$3,G$6,1),DATA!$K:$K,"<="&DATE($F$3,G$6,G$5),DATA!$N:$N,$Q23)*10)+COUNTIFS(DATA!$P:$P,"=S",DATA!$K:$K,">="&DATE($F$3,G$6,1),DATA!$K:$K,"<="&DATE($F$3,G$6,G$5),DATA!$N:$N,$Q23) -> 0 | H23: =(COUNTIFS(DATA!$P:$P,"=E",DATA!$K:$K,">="&DATE($F$3,H$6,1),DATA!$K:$K,"<="&DATE($F$3,H$6,H$5),DATA!$N:$N,$Q23)*10)+COUNTIFS(DATA!$P:$P,"=S",DATA!$K:$K,">="&DATE($F$3,H$6,1),DATA!$K:$K,"<="&DATE($F$3,H$6,H$5),DATA!$N:$N,$Q23) -> 0 | I23: =(COUNTIFS(DATA!$P:$P,"=E",DATA!$K:$K,">="&DATE($F$3,I$6,1),DATA!$K:$K,"<="&DATE($F$3,I$6,I$5),DATA!$N:$N,$Q23)*10)+COUNTIFS(DATA!$P:$P,"=S",DATA!$K:$K,">="&DATE($F$3,I$6,1),DATA!$K:$K,"<="&DATE($F$3,I$6,I$5),DATA!$N:$N,$Q23) -> 0 | J23: =(COUNTIFS(DATA!$P:$P,"=E",DATA!$K:$K,">="&DATE($F$3,J$6,1),DATA!$K:$K,"<="&DATE($F$3,J$6,J$5),DATA!$N:$N,$Q23)*10)+COUNTIFS(DATA!$P:$P,"=S",DATA!$K:$K,">="&DATE($F$3,J$6,1),DATA!$K:$K,"<="&DATE($F$3,J$6,J$5),DATA!$N:$N,$Q23) -> 0 | ... N23: =(COUNTIFS(DATA!$P:$P,"=E",DATA!$K:$K,">="&DATE($F$3,N$6,1),DATA!$K:$K,"<="&DATE($F$3,N$6,N$5),DATA!$N:$N,$Q23)*10)+COUNTIFS(DATA!$P:$P,"=S",DATA!$K:$K,">="&DATE($F$3,N$6,1),DATA!$K:$K,"<="&DATE($F$3,N$6,N$5),DATA!$N:$N,$Q23) -> 0 | O23: =SUM(C23:N23) -> 0 | Q23: ="*"&StaffList!B8&"*" -> *Hoang.v*
A24: 3 | B24: =VLOOKUP(Q24, StaffList!B:C,2,FALSE) -> Nguyễn Mạnh Hùng | C24: =(COUNTIFS(DATA!$P:$P,"=E",DATA!$K:$K,">="&DATE($F$3,C$6,1),DATA!$K:$K,"<="&DATE($F$3,C$6,C$5),DATA!$N:$N,$Q24)*10)+COUNTIFS(DATA!$P:$P,"=S",DATA!$K:$K,">="&DATE($F$3,C$6,1),DATA!$K:$K,"<="&DATE($F$3,C$6,C$5),DATA!$N:$N,$Q24) -> 0 | D24: =(COUNTIFS(DATA!$P:$P,"=E",DATA!$K:$K,">="&DATE($F$3,D$6,1),DATA!$K:$K,"<="&DATE($F$3,D$6,D$5),DATA!$N:$N,$Q24)*10)+COUNTIFS(DATA!$P:$P,"=S",DATA!$K:$K,">="&DATE($F$3,D$6,1),DATA!$K:$K,"<="&DATE($F$3,D$6,D$5),DATA!$N:$N,$Q24) -> 0 | E24: =(COUNTIFS(DATA!$P:$P,"=E",DATA!$K:$K,">="&DATE($F$3,E$6,1),DATA!$K:$K,"<="&DATE($F$3,E$6,E$5),DATA!$N:$N,$Q24)*10)+COUNTIFS(DATA!$P:$P,"=S",DATA!$K:$K,">="&DATE($F$3,E$6,1),DATA!$K:$K,"<="&DATE($F$3,E$6,E$5),DATA!$N:$N,$Q24) -> 0 | F24: =(COUNTIFS(DATA!$P:$P,"=E",DATA!$K:$K,">="&DATE($F$3,F$6,1),DATA!$K:$K,"<="&DATE($F$3,F$6,F$5),DATA!$N:$N,$Q24)*10)+COUNTIFS(DATA!$P:$P,"=S",DATA!$K:$K,">="&DATE($F$3,F$6,1),DATA!$K:$K,"<="&DATE($F$3,F$6,F$5),DATA!$N:$N,$Q24) -> 0 | G24: =(COUNTIFS(DATA!$P:$P,"=E",DATA!$K:$K,">="&DATE($F$3,G$6,1),DATA!$K:$K,"<="&DATE($F$3,G$6,G$5),DATA!$N:$N,$Q24)*10)+COUNTIFS(DATA!$P:$P,"=S",DATA!$K:$K,">="&DATE($F$3,G$6,1),DATA!$K:$K,"<="&DATE($F$3,G$6,G$5),DATA!$N:$N,$Q24) -> 0 | H24: =(COUNTIFS(DATA!$P:$P,"=E",DATA!$K:$K,">="&DATE($F$3,H$6,1),DATA!$K:$K,"<="&DATE($F$3,H$6,H$5),DATA!$N:$N,$Q24)*10)+COUNTIFS(DATA!$P:$P,"=S",DATA!$K:$K,">="&DATE($F$3,H$6,1),DATA!$K:$K,"<="&DATE($F$3,H$6,H$5),DATA!$N:$N,$Q24) -> 0 | I24: =(COUNTIFS(DATA!$P:$P,"=E",DATA!$K:$K,">="&DATE($F$3,I$6,1),DATA!$K:$K,"<="&DATE($F$3,I$6,I$5),DATA!$N:$N,$Q24)*10)+COUNTIFS(DATA!$P:$P,"=S",DATA!$K:$K,">="&DATE($F$3,I$6,1),DATA!$K:$K,"<="&DATE($F$3,I$6,I$5),DATA!$N:$N,$Q24) -> 0 | J24: =(COUNTIFS(DATA!$P:$P,"=E",DATA!$K:$K,">="&DATE($F$3,J$6,1),DATA!$K:$K,"<="&DATE($F$3,J$6,J$5),DATA!$N:$N,$Q24)*10)+COUNTIFS(DATA!$P:$P,"=S",DATA!$K:$K,">="&DATE($F$3,J$6,1),DATA!$K:$K,"<="&DATE($F$3,J$6,J$5),DATA!$N:$N,$Q24) -> 0 | ... N24: =(COUNTIFS(DATA!$P:$P,"=E",DATA!$K:$K,">="&DATE($F$3,N$6,1),DATA!$K:$K,"<="&DATE($F$3,N$6,N$5),DATA!$N:$N,$Q24)*10)+COUNTIFS(DATA!$P:$P,"=S",DATA!$K:$K,">="&DATE($F$3,N$6,1),DATA!$K:$K,"<="&DATE($F$3,N$6,N$5),DATA!$N:$N,$Q24) -> 0 | O24: =SUM(C24:N24) -> 0 | Q24: ="*"&StaffList!B7&"*" -> *Hung.nm*
A25: 21 | B25: =VLOOKUP(Q25, StaffList!B:C,2,FALSE) -> Bùi Văn Long | C25: =(COUNTIFS(DATA!$P:$P,"=E",DATA!$K:$K,">="&DATE($F$3,C$6,1),DATA!$K:$K,"<="&DATE($F$3,C$6,C$5),DATA!$N:$N,$Q25)*10)+COUNTIFS(DATA!$P:$P,"=S",DATA!$K:$K,">="&DATE($F$3,C$6,1),DATA!$K:$K,"<="&DATE($F$3,C$6,C$5),DATA!$N:$N,$Q25) -> 0 | D25: =(COUNTIFS(DATA!$P:$P,"=E",DATA!$K:$K,">="&DATE($F$3,D$6,1),DATA!$K:$K,"<="&DATE($F$3,D$6,D$5),DATA!$N:$N,$Q25)*10)+COUNTIFS(DATA!$P:$P,"=S",DATA!$K:$K,">="&DATE($F$3,D$6,1),DATA!$K:$K,"<="&DATE($F$3,D$6,D$5),DATA!$N:$N,$Q25) -> 0 | E25: =(COUNTIFS(DATA!$P:$P,"=E",DATA!$K:$K,">="&DATE($F$3,E$6,1),DATA!$K:$K,"<="&DATE($F$3,E$6,E$5),DATA!$N:$N,$Q25)*10)+COUNTIFS(DATA!$P:$P,"=S",DATA!$K:$K,">="&DATE($F$3,E$6,1),DATA!$K:$K,"<="&DATE($F$3,E$6,E$5),DATA!$N:$N,$Q25) -> 0 | F25: =(COUNTIFS(DATA!$P:$P,"=E",DATA!$K:$K,">="&DATE($F$3,F$6,1),DATA!$K:$K,"<="&DATE($F$3,F$6,F$5),DATA!$N:$N,$Q25)*10)+COUNTIFS(DATA!$P:$P,"=S",DATA!$K:$K,">="&DATE($F$3,F$6,1),DATA!$K:$K,"<="&DATE($F$3,F$6,F$5),DATA!$N:$N,$Q25) -> 0 | G25: =(COUNTIFS(DATA!$P:$P,"=E",DATA!$K:$K,">="&DATE($F$3,G$6,1),DATA!$K:$K,"<="&DATE($F$3,G$6,G$5),DATA!$N:$N,$Q25)*10)+COUNTIFS(DATA!$P:$P,"=S",DATA!$K:$K,">="&DATE($F$3,G$6,1),DATA!$K:$K,"<="&DATE($F$3,G$6,G$5),DATA!$N:$N,$Q25) -> 0 | H25: =(COUNTIFS(DATA!$P:$P,"=E",DATA!$K:$K,">="&DATE($F$3,H$6,1),DATA!$K:$K,"<="&DATE($F$3,H$6,H$5),DATA!$N:$N,$Q25)*10)+COUNTIFS(DATA!$P:$P,"=S",DATA!$K:$K,">="&DATE($F$3,H$6,1),DATA!$K:$K,"<="&DATE($F$3,H$6,H$5),DATA!$N:$N,$Q25) -> 0 | I25: =(COUNTIFS(DATA!$P:$P,"=E",DATA!$K:$K,">="&DATE($F$3,I$6,1),DATA!$K:$K,"<="&DATE($F$3,I$6,I$5),DATA!$N:$N,$Q25)*10)+COUNTIFS(DATA!$P:$P,"=S",DATA!$K:$K,">="&DATE($F$3,I$6,1),DATA!$K:$K,"<="&DATE($F$3,I$6,I$5),DATA!$N:$N,$Q25) -> 0 | J25: =(COUNTIFS(DATA!$P:$P,"=E",DATA!$K:$K,">="&DATE($F$3,J$6,1),DATA!$K:$K,"<="&DATE($F$3,J$6,J$5),DATA!$N:$N,$Q25)*10)+COUNTIFS(DATA!$P:$P,"=S",DATA!$K:$K,">="&DATE($F$3,J$6,1),DATA!$K:$K,"<="&DATE($F$3,J$6,J$5),DATA!$N:$N,$Q25) -> 0 | ... N25: =(COUNTIFS(DATA!$P:$P,"=E",DATA!$K:$K,">="&DATE($F$3,N$6,1),DATA!$K:$K,"<="&DATE($F$3,N$6,N$5),DATA!$N:$N,$Q25)*10)+COUNTIFS(DATA!$P:$P,"=S",DATA!$K:$K,">="&DATE($F$3,N$6,1),DATA!$K:$K,"<="&DATE($F$3,N$6,N$5),DATA!$N:$N,$Q25) -> 0 | O25: =SUM(C25:N25) -> 0 | Q25: ="*"&StaffList!B25&"*" -> *Long.bv*
A26: 22 | B26: =VLOOKUP(Q26, StaffList!B:C,2,FALSE) -> Đoàn Mạnh Thức | C26: =(COUNTIFS(DATA!$P:$P,"=E",DATA!$K:$K,">="&DATE($F$3,C$6,1),DATA!$K:$K,"<="&DATE($F$3,C$6,C$5),DATA!$N:$N,$Q26)*10)+COUNTIFS(DATA!$P:$P,"=S",DATA!$K:$K,">="&DATE($F$3,C$6,1),DATA!$K:$K,"<="&DATE($F$3,C$6,C$5),DATA!$N:$N,$Q26) -> 0 | D26: =(COUNTIFS(DATA!$P:$P,"=E",DATA!$K:$K,">="&DATE($F$3,D$6,1),DATA!$K:$K,"<="&DATE($F$3,D$6,D$5),DATA!$N:$N,$Q26)*10)+COUNTIFS(DATA!$P:$P,"=S",DATA!$K:$K,">="&DATE($F$3,D$6,1),DATA!$K:$K,"<="&DATE($F$3,D$6,D$5),DATA!$N:$N,$Q26) -> 0 | E26: =(COUNTIFS(DATA!$P:$P,"=E",DATA!$K:$K,">="&DATE($F$3,E$6,1),DATA!$K:$K,"<="&DATE($F$3,E$6,E$5),DATA!$N:$N,$Q26)*10)+COUNTIFS(DATA!$P:$P,"=S",DATA!$K:$K,">="&DATE($F$3,E$6,1),DATA!$K:$K,"<="&DATE($F$3,E$6,E$5),DATA!$N:$N,$Q26) -> 0 | F26: =(COUNTIFS(DATA!$P:$P,"=E",DATA!$K:$K,">="&DATE($F$3,F$6,1),DATA!$K:$K,"<="&DATE($F$3,F$6,F$5),DATA!$N:$N,$Q26)*10)+COUNTIFS(DATA!$P:$P,"=S",DATA!$K:$K,">="&DATE($F$3,F$6,1),DATA!$K:$K,"<="&DATE($F$3,F$6,F$5),DATA!$N:$N,$Q26) -> 0 | G26: =(COUNTIFS(DATA!$P:$P,"=E",DATA!$K:$K,">="&DATE($F$3,G$6,1),DATA!$K:$K,"<="&DATE($F$3,G$6,G$5),DATA!$N:$N,$Q26)*10)+COUNTIFS(DATA!$P:$P,"=S",DATA!$K:$K,">="&DATE($F$3,G$6,1),DATA!$K:$K,"<="&DATE($F$3,G$6,G$5),DATA!$N:$N,$Q26) -> 0 | H26: =(COUNTIFS(DATA!$P:$P,"=E",DATA!$K:$K,">="&DATE($F$3,H$6,1),DATA!$K:$K,"<="&DATE($F$3,H$6,H$5),DATA!$N:$N,$Q26)*10)+COUNTIFS(DATA!$P:$P,"=S",DATA!$K:$K,">="&DATE($F$3,H$6,1),DATA!$K:$K,"<="&DATE($F$3,H$6,H$5),DATA!$N:$N,$Q26) -> 0 | I26: =(COUNTIFS(DATA!$P:$P,"=E",DATA!$K:$K,">="&DATE($F$3,I$6,1),DATA!$K:$K,"<="&DATE($F$3,I$6,I$5),DATA!$N:$N,$Q26)*10)+COUNTIFS(DATA!$P:$P,"=S",DATA!$K:$K,">="&DATE($F$3,I$6,1),DATA!$K:$K,"<="&DATE($F$3,I$6,I$5),DATA!$N:$N,$Q26) -> 0 | J26: =(COUNTIFS(DATA!$P:$P,"=E",DATA!$K:$K,">="&DATE($F$3,J$6,1),DATA!$K:$K,"<="&DATE($F$3,J$6,J$5),DATA!$N:$N,$Q26)*10)+COUNTIFS(DATA!$P:$P,"=S",DATA!$K:$K,">="&DATE($F$3,J$6,1),DATA!$K:$K,"<="&DATE($F$3,J$6,J$5),DATA!$N:$N,$Q26) -> 0 | ... N26: =(COUNTIFS(DATA!$P:$P,"=E",DATA!$K:$K,">="&DATE($F$3,N$6,1),DATA!$K:$K,"<="&DATE($F$3,N$6,N$5),DATA!$N:$N,$Q26)*10)+COUNTIFS(DATA!$P:$P,"=S",DATA!$K:$K,">="&DATE($F$3,N$6,1),DATA!$K:$K,"<="&DATE($F$3,N$6,N$5),DATA!$N:$N,$Q26) -> 0 | O26: =SUM(C26:N26) -> 0 | Q26: ="*"&StaffList!B26&"*" -> *Thuc.dm*
A27: 23 | B27: =VLOOKUP(Q27, StaffList!B:C,2,FALSE) -> Đoàn Minh Đạo | C27: =(COUNTIFS(DATA!$P:$P,"=E",DATA!$K:$K,">="&DATE($F$3,C$6,1),DATA!$K:$K,"<="&DATE($F$3,C$6,C$5),DATA!$N:$N,$Q27)*10)+COUNTIFS(DATA!$P:$P,"=S",DATA!$K:$K,">="&DATE($F$3,C$6,1),DATA!$K:$K,"<="&DATE($F$3,C$6,C$5),DATA!$N:$N,$Q27) -> 0 | D27: =(COUNTIFS(DATA!$P:$P,"=E",DATA!$K:$K,">="&DATE($F$3,D$6,1),DATA!$K:$K,"<="&DATE($F$3,D$6,D$5),DATA!$N:$N,$Q27)*10)+COUNTIFS(DATA!$P:$P,"=S",DATA!$K:$K,">="&DATE($F$3,D$6,1),DATA!$K:$K,"<="&DATE($F$3,D$6,D$5),DATA!$N:$N,$Q27) -> 0 | E27: =(COUNTIFS(DATA!$P:$P,"=E",DATA!$K:$K,">="&DATE($F$3,E$6,1),DATA!$K:$K,"<="&DATE($F$3,E$6,E$5),DATA!$N:$N,$Q27)*10)+COUNTIFS(DATA!$P:$P,"=S",DATA!$K:$K,">="&DATE($F$3,E$6,1),DATA!$K:$K,"<="&DATE($F$3,E$6,E$5),DATA!$N:$N,$Q27) -> 0 | F27: =(COUNTIFS(DATA!$P:$P,"=E",DATA!$K:$K,">="&DATE($F$3,F$6,1),DATA!$K:$K,"<="&DATE($F$3,F$6,F$5),DATA!$N:$N,$Q27)*10)+COUNTIFS(DATA!$P:$P,"=S",DATA!$K:$K,">="&DATE($F$3,F$6,1),DATA!$K:$K,"<="&DATE($F$3,F$6,F$5),DATA!$N:$N,$Q27) -> 0 | G27: =(COUNTIFS(DATA!$P:$P,"=E",DATA!$K:$K,">="&DATE($F$3,G$6,1),DATA!$K:$K,"<="&DATE($F$3,G$6,G$5),DATA!$N:$N,$Q27)*10)+COUNTIFS(DATA!$P:$P,"=S",DATA!$K:$K,">="&DATE($F$3,G$6,1),DATA!$K:$K,"<="&DATE($F$3,G$6,G$5),DATA!$N:$N,$Q27) -> 0 | H27: =(COUNTIFS(DATA!$P:$P,"=E",DATA!$K:$K,">="&DATE($F$3,H$6,1),DATA!$K:$K,"<="&DATE($F$3,H$6,H$5),DATA!$N:$N,$Q27)*10)+COUNTIFS(DATA!$P:$P,"=S",DATA!$K:$K,">="&DATE($F$3,H$6,1),DATA!$K:$K,"<="&DATE($F$3,H$6,H$5),DATA!$N:$N,$Q27) -> 0 | I27: =(COUNTIFS(DATA!$P:$P,"=E",DATA!$K:$K,">="&DATE($F$3,I$6,1),DATA!$K:$K,"<="&DATE($F$3,I$6,I$5),DATA!$N:$N,$Q27)*10)+COUNTIFS(DATA!$P:$P,"=S",DATA!$K:$K,">="&DATE($F$3,I$6,1),DATA!$K:$K,"<="&DATE($F$3,I$6,I$5),DATA!$N:$N,$Q27) -> 0 | J27: =(COUNTIFS(DATA!$P:$P,"=E",DATA!$K:$K,">="&DATE($F$3,J$6,1),DATA!$K:$K,"<="&DATE($F$3,J$6,J$5),DATA!$N:$N,$Q27)*10)+COUNTIFS(DATA!$P:$P,"=S",DATA!$K:$K,">="&DATE($F$3,J$6,1),DATA!$K:$K,"<="&DATE($F$3,J$6,J$5),DATA!$N:$N,$Q27) -> 0 | ... N27: =(COUNTIFS(DATA!$P:$P,"=E",DATA!$K:$K,">="&DATE($F$3,N$6,1),DATA!$K:$K,"<="&DATE($F$3,N$6,N$5),DATA!$N:$N,$Q27)*10)+COUNTIFS(DATA!$P:$P,"=S",DATA!$K:$K,">="&DATE($F$3,N$6,1),DATA!$K:$K,"<="&DATE($F$3,N$6,N$5),DATA!$N:$N,$Q27) -> 0 | O27: =SUM(C27:N27) -> 0 | Q27: ="*"&StaffList!B27&"*" -> *Dao.dm*
A28: 1 | B28: =VLOOKUP(Q28, StaffList!B:C,2,FALSE) -> Lê Hùng Mạnh | C28: =(COUNTIFS(DATA!$P:$P,"=E",DATA!$K:$K,">="&DATE($F$3,C$6,1),DATA!$K:$K,"<="&DATE($F$3,C$6,C$5),DATA!$N:$N,$Q28)*10)+COUNTIFS(DATA!$P:$P,"=S",DATA!$K:$K,">="&DATE($F$3,C$6,1),DATA!$K:$K,"<="&DATE($F$3,C$6,C$5),DATA!$N:$N,$Q28) -> 0 | D28: =(COUNTIFS(DATA!$P:$P,"=E",DATA!$K:$K,">="&DATE($F$3,D$6,1),DATA!$K:$K,"<="&DATE($F$3,D$6,D$5),DATA!$N:$N,$Q28)*10)+COUNTIFS(DATA!$P:$P,"=S",DATA!$K:$K,">="&DATE($F$3,D$6,1),DATA!$K:$K,"<="&DATE($F$3,D$6,D$5),DATA!$N:$N,$Q28) -> 0 | E28: =(COUNTIFS(DATA!$P:$P,"=E",DATA!$K:$K,">="&DATE($F$3,E$6,1),DATA!$K:$K,"<="&DATE($F$3,E$6,E$5),DATA!$N:$N,$Q28)*10)+COUNTIFS(DATA!$P:$P,"=S",DATA!$K:$K,">="&DATE($F$3,E$6,1),DATA!$K:$K,"<="&DATE($F$3,E$6,E$5),DATA!$N:$N,$Q28) -> 0 | F28: =(COUNTIFS(DATA!$P:$P,"=E",DATA!$K:$K,">="&DATE($F$3,F$6,1),DATA!$K:$K,"<="&DATE($F$3,F$6,F$5),DATA!$N:$N,$Q28)*10)+COUNTIFS(DATA!$P:$P,"=S",DATA!$K:$K,">="&DATE($F$3,F$6,1),DATA!$K:$K,"<="&DATE($F$3,F$6,F$5),DATA!$N:$N,$Q28) -> 0 | G28: =(COUNTIFS(DATA!$P:$P,"=E",DATA!$K:$K,">="&DATE($F$3,G$6,1),DATA!$K:$K,"<="&DATE($F$3,G$6,G$5),DATA!$N:$N,$Q28)*10)+COUNTIFS(DATA!$P:$P,"=S",DATA!$K:$K,">="&DATE($F$3,G$6,1),DATA!$K:$K,"<="&DATE($F$3,G$6,G$5),DATA!$N:$N,$Q28) -> 0 | H28: =(COUNTIFS(DATA!$P:$P,"=E",DATA!$K:$K,">="&DATE($F$3,H$6,1),DATA!$K:$K,"<="&DATE($F$3,H$6,H$5),DATA!$N:$N,$Q28)*10)+COUNTIFS(DATA!$P:$P,"=S",DATA!$K:$K,">="&DATE($F$3,H$6,1),DATA!$K:$K,"<="&DATE($F$3,H$6,H$5),DATA!$N:$N,$Q28) -> 0 | I28: =(COUNTIFS(DATA!$P:$P,"=E",DATA!$K:$K,">="&DATE($F$3,I$6,1),DATA!$K:$K,"<="&DATE($F$3,I$6,I$5),DATA!$N:$N,$Q28)*10)+COUNTIFS(DATA!$P:$P,"=S",DATA!$K:$K,">="&DATE($F$3,I$6,1),DATA!$K:$K,"<="&DATE($F$3,I$6,I$5),DATA!$N:$N,$Q28) -> 0 | J28: =(COUNTIFS(DATA!$P:$P,"=E",DATA!$K:$K,">="&DATE($F$3,J$6,1),DATA!$K:$K,"<="&DATE($F$3,J$6,J$5),DATA!$N:$N,$Q28)*10)+COUNTIFS(DATA!$P:$P,"=S",DATA!$K:$K,">="&DATE($F$3,J$6,1),DATA!$K:$K,"<="&DATE($F$3,J$6,J$5),DATA!$N:$N,$Q28) -> 0 | ... N28: =(COUNTIFS(DATA!$P:$P,"=E",DATA!$K:$K,">="&DATE($F$3,N$6,1),DATA!$K:$K,"<="&DATE($F$3,N$6,N$5),DATA!$N:$N,$Q28)*10)+COUNTIFS(DATA!$P:$P,"=S",DATA!$K:$K,">="&DATE($F$3,N$6,1),DATA!$K:$K,"<="&DATE($F$3,N$6,N$5),DATA!$N:$N,$Q28) -> 0 | O28: =SUM(C28:N28) -> 0 | Q28: ="*"&StaffList!B5&"*" -> *Manh.lh*
